
2020-09-20 22:58:14,960 INFO: errors [in C:/Projects/Udacity/Python/Fyyur/app.py:542]
2020-09-20 22:58:45,149 INFO: errors [in C:/Projects/Udacity/Python/Fyyur/app.py:542]
2020-09-20 23:32:46,422 INFO: errors [in C:/Projects/Udacity/Python/Fyyur/app.py:554]
2020-09-20 23:33:07,687 INFO: errors [in C:/Projects/Udacity/Python/Fyyur/app.py:556]
2020-09-20 23:34:34,172 INFO: errors [in C:/Projects/Udacity/Python/Fyyur/app.py:557]
2020-09-20 23:37:25,186 INFO: errors [in C:/Projects/Udacity/Python/Fyyur/app.py:560]
2020-09-20 23:45:43,797 INFO: errors [in C:/Projects/Udacity/Python/Fyyur/app.py:584]
2020-09-20 23:47:07,733 INFO: errors [in C:/Projects/Udacity/Python/Fyyur/app.py:584]
2020-09-20 23:49:17,157 ERROR: Exception on /venues/3 [GET] [in C:\Users\Major Ahmed\AppData\Local\Programs\Python\Python37\lib\site-packages\flask\app.py:1892]
Traceback (most recent call last):
  File "C:\Users\Major Ahmed\AppData\Local\Programs\Python\Python37\lib\site-packages\flask\app.py", line 2447, in wsgi_app
    response = self.full_dispatch_request()
  File "C:\Users\Major Ahmed\AppData\Local\Programs\Python\Python37\lib\site-packages\flask\app.py", line 1952, in full_dispatch_request
    rv = self.handle_user_exception(e)
  File "C:\Users\Major Ahmed\AppData\Local\Programs\Python\Python37\lib\site-packages\flask\app.py", line 1821, in handle_user_exception
    reraise(exc_type, exc_value, tb)
  File "C:\Users\Major Ahmed\AppData\Local\Programs\Python\Python37\lib\site-packages\flask\_compat.py", line 39, in reraise
    raise value
  File "C:\Users\Major Ahmed\AppData\Local\Programs\Python\Python37\lib\site-packages\flask\app.py", line 1950, in full_dispatch_request
    rv = self.dispatch_request()
  File "C:\Users\Major Ahmed\AppData\Local\Programs\Python\Python37\lib\site-packages\flask\app.py", line 1936, in dispatch_request
    return self.view_functions[rule.endpoint](**req.view_args)
  File "C:/Projects/Udacity/Python/Fyyur/app.py", line 287, in show_venue
    return render_template('pages/show_venue.html', venue=data)
  File "C:\Users\Major Ahmed\AppData\Local\Programs\Python\Python37\lib\site-packages\flask\templating.py", line 140, in render_template
    ctx.app,
  File "C:\Users\Major Ahmed\AppData\Local\Programs\Python\Python37\lib\site-packages\flask\templating.py", line 120, in _render
    rv = template.render(context)
  File "C:\Users\Major Ahmed\AppData\Local\Programs\Python\Python37\lib\site-packages\jinja2\environment.py", line 1090, in render
    self.environment.handle_exception()
  File "C:\Users\Major Ahmed\AppData\Local\Programs\Python\Python37\lib\site-packages\jinja2\environment.py", line 832, in handle_exception
    reraise(*rewrite_traceback_stack(source=source))
  File "C:\Users\Major Ahmed\AppData\Local\Programs\Python\Python37\lib\site-packages\jinja2\_compat.py", line 28, in reraise
    raise value.with_traceback(tb)
  File "C:\Projects\Udacity\Python\Fyyur\templates\pages\show_venue.html", line 1, in top-level template code
    {% extends 'layouts/main.html' %}
  File "C:\Projects\Udacity\Python\Fyyur\templates\layouts\main.html", line 103, in top-level template code
    {% block content %}{% endblock %}
  File "C:\Projects\Udacity\Python\Fyyur\templates\pages\show_venue.html", line 57, in block "content"
    <h6>{{ show.start_time|datetime('full') }}</h6>
  File "C:/Projects/Udacity/Python/Fyyur/app.py", line 126, in format_datetime
    return babel.dates.format_datetime(date, format)
  File "C:\Users\Major Ahmed\AppData\Local\Programs\Python\Python37\lib\site-packages\babel\dates.py", line 738, in format_datetime
    return parse_pattern(format).apply(datetime, locale)
  File "C:\Users\Major Ahmed\AppData\Local\Programs\Python\Python37\lib\site-packages\babel\dates.py", line 1232, in apply
    return self % DateTimeFormat(datetime, locale)
  File "C:\Users\Major Ahmed\AppData\Local\Programs\Python\Python37\lib\site-packages\babel\dates.py", line 1229, in __mod__
    return self.format % other
  File "C:\Users\Major Ahmed\AppData\Local\Programs\Python\Python37\lib\site-packages\babel\dates.py", line 1264, in __getitem__
    return self.format_weekday(char, num)
  File "C:\Users\Major Ahmed\AppData\Local\Programs\Python\Python37\lib\site-packages\babel\dates.py", line 1397, in format_weekday
    return get_day_names(width, context, self.locale)[weekday]
  File "C:\Users\Major Ahmed\AppData\Local\Programs\Python\Python37\lib\site-packages\babel\dates.py", line 314, in get_day_names
    return Locale.parse(locale).days[context][width]
AttributeError: 'NoneType' object has no attribute 'days'
2020-09-20 23:49:33,695 ERROR: Exception on /venues/3 [GET] [in C:\Users\Major Ahmed\AppData\Local\Programs\Python\Python37\lib\site-packages\flask\app.py:1892]
Traceback (most recent call last):
  File "C:\Users\Major Ahmed\AppData\Local\Programs\Python\Python37\lib\site-packages\flask\app.py", line 2447, in wsgi_app
    response = self.full_dispatch_request()
  File "C:\Users\Major Ahmed\AppData\Local\Programs\Python\Python37\lib\site-packages\flask\app.py", line 1952, in full_dispatch_request
    rv = self.handle_user_exception(e)
  File "C:\Users\Major Ahmed\AppData\Local\Programs\Python\Python37\lib\site-packages\flask\app.py", line 1821, in handle_user_exception
    reraise(exc_type, exc_value, tb)
  File "C:\Users\Major Ahmed\AppData\Local\Programs\Python\Python37\lib\site-packages\flask\_compat.py", line 39, in reraise
    raise value
  File "C:\Users\Major Ahmed\AppData\Local\Programs\Python\Python37\lib\site-packages\flask\app.py", line 1950, in full_dispatch_request
    rv = self.dispatch_request()
  File "C:\Users\Major Ahmed\AppData\Local\Programs\Python\Python37\lib\site-packages\flask\app.py", line 1936, in dispatch_request
    return self.view_functions[rule.endpoint](**req.view_args)
  File "C:/Projects/Udacity/Python/Fyyur/app.py", line 287, in show_venue
    return render_template('pages/show_venue.html', venue=data)
  File "C:\Users\Major Ahmed\AppData\Local\Programs\Python\Python37\lib\site-packages\flask\templating.py", line 140, in render_template
    ctx.app,
  File "C:\Users\Major Ahmed\AppData\Local\Programs\Python\Python37\lib\site-packages\flask\templating.py", line 120, in _render
    rv = template.render(context)
  File "C:\Users\Major Ahmed\AppData\Local\Programs\Python\Python37\lib\site-packages\jinja2\environment.py", line 1090, in render
    self.environment.handle_exception()
  File "C:\Users\Major Ahmed\AppData\Local\Programs\Python\Python37\lib\site-packages\jinja2\environment.py", line 832, in handle_exception
    reraise(*rewrite_traceback_stack(source=source))
  File "C:\Users\Major Ahmed\AppData\Local\Programs\Python\Python37\lib\site-packages\jinja2\_compat.py", line 28, in reraise
    raise value.with_traceback(tb)
  File "C:\Projects\Udacity\Python\Fyyur\templates\pages\show_venue.html", line 1, in top-level template code
    {% extends 'layouts/main.html' %}
  File "C:\Projects\Udacity\Python\Fyyur\templates\layouts\main.html", line 103, in top-level template code
    {% block content %}{% endblock %}
  File "C:\Projects\Udacity\Python\Fyyur\templates\pages\show_venue.html", line 57, in block "content"
    <h6>{{ show.start_time|datetime('full') }}</h6>
  File "C:/Projects/Udacity/Python/Fyyur/app.py", line 126, in format_datetime
    return babel.dates.format_datetime(date, format)
  File "C:\Users\Major Ahmed\AppData\Local\Programs\Python\Python37\lib\site-packages\babel\dates.py", line 738, in format_datetime
    return parse_pattern(format).apply(datetime, locale)
  File "C:\Users\Major Ahmed\AppData\Local\Programs\Python\Python37\lib\site-packages\babel\dates.py", line 1232, in apply
    return self % DateTimeFormat(datetime, locale)
  File "C:\Users\Major Ahmed\AppData\Local\Programs\Python\Python37\lib\site-packages\babel\dates.py", line 1229, in __mod__
    return self.format % other
  File "C:\Users\Major Ahmed\AppData\Local\Programs\Python\Python37\lib\site-packages\babel\dates.py", line 1264, in __getitem__
    return self.format_weekday(char, num)
  File "C:\Users\Major Ahmed\AppData\Local\Programs\Python\Python37\lib\site-packages\babel\dates.py", line 1397, in format_weekday
    return get_day_names(width, context, self.locale)[weekday]
  File "C:\Users\Major Ahmed\AppData\Local\Programs\Python\Python37\lib\site-packages\babel\dates.py", line 314, in get_day_names
    return Locale.parse(locale).days[context][width]
AttributeError: 'NoneType' object has no attribute 'days'
2020-09-20 23:49:35,375 ERROR: Exception on /venues/6 [GET] [in C:\Users\Major Ahmed\AppData\Local\Programs\Python\Python37\lib\site-packages\flask\app.py:1892]
Traceback (most recent call last):
  File "C:\Users\Major Ahmed\AppData\Local\Programs\Python\Python37\lib\site-packages\flask\app.py", line 2447, in wsgi_app
    response = self.full_dispatch_request()
  File "C:\Users\Major Ahmed\AppData\Local\Programs\Python\Python37\lib\site-packages\flask\app.py", line 1952, in full_dispatch_request
    rv = self.handle_user_exception(e)
  File "C:\Users\Major Ahmed\AppData\Local\Programs\Python\Python37\lib\site-packages\flask\app.py", line 1821, in handle_user_exception
    reraise(exc_type, exc_value, tb)
  File "C:\Users\Major Ahmed\AppData\Local\Programs\Python\Python37\lib\site-packages\flask\_compat.py", line 39, in reraise
    raise value
  File "C:\Users\Major Ahmed\AppData\Local\Programs\Python\Python37\lib\site-packages\flask\app.py", line 1950, in full_dispatch_request
    rv = self.dispatch_request()
  File "C:\Users\Major Ahmed\AppData\Local\Programs\Python\Python37\lib\site-packages\flask\app.py", line 1936, in dispatch_request
    return self.view_functions[rule.endpoint](**req.view_args)
  File "C:/Projects/Udacity/Python/Fyyur/app.py", line 286, in show_venue
    data = list(filter(lambda d: d['id'] == venue_id, [data1, data2, data3]))[0]
IndexError: list index out of range
2020-09-20 23:49:37,328 ERROR: Exception on /venues/1 [GET] [in C:\Users\Major Ahmed\AppData\Local\Programs\Python\Python37\lib\site-packages\flask\app.py:1892]
Traceback (most recent call last):
  File "C:\Users\Major Ahmed\AppData\Local\Programs\Python\Python37\lib\site-packages\flask\app.py", line 2447, in wsgi_app
    response = self.full_dispatch_request()
  File "C:\Users\Major Ahmed\AppData\Local\Programs\Python\Python37\lib\site-packages\flask\app.py", line 1952, in full_dispatch_request
    rv = self.handle_user_exception(e)
  File "C:\Users\Major Ahmed\AppData\Local\Programs\Python\Python37\lib\site-packages\flask\app.py", line 1821, in handle_user_exception
    reraise(exc_type, exc_value, tb)
  File "C:\Users\Major Ahmed\AppData\Local\Programs\Python\Python37\lib\site-packages\flask\_compat.py", line 39, in reraise
    raise value
  File "C:\Users\Major Ahmed\AppData\Local\Programs\Python\Python37\lib\site-packages\flask\app.py", line 1950, in full_dispatch_request
    rv = self.dispatch_request()
  File "C:\Users\Major Ahmed\AppData\Local\Programs\Python\Python37\lib\site-packages\flask\app.py", line 1936, in dispatch_request
    return self.view_functions[rule.endpoint](**req.view_args)
  File "C:/Projects/Udacity/Python/Fyyur/app.py", line 287, in show_venue
    return render_template('pages/show_venue.html', venue=data)
  File "C:\Users\Major Ahmed\AppData\Local\Programs\Python\Python37\lib\site-packages\flask\templating.py", line 140, in render_template
    ctx.app,
  File "C:\Users\Major Ahmed\AppData\Local\Programs\Python\Python37\lib\site-packages\flask\templating.py", line 120, in _render
    rv = template.render(context)
  File "C:\Users\Major Ahmed\AppData\Local\Programs\Python\Python37\lib\site-packages\jinja2\environment.py", line 1090, in render
    self.environment.handle_exception()
  File "C:\Users\Major Ahmed\AppData\Local\Programs\Python\Python37\lib\site-packages\jinja2\environment.py", line 832, in handle_exception
    reraise(*rewrite_traceback_stack(source=source))
  File "C:\Users\Major Ahmed\AppData\Local\Programs\Python\Python37\lib\site-packages\jinja2\_compat.py", line 28, in reraise
    raise value.with_traceback(tb)
  File "C:\Projects\Udacity\Python\Fyyur\templates\pages\show_venue.html", line 1, in top-level template code
    {% extends 'layouts/main.html' %}
  File "C:\Projects\Udacity\Python\Fyyur\templates\layouts\main.html", line 103, in top-level template code
    {% block content %}{% endblock %}
  File "C:\Projects\Udacity\Python\Fyyur\templates\pages\show_venue.html", line 71, in block "content"
    <h6>{{ show.start_time|datetime('full') }}</h6>
  File "C:/Projects/Udacity/Python/Fyyur/app.py", line 126, in format_datetime
    return babel.dates.format_datetime(date, format)
  File "C:\Users\Major Ahmed\AppData\Local\Programs\Python\Python37\lib\site-packages\babel\dates.py", line 738, in format_datetime
    return parse_pattern(format).apply(datetime, locale)
  File "C:\Users\Major Ahmed\AppData\Local\Programs\Python\Python37\lib\site-packages\babel\dates.py", line 1232, in apply
    return self % DateTimeFormat(datetime, locale)
  File "C:\Users\Major Ahmed\AppData\Local\Programs\Python\Python37\lib\site-packages\babel\dates.py", line 1229, in __mod__
    return self.format % other
  File "C:\Users\Major Ahmed\AppData\Local\Programs\Python\Python37\lib\site-packages\babel\dates.py", line 1264, in __getitem__
    return self.format_weekday(char, num)
  File "C:\Users\Major Ahmed\AppData\Local\Programs\Python\Python37\lib\site-packages\babel\dates.py", line 1397, in format_weekday
    return get_day_names(width, context, self.locale)[weekday]
  File "C:\Users\Major Ahmed\AppData\Local\Programs\Python\Python37\lib\site-packages\babel\dates.py", line 314, in get_day_names
    return Locale.parse(locale).days[context][width]
AttributeError: 'NoneType' object has no attribute 'days'
2020-09-20 23:49:42,680 ERROR: Exception on /venues/4 [GET] [in C:\Users\Major Ahmed\AppData\Local\Programs\Python\Python37\lib\site-packages\flask\app.py:1892]
Traceback (most recent call last):
  File "C:\Users\Major Ahmed\AppData\Local\Programs\Python\Python37\lib\site-packages\flask\app.py", line 2447, in wsgi_app
    response = self.full_dispatch_request()
  File "C:\Users\Major Ahmed\AppData\Local\Programs\Python\Python37\lib\site-packages\flask\app.py", line 1952, in full_dispatch_request
    rv = self.handle_user_exception(e)
  File "C:\Users\Major Ahmed\AppData\Local\Programs\Python\Python37\lib\site-packages\flask\app.py", line 1821, in handle_user_exception
    reraise(exc_type, exc_value, tb)
  File "C:\Users\Major Ahmed\AppData\Local\Programs\Python\Python37\lib\site-packages\flask\_compat.py", line 39, in reraise
    raise value
  File "C:\Users\Major Ahmed\AppData\Local\Programs\Python\Python37\lib\site-packages\flask\app.py", line 1950, in full_dispatch_request
    rv = self.dispatch_request()
  File "C:\Users\Major Ahmed\AppData\Local\Programs\Python\Python37\lib\site-packages\flask\app.py", line 1936, in dispatch_request
    return self.view_functions[rule.endpoint](**req.view_args)
  File "C:/Projects/Udacity/Python/Fyyur/app.py", line 286, in show_venue
    data = list(filter(lambda d: d['id'] == venue_id, [data1, data2, data3]))[0]
IndexError: list index out of range
2020-09-20 23:49:44,591 ERROR: Exception on /venues/5 [GET] [in C:\Users\Major Ahmed\AppData\Local\Programs\Python\Python37\lib\site-packages\flask\app.py:1892]
Traceback (most recent call last):
  File "C:\Users\Major Ahmed\AppData\Local\Programs\Python\Python37\lib\site-packages\flask\app.py", line 2447, in wsgi_app
    response = self.full_dispatch_request()
  File "C:\Users\Major Ahmed\AppData\Local\Programs\Python\Python37\lib\site-packages\flask\app.py", line 1952, in full_dispatch_request
    rv = self.handle_user_exception(e)
  File "C:\Users\Major Ahmed\AppData\Local\Programs\Python\Python37\lib\site-packages\flask\app.py", line 1821, in handle_user_exception
    reraise(exc_type, exc_value, tb)
  File "C:\Users\Major Ahmed\AppData\Local\Programs\Python\Python37\lib\site-packages\flask\_compat.py", line 39, in reraise
    raise value
  File "C:\Users\Major Ahmed\AppData\Local\Programs\Python\Python37\lib\site-packages\flask\app.py", line 1950, in full_dispatch_request
    rv = self.dispatch_request()
  File "C:\Users\Major Ahmed\AppData\Local\Programs\Python\Python37\lib\site-packages\flask\app.py", line 1936, in dispatch_request
    return self.view_functions[rule.endpoint](**req.view_args)
  File "C:/Projects/Udacity/Python/Fyyur/app.py", line 286, in show_venue
    data = list(filter(lambda d: d['id'] == venue_id, [data1, data2, data3]))[0]
IndexError: list index out of range
2020-09-20 23:58:05,409 INFO: errors [in C:/Projects/Udacity/Python/Fyyur/app.py:564]
2020-09-20 23:58:12,677 ERROR: Exception on /venues/search [POST] [in C:\Users\Major Ahmed\AppData\Local\Programs\Python\Python37\lib\site-packages\flask\app.py:1892]
Traceback (most recent call last):
  File "C:\Users\Major Ahmed\AppData\Local\Programs\Python\Python37\lib\site-packages\flask\app.py", line 2447, in wsgi_app
    response = self.full_dispatch_request()
  File "C:\Users\Major Ahmed\AppData\Local\Programs\Python\Python37\lib\site-packages\flask\app.py", line 1952, in full_dispatch_request
    rv = self.handle_user_exception(e)
  File "C:\Users\Major Ahmed\AppData\Local\Programs\Python\Python37\lib\site-packages\flask\app.py", line 1821, in handle_user_exception
    reraise(exc_type, exc_value, tb)
  File "C:\Users\Major Ahmed\AppData\Local\Programs\Python\Python37\lib\site-packages\flask\_compat.py", line 39, in reraise
    raise value
  File "C:\Users\Major Ahmed\AppData\Local\Programs\Python\Python37\lib\site-packages\flask\app.py", line 1950, in full_dispatch_request
    rv = self.dispatch_request()
  File "C:\Users\Major Ahmed\AppData\Local\Programs\Python\Python37\lib\site-packages\flask\app.py", line 1936, in dispatch_request
    return self.view_functions[rule.endpoint](**req.view_args)
  File "C:/Projects/Udacity/Python/Fyyur/app.py", line 174, in search_venues
    print(rerquest.get_json())
NameError: name 'rerquest' is not defined
2020-09-20 23:58:38,892 INFO: errors [in C:/Projects/Udacity/Python/Fyyur/app.py:564]
2020-09-20 23:59:30,462 INFO: errors [in C:/Projects/Udacity/Python/Fyyur/app.py:564]
2020-09-21 00:04:34,612 INFO: errors [in C:/Projects/Udacity/Python/Fyyur/app.py:566]
2020-09-21 00:07:40,988 INFO: errors [in C:/Projects/Udacity/Python/Fyyur/app.py:570]
2020-09-21 00:13:06,712 INFO: errors [in C:/Projects/Udacity/Python/Fyyur/app.py:562]
2020-09-21 00:13:22,510 ERROR: Exception on /venues/6 [GET] [in C:\Users\Major Ahmed\AppData\Local\Programs\Python\Python37\lib\site-packages\flask\app.py:1892]
Traceback (most recent call last):
  File "C:\Users\Major Ahmed\AppData\Local\Programs\Python\Python37\lib\site-packages\flask\app.py", line 2447, in wsgi_app
    response = self.full_dispatch_request()
  File "C:\Users\Major Ahmed\AppData\Local\Programs\Python\Python37\lib\site-packages\flask\app.py", line 1952, in full_dispatch_request
    rv = self.handle_user_exception(e)
  File "C:\Users\Major Ahmed\AppData\Local\Programs\Python\Python37\lib\site-packages\flask\app.py", line 1821, in handle_user_exception
    reraise(exc_type, exc_value, tb)
  File "C:\Users\Major Ahmed\AppData\Local\Programs\Python\Python37\lib\site-packages\flask\_compat.py", line 39, in reraise
    raise value
  File "C:\Users\Major Ahmed\AppData\Local\Programs\Python\Python37\lib\site-packages\flask\app.py", line 1950, in full_dispatch_request
    rv = self.dispatch_request()
  File "C:\Users\Major Ahmed\AppData\Local\Programs\Python\Python37\lib\site-packages\flask\app.py", line 1936, in dispatch_request
    return self.view_functions[rule.endpoint](**req.view_args)
  File "C:/Projects/Udacity/Python/Fyyur/app.py", line 263, in show_venue
    data = list(filter(lambda d: d['id'] == venue_id, [data1, data2, data3]))[0]
IndexError: list index out of range
2020-09-21 00:13:33,452 ERROR: Exception on /venues/4 [GET] [in C:\Users\Major Ahmed\AppData\Local\Programs\Python\Python37\lib\site-packages\flask\app.py:1892]
Traceback (most recent call last):
  File "C:\Users\Major Ahmed\AppData\Local\Programs\Python\Python37\lib\site-packages\flask\app.py", line 2447, in wsgi_app
    response = self.full_dispatch_request()
  File "C:\Users\Major Ahmed\AppData\Local\Programs\Python\Python37\lib\site-packages\flask\app.py", line 1952, in full_dispatch_request
    rv = self.handle_user_exception(e)
  File "C:\Users\Major Ahmed\AppData\Local\Programs\Python\Python37\lib\site-packages\flask\app.py", line 1821, in handle_user_exception
    reraise(exc_type, exc_value, tb)
  File "C:\Users\Major Ahmed\AppData\Local\Programs\Python\Python37\lib\site-packages\flask\_compat.py", line 39, in reraise
    raise value
  File "C:\Users\Major Ahmed\AppData\Local\Programs\Python\Python37\lib\site-packages\flask\app.py", line 1950, in full_dispatch_request
    rv = self.dispatch_request()
  File "C:\Users\Major Ahmed\AppData\Local\Programs\Python\Python37\lib\site-packages\flask\app.py", line 1936, in dispatch_request
    return self.view_functions[rule.endpoint](**req.view_args)
  File "C:/Projects/Udacity/Python/Fyyur/app.py", line 263, in show_venue
    data = list(filter(lambda d: d['id'] == venue_id, [data1, data2, data3]))[0]
IndexError: list index out of range
2020-09-21 00:13:35,065 ERROR: Exception on /venues/4 [GET] [in C:\Users\Major Ahmed\AppData\Local\Programs\Python\Python37\lib\site-packages\flask\app.py:1892]
Traceback (most recent call last):
  File "C:\Users\Major Ahmed\AppData\Local\Programs\Python\Python37\lib\site-packages\flask\app.py", line 2447, in wsgi_app
    response = self.full_dispatch_request()
  File "C:\Users\Major Ahmed\AppData\Local\Programs\Python\Python37\lib\site-packages\flask\app.py", line 1952, in full_dispatch_request
    rv = self.handle_user_exception(e)
  File "C:\Users\Major Ahmed\AppData\Local\Programs\Python\Python37\lib\site-packages\flask\app.py", line 1821, in handle_user_exception
    reraise(exc_type, exc_value, tb)
  File "C:\Users\Major Ahmed\AppData\Local\Programs\Python\Python37\lib\site-packages\flask\_compat.py", line 39, in reraise
    raise value
  File "C:\Users\Major Ahmed\AppData\Local\Programs\Python\Python37\lib\site-packages\flask\app.py", line 1950, in full_dispatch_request
    rv = self.dispatch_request()
  File "C:\Users\Major Ahmed\AppData\Local\Programs\Python\Python37\lib\site-packages\flask\app.py", line 1936, in dispatch_request
    return self.view_functions[rule.endpoint](**req.view_args)
  File "C:/Projects/Udacity/Python/Fyyur/app.py", line 263, in show_venue
    data = list(filter(lambda d: d['id'] == venue_id, [data1, data2, data3]))[0]
IndexError: list index out of range
2020-09-21 00:13:43,337 ERROR: Exception on /venues/5 [GET] [in C:\Users\Major Ahmed\AppData\Local\Programs\Python\Python37\lib\site-packages\flask\app.py:1892]
Traceback (most recent call last):
  File "C:\Users\Major Ahmed\AppData\Local\Programs\Python\Python37\lib\site-packages\flask\app.py", line 2447, in wsgi_app
    response = self.full_dispatch_request()
  File "C:\Users\Major Ahmed\AppData\Local\Programs\Python\Python37\lib\site-packages\flask\app.py", line 1952, in full_dispatch_request
    rv = self.handle_user_exception(e)
  File "C:\Users\Major Ahmed\AppData\Local\Programs\Python\Python37\lib\site-packages\flask\app.py", line 1821, in handle_user_exception
    reraise(exc_type, exc_value, tb)
  File "C:\Users\Major Ahmed\AppData\Local\Programs\Python\Python37\lib\site-packages\flask\_compat.py", line 39, in reraise
    raise value
  File "C:\Users\Major Ahmed\AppData\Local\Programs\Python\Python37\lib\site-packages\flask\app.py", line 1950, in full_dispatch_request
    rv = self.dispatch_request()
  File "C:\Users\Major Ahmed\AppData\Local\Programs\Python\Python37\lib\site-packages\flask\app.py", line 1936, in dispatch_request
    return self.view_functions[rule.endpoint](**req.view_args)
  File "C:/Projects/Udacity/Python/Fyyur/app.py", line 263, in show_venue
    data = list(filter(lambda d: d['id'] == venue_id, [data1, data2, data3]))[0]
IndexError: list index out of range
2020-09-21 00:14:38,046 INFO: errors [in C:/Projects/Udacity/Python/Fyyur/app.py:485]
2020-09-21 00:46:47,800 INFO: errors [in C:\Projects\Udacity\Python\Fyyur\app.py:494]
2020-09-21 00:46:55,796 INFO: errors [in C:\Projects\Udacity\Python\Fyyur\app.py:494]
2020-09-21 00:54:51,163 INFO: errors [in C:/Projects/Udacity/Python/Fyyur/app.py:514]
2020-09-21 00:55:49,664 INFO: errors [in C:/Projects/Udacity/Python/Fyyur/app.py:514]
2020-09-21 01:14:37,813 INFO: errors [in C:\Projects\Udacity\Python\Fyyur\app.py:485]
2020-09-21 01:14:42,769 INFO: errors [in C:\Projects\Udacity\Python\Fyyur\app.py:485]
2020-09-21 01:14:51,867 INFO: errors [in C:/Projects/Udacity/Python/Fyyur/app.py:504]
2020-09-21 01:25:15,820 INFO: errors [in C:/Projects/Udacity/Python/Fyyur/app.py:493]
2020-09-21 13:32:21,261 INFO: errors [in C:/Projects/Udacity/Python/Fyyur/app.py:493]
2020-09-21 13:41:24,572 INFO: errors [in C:/Projects/Udacity/Python/Fyyur/app.py:503]
2020-09-21 13:41:37,995 ERROR: Exception on /venues [GET] [in C:\Users\Major Ahmed\AppData\Local\Programs\Python\Python37\lib\site-packages\flask\app.py:1892]
Traceback (most recent call last):
  File "C:\Users\Major Ahmed\AppData\Local\Programs\Python\Python37\lib\site-packages\flask\app.py", line 2447, in wsgi_app
    response = self.full_dispatch_request()
  File "C:\Users\Major Ahmed\AppData\Local\Programs\Python\Python37\lib\site-packages\flask\app.py", line 1952, in full_dispatch_request
    rv = self.handle_user_exception(e)
  File "C:\Users\Major Ahmed\AppData\Local\Programs\Python\Python37\lib\site-packages\flask\app.py", line 1821, in handle_user_exception
    reraise(exc_type, exc_value, tb)
  File "C:\Users\Major Ahmed\AppData\Local\Programs\Python\Python37\lib\site-packages\flask\_compat.py", line 39, in reraise
    raise value
  File "C:\Users\Major Ahmed\AppData\Local\Programs\Python\Python37\lib\site-packages\flask\app.py", line 1950, in full_dispatch_request
    rv = self.dispatch_request()
  File "C:\Users\Major Ahmed\AppData\Local\Programs\Python\Python37\lib\site-packages\flask\app.py", line 1936, in dispatch_request
    return self.view_functions[rule.endpoint](**req.view_args)
  File "C:/Projects/Udacity/Python/Fyyur/app.py", line 164, in venues
    states.append(state)
NameError: name 'state' is not defined
2020-09-21 13:42:08,151 INFO: errors [in C:/Projects/Udacity/Python/Fyyur/app.py:503]
2020-09-21 13:42:16,290 ERROR: Exception on /venues [GET] [in C:\Users\Major Ahmed\AppData\Local\Programs\Python\Python37\lib\site-packages\flask\app.py:1892]
Traceback (most recent call last):
  File "C:\Users\Major Ahmed\AppData\Local\Programs\Python\Python37\lib\site-packages\flask\app.py", line 2447, in wsgi_app
    response = self.full_dispatch_request()
  File "C:\Users\Major Ahmed\AppData\Local\Programs\Python\Python37\lib\site-packages\flask\app.py", line 1952, in full_dispatch_request
    rv = self.handle_user_exception(e)
  File "C:\Users\Major Ahmed\AppData\Local\Programs\Python\Python37\lib\site-packages\flask\app.py", line 1821, in handle_user_exception
    reraise(exc_type, exc_value, tb)
  File "C:\Users\Major Ahmed\AppData\Local\Programs\Python\Python37\lib\site-packages\flask\_compat.py", line 39, in reraise
    raise value
  File "C:\Users\Major Ahmed\AppData\Local\Programs\Python\Python37\lib\site-packages\flask\app.py", line 1950, in full_dispatch_request
    rv = self.dispatch_request()
  File "C:\Users\Major Ahmed\AppData\Local\Programs\Python\Python37\lib\site-packages\flask\app.py", line 1936, in dispatch_request
    return self.view_functions[rule.endpoint](**req.view_args)
  File "C:/Projects/Udacity/Python/Fyyur/app.py", line 173, in venues
    for show in ven.shows:
AttributeError: 'list' object has no attribute 'shows'
2020-09-21 13:44:27,857 INFO: errors [in C:/Projects/Udacity/Python/Fyyur/app.py:504]
2020-09-21 13:44:35,161 ERROR: Exception on /venues [GET] [in C:\Users\Major Ahmed\AppData\Local\Programs\Python\Python37\lib\site-packages\flask\app.py:1892]
Traceback (most recent call last):
  File "C:\Users\Major Ahmed\AppData\Local\Programs\Python\Python37\lib\site-packages\flask\app.py", line 2447, in wsgi_app
    response = self.full_dispatch_request()
  File "C:\Users\Major Ahmed\AppData\Local\Programs\Python\Python37\lib\site-packages\flask\app.py", line 1952, in full_dispatch_request
    rv = self.handle_user_exception(e)
  File "C:\Users\Major Ahmed\AppData\Local\Programs\Python\Python37\lib\site-packages\flask\app.py", line 1821, in handle_user_exception
    reraise(exc_type, exc_value, tb)
  File "C:\Users\Major Ahmed\AppData\Local\Programs\Python\Python37\lib\site-packages\flask\_compat.py", line 39, in reraise
    raise value
  File "C:\Users\Major Ahmed\AppData\Local\Programs\Python\Python37\lib\site-packages\flask\app.py", line 1950, in full_dispatch_request
    rv = self.dispatch_request()
  File "C:\Users\Major Ahmed\AppData\Local\Programs\Python\Python37\lib\site-packages\flask\app.py", line 1936, in dispatch_request
    return self.view_functions[rule.endpoint](**req.view_args)
  File "C:/Projects/Udacity/Python/Fyyur/app.py", line 177, in venues
    ven["num_upcoming_shows"] = upcoming_shows
TypeError: 'Venue' object does not support item assignment
2020-09-21 13:47:48,874 INFO: errors [in C:/Projects/Udacity/Python/Fyyur/app.py:504]
2020-09-21 13:48:24,771 INFO: errors [in C:/Projects/Udacity/Python/Fyyur/app.py:512]
2020-09-21 13:49:36,662 INFO: errors [in C:/Projects/Udacity/Python/Fyyur/app.py:516]
2020-09-21 13:50:12,724 INFO: errors [in C:/Projects/Udacity/Python/Fyyur/app.py:516]
2020-09-21 13:55:19,936 INFO: errors [in C:/Projects/Udacity/Python/Fyyur/app.py:505]
2020-09-21 13:56:20,890 INFO: errors [in C:/Projects/Udacity/Python/Fyyur/app.py:505]
2020-09-21 13:56:33,973 INFO: errors [in C:/Projects/Udacity/Python/Fyyur/app.py:505]
2020-09-21 13:56:46,686 INFO: errors [in C:/Projects/Udacity/Python/Fyyur/app.py:505]
2020-09-21 13:57:34,424 INFO: errors [in C:/Projects/Udacity/Python/Fyyur/app.py:505]
2020-09-21 13:58:21,621 INFO: errors [in C:/Projects/Udacity/Python/Fyyur/app.py:515]
2020-09-21 14:00:48,467 INFO: errors [in C:/Projects/Udacity/Python/Fyyur/app.py:524]
2020-09-21 14:09:20,193 INFO: errors [in C:/Projects/Udacity/Python/Fyyur/app.py:525]
2020-09-21 14:09:44,452 INFO: errors [in C:/Projects/Udacity/Python/Fyyur/app.py:529]
2020-09-21 14:11:24,879 INFO: errors [in C:/Projects/Udacity/Python/Fyyur/app.py:529]
2020-09-21 14:14:14,128 INFO: errors [in C:/Projects/Udacity/Python/Fyyur/app.py:529]
2020-09-21 14:17:39,547 INFO: errors [in C:/Projects/Udacity/Python/Fyyur/app.py:530]
2020-09-21 14:19:35,573 INFO: errors [in C:/Projects/Udacity/Python/Fyyur/app.py:529]
2020-09-21 14:23:15,837 INFO: errors [in C:/Projects/Udacity/Python/Fyyur/app.py:529]
2020-09-21 14:25:39,677 INFO: errors [in C:/Projects/Udacity/Python/Fyyur/app.py:528]
2020-09-21 14:26:41,544 INFO: errors [in C:/Projects/Udacity/Python/Fyyur/app.py:528]
2020-09-21 14:27:21,711 INFO: errors [in C:/Projects/Udacity/Python/Fyyur/app.py:528]
2020-09-21 14:27:56,946 INFO: errors [in C:/Projects/Udacity/Python/Fyyur/app.py:529]
2020-09-21 14:30:41,505 INFO: errors [in C:/Projects/Udacity/Python/Fyyur/app.py:529]
2020-09-21 14:35:40,459 INFO: errors [in C:/Projects/Udacity/Python/Fyyur/app.py:529]
2020-09-21 14:37:40,514 INFO: errors [in C:/Projects/Udacity/Python/Fyyur/app.py:529]
2020-09-21 14:39:07,069 INFO: errors [in C:/Projects/Udacity/Python/Fyyur/app.py:530]
2020-09-21 14:39:23,599 INFO: errors [in C:/Projects/Udacity/Python/Fyyur/app.py:530]
2020-09-21 14:39:52,275 INFO: errors [in C:/Projects/Udacity/Python/Fyyur/app.py:531]
2020-09-21 14:40:17,597 INFO: errors [in C:/Projects/Udacity/Python/Fyyur/app.py:531]
2020-09-21 14:41:30,112 INFO: errors [in C:/Projects/Udacity/Python/Fyyur/app.py:530]
2020-09-21 14:42:15,504 INFO: errors [in C:/Projects/Udacity/Python/Fyyur/app.py:530]
2020-09-21 14:43:19,467 INFO: errors [in C:/Projects/Udacity/Python/Fyyur/app.py:526]
2020-09-21 14:43:39,195 INFO: errors [in C:/Projects/Udacity/Python/Fyyur/app.py:527]
2020-09-21 14:44:32,372 INFO: errors [in C:/Projects/Udacity/Python/Fyyur/app.py:526]
2020-09-21 14:45:27,697 INFO: errors [in C:/Projects/Udacity/Python/Fyyur/app.py:526]
2020-09-21 14:46:15,582 INFO: errors [in C:/Projects/Udacity/Python/Fyyur/app.py:526]
2020-09-21 14:47:04,864 INFO: errors [in C:/Projects/Udacity/Python/Fyyur/app.py:527]
2020-09-21 14:55:44,493 INFO: errors [in C:/Projects/Udacity/Python/Fyyur/app.py:528]
2020-09-21 15:00:54,738 INFO: errors [in C:/Projects/Udacity/Python/Fyyur/app.py:530]
2020-09-21 15:01:05,128 INFO: errors [in C:/Projects/Udacity/Python/Fyyur/app.py:529]
2020-09-21 15:07:07,589 INFO: errors [in C:/Projects/Udacity/Python/Fyyur/app.py:532]
2020-09-21 15:58:29,132 INFO: errors [in C:/Projects/Udacity/Python/Fyyur/app.py:539]
2020-09-21 16:04:59,084 INFO: errors [in C:\Projects\Udacity\Python\Fyyur\app.py:519]
2020-09-21 16:05:21,800 INFO: errors [in C:\Projects\Udacity\Python\Fyyur\app.py:519]
