
2020-09-20 22:58:14,960 INFO: errors [in C:/Projects/Udacity/Python/Fyyur/app.py:542]
2020-09-20 22:58:45,149 INFO: errors [in C:/Projects/Udacity/Python/Fyyur/app.py:542]
2020-09-20 23:32:46,422 INFO: errors [in C:/Projects/Udacity/Python/Fyyur/app.py:554]
2020-09-20 23:33:07,687 INFO: errors [in C:/Projects/Udacity/Python/Fyyur/app.py:556]
2020-09-20 23:34:34,172 INFO: errors [in C:/Projects/Udacity/Python/Fyyur/app.py:557]
2020-09-20 23:37:25,186 INFO: errors [in C:/Projects/Udacity/Python/Fyyur/app.py:560]
2020-09-20 23:45:43,797 INFO: errors [in C:/Projects/Udacity/Python/Fyyur/app.py:584]
2020-09-20 23:47:07,733 INFO: errors [in C:/Projects/Udacity/Python/Fyyur/app.py:584]
2020-09-20 23:49:17,157 ERROR: Exception on /venues/3 [GET] [in C:\Users\Major Ahmed\AppData\Local\Programs\Python\Python37\lib\site-packages\flask\app.py:1892]
Traceback (most recent call last):
  File "C:\Users\Major Ahmed\AppData\Local\Programs\Python\Python37\lib\site-packages\flask\app.py", line 2447, in wsgi_app
    response = self.full_dispatch_request()
  File "C:\Users\Major Ahmed\AppData\Local\Programs\Python\Python37\lib\site-packages\flask\app.py", line 1952, in full_dispatch_request
    rv = self.handle_user_exception(e)
  File "C:\Users\Major Ahmed\AppData\Local\Programs\Python\Python37\lib\site-packages\flask\app.py", line 1821, in handle_user_exception
    reraise(exc_type, exc_value, tb)
  File "C:\Users\Major Ahmed\AppData\Local\Programs\Python\Python37\lib\site-packages\flask\_compat.py", line 39, in reraise
    raise value
  File "C:\Users\Major Ahmed\AppData\Local\Programs\Python\Python37\lib\site-packages\flask\app.py", line 1950, in full_dispatch_request
    rv = self.dispatch_request()
  File "C:\Users\Major Ahmed\AppData\Local\Programs\Python\Python37\lib\site-packages\flask\app.py", line 1936, in dispatch_request
    return self.view_functions[rule.endpoint](**req.view_args)
  File "C:/Projects/Udacity/Python/Fyyur/app.py", line 287, in show_venue
    return render_template('pages/show_venue.html', venue=data)
  File "C:\Users\Major Ahmed\AppData\Local\Programs\Python\Python37\lib\site-packages\flask\templating.py", line 140, in render_template
    ctx.app,
  File "C:\Users\Major Ahmed\AppData\Local\Programs\Python\Python37\lib\site-packages\flask\templating.py", line 120, in _render
    rv = template.render(context)
  File "C:\Users\Major Ahmed\AppData\Local\Programs\Python\Python37\lib\site-packages\jinja2\environment.py", line 1090, in render
    self.environment.handle_exception()
  File "C:\Users\Major Ahmed\AppData\Local\Programs\Python\Python37\lib\site-packages\jinja2\environment.py", line 832, in handle_exception
    reraise(*rewrite_traceback_stack(source=source))
  File "C:\Users\Major Ahmed\AppData\Local\Programs\Python\Python37\lib\site-packages\jinja2\_compat.py", line 28, in reraise
    raise value.with_traceback(tb)
  File "C:\Projects\Udacity\Python\Fyyur\templates\pages\show_venue.html", line 1, in top-level template code
    {% extends 'layouts/main.html' %}
  File "C:\Projects\Udacity\Python\Fyyur\templates\layouts\main.html", line 103, in top-level template code
    {% block content %}{% endblock %}
  File "C:\Projects\Udacity\Python\Fyyur\templates\pages\show_venue.html", line 57, in block "content"
    <h6>{{ show.start_time|datetime('full') }}</h6>
  File "C:/Projects/Udacity/Python/Fyyur/app.py", line 126, in format_datetime
    return babel.dates.format_datetime(date, format)
  File "C:\Users\Major Ahmed\AppData\Local\Programs\Python\Python37\lib\site-packages\babel\dates.py", line 738, in format_datetime
    return parse_pattern(format).apply(datetime, locale)
  File "C:\Users\Major Ahmed\AppData\Local\Programs\Python\Python37\lib\site-packages\babel\dates.py", line 1232, in apply
    return self % DateTimeFormat(datetime, locale)
  File "C:\Users\Major Ahmed\AppData\Local\Programs\Python\Python37\lib\site-packages\babel\dates.py", line 1229, in __mod__
    return self.format % other
  File "C:\Users\Major Ahmed\AppData\Local\Programs\Python\Python37\lib\site-packages\babel\dates.py", line 1264, in __getitem__
    return self.format_weekday(char, num)
  File "C:\Users\Major Ahmed\AppData\Local\Programs\Python\Python37\lib\site-packages\babel\dates.py", line 1397, in format_weekday
    return get_day_names(width, context, self.locale)[weekday]
  File "C:\Users\Major Ahmed\AppData\Local\Programs\Python\Python37\lib\site-packages\babel\dates.py", line 314, in get_day_names
    return Locale.parse(locale).days[context][width]
AttributeError: 'NoneType' object has no attribute 'days'
2020-09-20 23:49:33,695 ERROR: Exception on /venues/3 [GET] [in C:\Users\Major Ahmed\AppData\Local\Programs\Python\Python37\lib\site-packages\flask\app.py:1892]
Traceback (most recent call last):
  File "C:\Users\Major Ahmed\AppData\Local\Programs\Python\Python37\lib\site-packages\flask\app.py", line 2447, in wsgi_app
    response = self.full_dispatch_request()
  File "C:\Users\Major Ahmed\AppData\Local\Programs\Python\Python37\lib\site-packages\flask\app.py", line 1952, in full_dispatch_request
    rv = self.handle_user_exception(e)
  File "C:\Users\Major Ahmed\AppData\Local\Programs\Python\Python37\lib\site-packages\flask\app.py", line 1821, in handle_user_exception
    reraise(exc_type, exc_value, tb)
  File "C:\Users\Major Ahmed\AppData\Local\Programs\Python\Python37\lib\site-packages\flask\_compat.py", line 39, in reraise
    raise value
  File "C:\Users\Major Ahmed\AppData\Local\Programs\Python\Python37\lib\site-packages\flask\app.py", line 1950, in full_dispatch_request
    rv = self.dispatch_request()
  File "C:\Users\Major Ahmed\AppData\Local\Programs\Python\Python37\lib\site-packages\flask\app.py", line 1936, in dispatch_request
    return self.view_functions[rule.endpoint](**req.view_args)
  File "C:/Projects/Udacity/Python/Fyyur/app.py", line 287, in show_venue
    return render_template('pages/show_venue.html', venue=data)
  File "C:\Users\Major Ahmed\AppData\Local\Programs\Python\Python37\lib\site-packages\flask\templating.py", line 140, in render_template
    ctx.app,
  File "C:\Users\Major Ahmed\AppData\Local\Programs\Python\Python37\lib\site-packages\flask\templating.py", line 120, in _render
    rv = template.render(context)
  File "C:\Users\Major Ahmed\AppData\Local\Programs\Python\Python37\lib\site-packages\jinja2\environment.py", line 1090, in render
    self.environment.handle_exception()
  File "C:\Users\Major Ahmed\AppData\Local\Programs\Python\Python37\lib\site-packages\jinja2\environment.py", line 832, in handle_exception
    reraise(*rewrite_traceback_stack(source=source))
  File "C:\Users\Major Ahmed\AppData\Local\Programs\Python\Python37\lib\site-packages\jinja2\_compat.py", line 28, in reraise
    raise value.with_traceback(tb)
  File "C:\Projects\Udacity\Python\Fyyur\templates\pages\show_venue.html", line 1, in top-level template code
    {% extends 'layouts/main.html' %}
  File "C:\Projects\Udacity\Python\Fyyur\templates\layouts\main.html", line 103, in top-level template code
    {% block content %}{% endblock %}
  File "C:\Projects\Udacity\Python\Fyyur\templates\pages\show_venue.html", line 57, in block "content"
    <h6>{{ show.start_time|datetime('full') }}</h6>
  File "C:/Projects/Udacity/Python/Fyyur/app.py", line 126, in format_datetime
    return babel.dates.format_datetime(date, format)
  File "C:\Users\Major Ahmed\AppData\Local\Programs\Python\Python37\lib\site-packages\babel\dates.py", line 738, in format_datetime
    return parse_pattern(format).apply(datetime, locale)
  File "C:\Users\Major Ahmed\AppData\Local\Programs\Python\Python37\lib\site-packages\babel\dates.py", line 1232, in apply
    return self % DateTimeFormat(datetime, locale)
  File "C:\Users\Major Ahmed\AppData\Local\Programs\Python\Python37\lib\site-packages\babel\dates.py", line 1229, in __mod__
    return self.format % other
  File "C:\Users\Major Ahmed\AppData\Local\Programs\Python\Python37\lib\site-packages\babel\dates.py", line 1264, in __getitem__
    return self.format_weekday(char, num)
  File "C:\Users\Major Ahmed\AppData\Local\Programs\Python\Python37\lib\site-packages\babel\dates.py", line 1397, in format_weekday
    return get_day_names(width, context, self.locale)[weekday]
  File "C:\Users\Major Ahmed\AppData\Local\Programs\Python\Python37\lib\site-packages\babel\dates.py", line 314, in get_day_names
    return Locale.parse(locale).days[context][width]
AttributeError: 'NoneType' object has no attribute 'days'
2020-09-20 23:49:35,375 ERROR: Exception on /venues/6 [GET] [in C:\Users\Major Ahmed\AppData\Local\Programs\Python\Python37\lib\site-packages\flask\app.py:1892]
Traceback (most recent call last):
  File "C:\Users\Major Ahmed\AppData\Local\Programs\Python\Python37\lib\site-packages\flask\app.py", line 2447, in wsgi_app
    response = self.full_dispatch_request()
  File "C:\Users\Major Ahmed\AppData\Local\Programs\Python\Python37\lib\site-packages\flask\app.py", line 1952, in full_dispatch_request
    rv = self.handle_user_exception(e)
  File "C:\Users\Major Ahmed\AppData\Local\Programs\Python\Python37\lib\site-packages\flask\app.py", line 1821, in handle_user_exception
    reraise(exc_type, exc_value, tb)
  File "C:\Users\Major Ahmed\AppData\Local\Programs\Python\Python37\lib\site-packages\flask\_compat.py", line 39, in reraise
    raise value
  File "C:\Users\Major Ahmed\AppData\Local\Programs\Python\Python37\lib\site-packages\flask\app.py", line 1950, in full_dispatch_request
    rv = self.dispatch_request()
  File "C:\Users\Major Ahmed\AppData\Local\Programs\Python\Python37\lib\site-packages\flask\app.py", line 1936, in dispatch_request
    return self.view_functions[rule.endpoint](**req.view_args)
  File "C:/Projects/Udacity/Python/Fyyur/app.py", line 286, in show_venue
    data = list(filter(lambda d: d['id'] == venue_id, [data1, data2, data3]))[0]
IndexError: list index out of range
2020-09-20 23:49:37,328 ERROR: Exception on /venues/1 [GET] [in C:\Users\Major Ahmed\AppData\Local\Programs\Python\Python37\lib\site-packages\flask\app.py:1892]
Traceback (most recent call last):
  File "C:\Users\Major Ahmed\AppData\Local\Programs\Python\Python37\lib\site-packages\flask\app.py", line 2447, in wsgi_app
    response = self.full_dispatch_request()
  File "C:\Users\Major Ahmed\AppData\Local\Programs\Python\Python37\lib\site-packages\flask\app.py", line 1952, in full_dispatch_request
    rv = self.handle_user_exception(e)
  File "C:\Users\Major Ahmed\AppData\Local\Programs\Python\Python37\lib\site-packages\flask\app.py", line 1821, in handle_user_exception
    reraise(exc_type, exc_value, tb)
  File "C:\Users\Major Ahmed\AppData\Local\Programs\Python\Python37\lib\site-packages\flask\_compat.py", line 39, in reraise
    raise value
  File "C:\Users\Major Ahmed\AppData\Local\Programs\Python\Python37\lib\site-packages\flask\app.py", line 1950, in full_dispatch_request
    rv = self.dispatch_request()
  File "C:\Users\Major Ahmed\AppData\Local\Programs\Python\Python37\lib\site-packages\flask\app.py", line 1936, in dispatch_request
    return self.view_functions[rule.endpoint](**req.view_args)
  File "C:/Projects/Udacity/Python/Fyyur/app.py", line 287, in show_venue
    return render_template('pages/show_venue.html', venue=data)
  File "C:\Users\Major Ahmed\AppData\Local\Programs\Python\Python37\lib\site-packages\flask\templating.py", line 140, in render_template
    ctx.app,
  File "C:\Users\Major Ahmed\AppData\Local\Programs\Python\Python37\lib\site-packages\flask\templating.py", line 120, in _render
    rv = template.render(context)
  File "C:\Users\Major Ahmed\AppData\Local\Programs\Python\Python37\lib\site-packages\jinja2\environment.py", line 1090, in render
    self.environment.handle_exception()
  File "C:\Users\Major Ahmed\AppData\Local\Programs\Python\Python37\lib\site-packages\jinja2\environment.py", line 832, in handle_exception
    reraise(*rewrite_traceback_stack(source=source))
  File "C:\Users\Major Ahmed\AppData\Local\Programs\Python\Python37\lib\site-packages\jinja2\_compat.py", line 28, in reraise
    raise value.with_traceback(tb)
  File "C:\Projects\Udacity\Python\Fyyur\templates\pages\show_venue.html", line 1, in top-level template code
    {% extends 'layouts/main.html' %}
  File "C:\Projects\Udacity\Python\Fyyur\templates\layouts\main.html", line 103, in top-level template code
    {% block content %}{% endblock %}
  File "C:\Projects\Udacity\Python\Fyyur\templates\pages\show_venue.html", line 71, in block "content"
    <h6>{{ show.start_time|datetime('full') }}</h6>
  File "C:/Projects/Udacity/Python/Fyyur/app.py", line 126, in format_datetime
    return babel.dates.format_datetime(date, format)
  File "C:\Users\Major Ahmed\AppData\Local\Programs\Python\Python37\lib\site-packages\babel\dates.py", line 738, in format_datetime
    return parse_pattern(format).apply(datetime, locale)
  File "C:\Users\Major Ahmed\AppData\Local\Programs\Python\Python37\lib\site-packages\babel\dates.py", line 1232, in apply
    return self % DateTimeFormat(datetime, locale)
  File "C:\Users\Major Ahmed\AppData\Local\Programs\Python\Python37\lib\site-packages\babel\dates.py", line 1229, in __mod__
    return self.format % other
  File "C:\Users\Major Ahmed\AppData\Local\Programs\Python\Python37\lib\site-packages\babel\dates.py", line 1264, in __getitem__
    return self.format_weekday(char, num)
  File "C:\Users\Major Ahmed\AppData\Local\Programs\Python\Python37\lib\site-packages\babel\dates.py", line 1397, in format_weekday
    return get_day_names(width, context, self.locale)[weekday]
  File "C:\Users\Major Ahmed\AppData\Local\Programs\Python\Python37\lib\site-packages\babel\dates.py", line 314, in get_day_names
    return Locale.parse(locale).days[context][width]
AttributeError: 'NoneType' object has no attribute 'days'
2020-09-20 23:49:42,680 ERROR: Exception on /venues/4 [GET] [in C:\Users\Major Ahmed\AppData\Local\Programs\Python\Python37\lib\site-packages\flask\app.py:1892]
Traceback (most recent call last):
  File "C:\Users\Major Ahmed\AppData\Local\Programs\Python\Python37\lib\site-packages\flask\app.py", line 2447, in wsgi_app
    response = self.full_dispatch_request()
  File "C:\Users\Major Ahmed\AppData\Local\Programs\Python\Python37\lib\site-packages\flask\app.py", line 1952, in full_dispatch_request
    rv = self.handle_user_exception(e)
  File "C:\Users\Major Ahmed\AppData\Local\Programs\Python\Python37\lib\site-packages\flask\app.py", line 1821, in handle_user_exception
    reraise(exc_type, exc_value, tb)
  File "C:\Users\Major Ahmed\AppData\Local\Programs\Python\Python37\lib\site-packages\flask\_compat.py", line 39, in reraise
    raise value
  File "C:\Users\Major Ahmed\AppData\Local\Programs\Python\Python37\lib\site-packages\flask\app.py", line 1950, in full_dispatch_request
    rv = self.dispatch_request()
  File "C:\Users\Major Ahmed\AppData\Local\Programs\Python\Python37\lib\site-packages\flask\app.py", line 1936, in dispatch_request
    return self.view_functions[rule.endpoint](**req.view_args)
  File "C:/Projects/Udacity/Python/Fyyur/app.py", line 286, in show_venue
    data = list(filter(lambda d: d['id'] == venue_id, [data1, data2, data3]))[0]
IndexError: list index out of range
2020-09-20 23:49:44,591 ERROR: Exception on /venues/5 [GET] [in C:\Users\Major Ahmed\AppData\Local\Programs\Python\Python37\lib\site-packages\flask\app.py:1892]
Traceback (most recent call last):
  File "C:\Users\Major Ahmed\AppData\Local\Programs\Python\Python37\lib\site-packages\flask\app.py", line 2447, in wsgi_app
    response = self.full_dispatch_request()
  File "C:\Users\Major Ahmed\AppData\Local\Programs\Python\Python37\lib\site-packages\flask\app.py", line 1952, in full_dispatch_request
    rv = self.handle_user_exception(e)
  File "C:\Users\Major Ahmed\AppData\Local\Programs\Python\Python37\lib\site-packages\flask\app.py", line 1821, in handle_user_exception
    reraise(exc_type, exc_value, tb)
  File "C:\Users\Major Ahmed\AppData\Local\Programs\Python\Python37\lib\site-packages\flask\_compat.py", line 39, in reraise
    raise value
  File "C:\Users\Major Ahmed\AppData\Local\Programs\Python\Python37\lib\site-packages\flask\app.py", line 1950, in full_dispatch_request
    rv = self.dispatch_request()
  File "C:\Users\Major Ahmed\AppData\Local\Programs\Python\Python37\lib\site-packages\flask\app.py", line 1936, in dispatch_request
    return self.view_functions[rule.endpoint](**req.view_args)
  File "C:/Projects/Udacity/Python/Fyyur/app.py", line 286, in show_venue
    data = list(filter(lambda d: d['id'] == venue_id, [data1, data2, data3]))[0]
IndexError: list index out of range
2020-09-20 23:58:05,409 INFO: errors [in C:/Projects/Udacity/Python/Fyyur/app.py:564]
2020-09-20 23:58:12,677 ERROR: Exception on /venues/search [POST] [in C:\Users\Major Ahmed\AppData\Local\Programs\Python\Python37\lib\site-packages\flask\app.py:1892]
Traceback (most recent call last):
  File "C:\Users\Major Ahmed\AppData\Local\Programs\Python\Python37\lib\site-packages\flask\app.py", line 2447, in wsgi_app
    response = self.full_dispatch_request()
  File "C:\Users\Major Ahmed\AppData\Local\Programs\Python\Python37\lib\site-packages\flask\app.py", line 1952, in full_dispatch_request
    rv = self.handle_user_exception(e)
  File "C:\Users\Major Ahmed\AppData\Local\Programs\Python\Python37\lib\site-packages\flask\app.py", line 1821, in handle_user_exception
    reraise(exc_type, exc_value, tb)
  File "C:\Users\Major Ahmed\AppData\Local\Programs\Python\Python37\lib\site-packages\flask\_compat.py", line 39, in reraise
    raise value
  File "C:\Users\Major Ahmed\AppData\Local\Programs\Python\Python37\lib\site-packages\flask\app.py", line 1950, in full_dispatch_request
    rv = self.dispatch_request()
  File "C:\Users\Major Ahmed\AppData\Local\Programs\Python\Python37\lib\site-packages\flask\app.py", line 1936, in dispatch_request
    return self.view_functions[rule.endpoint](**req.view_args)
  File "C:/Projects/Udacity/Python/Fyyur/app.py", line 174, in search_venues
    print(rerquest.get_json())
NameError: name 'rerquest' is not defined
2020-09-20 23:58:38,892 INFO: errors [in C:/Projects/Udacity/Python/Fyyur/app.py:564]
2020-09-20 23:59:30,462 INFO: errors [in C:/Projects/Udacity/Python/Fyyur/app.py:564]
2020-09-21 00:04:34,612 INFO: errors [in C:/Projects/Udacity/Python/Fyyur/app.py:566]
2020-09-21 00:07:40,988 INFO: errors [in C:/Projects/Udacity/Python/Fyyur/app.py:570]
2020-09-21 00:13:06,712 INFO: errors [in C:/Projects/Udacity/Python/Fyyur/app.py:562]
2020-09-21 00:13:22,510 ERROR: Exception on /venues/6 [GET] [in C:\Users\Major Ahmed\AppData\Local\Programs\Python\Python37\lib\site-packages\flask\app.py:1892]
Traceback (most recent call last):
  File "C:\Users\Major Ahmed\AppData\Local\Programs\Python\Python37\lib\site-packages\flask\app.py", line 2447, in wsgi_app
    response = self.full_dispatch_request()
  File "C:\Users\Major Ahmed\AppData\Local\Programs\Python\Python37\lib\site-packages\flask\app.py", line 1952, in full_dispatch_request
    rv = self.handle_user_exception(e)
  File "C:\Users\Major Ahmed\AppData\Local\Programs\Python\Python37\lib\site-packages\flask\app.py", line 1821, in handle_user_exception
    reraise(exc_type, exc_value, tb)
  File "C:\Users\Major Ahmed\AppData\Local\Programs\Python\Python37\lib\site-packages\flask\_compat.py", line 39, in reraise
    raise value
  File "C:\Users\Major Ahmed\AppData\Local\Programs\Python\Python37\lib\site-packages\flask\app.py", line 1950, in full_dispatch_request
    rv = self.dispatch_request()
  File "C:\Users\Major Ahmed\AppData\Local\Programs\Python\Python37\lib\site-packages\flask\app.py", line 1936, in dispatch_request
    return self.view_functions[rule.endpoint](**req.view_args)
  File "C:/Projects/Udacity/Python/Fyyur/app.py", line 263, in show_venue
    data = list(filter(lambda d: d['id'] == venue_id, [data1, data2, data3]))[0]
IndexError: list index out of range
2020-09-21 00:13:33,452 ERROR: Exception on /venues/4 [GET] [in C:\Users\Major Ahmed\AppData\Local\Programs\Python\Python37\lib\site-packages\flask\app.py:1892]
Traceback (most recent call last):
  File "C:\Users\Major Ahmed\AppData\Local\Programs\Python\Python37\lib\site-packages\flask\app.py", line 2447, in wsgi_app
    response = self.full_dispatch_request()
  File "C:\Users\Major Ahmed\AppData\Local\Programs\Python\Python37\lib\site-packages\flask\app.py", line 1952, in full_dispatch_request
    rv = self.handle_user_exception(e)
  File "C:\Users\Major Ahmed\AppData\Local\Programs\Python\Python37\lib\site-packages\flask\app.py", line 1821, in handle_user_exception
    reraise(exc_type, exc_value, tb)
  File "C:\Users\Major Ahmed\AppData\Local\Programs\Python\Python37\lib\site-packages\flask\_compat.py", line 39, in reraise
    raise value
  File "C:\Users\Major Ahmed\AppData\Local\Programs\Python\Python37\lib\site-packages\flask\app.py", line 1950, in full_dispatch_request
    rv = self.dispatch_request()
  File "C:\Users\Major Ahmed\AppData\Local\Programs\Python\Python37\lib\site-packages\flask\app.py", line 1936, in dispatch_request
    return self.view_functions[rule.endpoint](**req.view_args)
  File "C:/Projects/Udacity/Python/Fyyur/app.py", line 263, in show_venue
    data = list(filter(lambda d: d['id'] == venue_id, [data1, data2, data3]))[0]
IndexError: list index out of range
2020-09-21 00:13:35,065 ERROR: Exception on /venues/4 [GET] [in C:\Users\Major Ahmed\AppData\Local\Programs\Python\Python37\lib\site-packages\flask\app.py:1892]
Traceback (most recent call last):
  File "C:\Users\Major Ahmed\AppData\Local\Programs\Python\Python37\lib\site-packages\flask\app.py", line 2447, in wsgi_app
    response = self.full_dispatch_request()
  File "C:\Users\Major Ahmed\AppData\Local\Programs\Python\Python37\lib\site-packages\flask\app.py", line 1952, in full_dispatch_request
    rv = self.handle_user_exception(e)
  File "C:\Users\Major Ahmed\AppData\Local\Programs\Python\Python37\lib\site-packages\flask\app.py", line 1821, in handle_user_exception
    reraise(exc_type, exc_value, tb)
  File "C:\Users\Major Ahmed\AppData\Local\Programs\Python\Python37\lib\site-packages\flask\_compat.py", line 39, in reraise
    raise value
  File "C:\Users\Major Ahmed\AppData\Local\Programs\Python\Python37\lib\site-packages\flask\app.py", line 1950, in full_dispatch_request
    rv = self.dispatch_request()
  File "C:\Users\Major Ahmed\AppData\Local\Programs\Python\Python37\lib\site-packages\flask\app.py", line 1936, in dispatch_request
    return self.view_functions[rule.endpoint](**req.view_args)
  File "C:/Projects/Udacity/Python/Fyyur/app.py", line 263, in show_venue
    data = list(filter(lambda d: d['id'] == venue_id, [data1, data2, data3]))[0]
IndexError: list index out of range
2020-09-21 00:13:43,337 ERROR: Exception on /venues/5 [GET] [in C:\Users\Major Ahmed\AppData\Local\Programs\Python\Python37\lib\site-packages\flask\app.py:1892]
Traceback (most recent call last):
  File "C:\Users\Major Ahmed\AppData\Local\Programs\Python\Python37\lib\site-packages\flask\app.py", line 2447, in wsgi_app
    response = self.full_dispatch_request()
  File "C:\Users\Major Ahmed\AppData\Local\Programs\Python\Python37\lib\site-packages\flask\app.py", line 1952, in full_dispatch_request
    rv = self.handle_user_exception(e)
  File "C:\Users\Major Ahmed\AppData\Local\Programs\Python\Python37\lib\site-packages\flask\app.py", line 1821, in handle_user_exception
    reraise(exc_type, exc_value, tb)
  File "C:\Users\Major Ahmed\AppData\Local\Programs\Python\Python37\lib\site-packages\flask\_compat.py", line 39, in reraise
    raise value
  File "C:\Users\Major Ahmed\AppData\Local\Programs\Python\Python37\lib\site-packages\flask\app.py", line 1950, in full_dispatch_request
    rv = self.dispatch_request()
  File "C:\Users\Major Ahmed\AppData\Local\Programs\Python\Python37\lib\site-packages\flask\app.py", line 1936, in dispatch_request
    return self.view_functions[rule.endpoint](**req.view_args)
  File "C:/Projects/Udacity/Python/Fyyur/app.py", line 263, in show_venue
    data = list(filter(lambda d: d['id'] == venue_id, [data1, data2, data3]))[0]
IndexError: list index out of range
2020-09-21 00:14:38,046 INFO: errors [in C:/Projects/Udacity/Python/Fyyur/app.py:485]
2020-09-21 00:46:47,800 INFO: errors [in C:\Projects\Udacity\Python\Fyyur\app.py:494]
2020-09-21 00:46:55,796 INFO: errors [in C:\Projects\Udacity\Python\Fyyur\app.py:494]
2020-09-21 00:54:51,163 INFO: errors [in C:/Projects/Udacity/Python/Fyyur/app.py:514]
2020-09-21 00:55:49,664 INFO: errors [in C:/Projects/Udacity/Python/Fyyur/app.py:514]
2020-09-21 01:14:37,813 INFO: errors [in C:\Projects\Udacity\Python\Fyyur\app.py:485]
2020-09-21 01:14:42,769 INFO: errors [in C:\Projects\Udacity\Python\Fyyur\app.py:485]
2020-09-21 01:14:51,867 INFO: errors [in C:/Projects/Udacity/Python/Fyyur/app.py:504]
2020-09-21 01:25:15,820 INFO: errors [in C:/Projects/Udacity/Python/Fyyur/app.py:493]
2020-09-21 13:32:21,261 INFO: errors [in C:/Projects/Udacity/Python/Fyyur/app.py:493]
2020-09-21 13:41:24,572 INFO: errors [in C:/Projects/Udacity/Python/Fyyur/app.py:503]
2020-09-21 13:41:37,995 ERROR: Exception on /venues [GET] [in C:\Users\Major Ahmed\AppData\Local\Programs\Python\Python37\lib\site-packages\flask\app.py:1892]
Traceback (most recent call last):
  File "C:\Users\Major Ahmed\AppData\Local\Programs\Python\Python37\lib\site-packages\flask\app.py", line 2447, in wsgi_app
    response = self.full_dispatch_request()
  File "C:\Users\Major Ahmed\AppData\Local\Programs\Python\Python37\lib\site-packages\flask\app.py", line 1952, in full_dispatch_request
    rv = self.handle_user_exception(e)
  File "C:\Users\Major Ahmed\AppData\Local\Programs\Python\Python37\lib\site-packages\flask\app.py", line 1821, in handle_user_exception
    reraise(exc_type, exc_value, tb)
  File "C:\Users\Major Ahmed\AppData\Local\Programs\Python\Python37\lib\site-packages\flask\_compat.py", line 39, in reraise
    raise value
  File "C:\Users\Major Ahmed\AppData\Local\Programs\Python\Python37\lib\site-packages\flask\app.py", line 1950, in full_dispatch_request
    rv = self.dispatch_request()
  File "C:\Users\Major Ahmed\AppData\Local\Programs\Python\Python37\lib\site-packages\flask\app.py", line 1936, in dispatch_request
    return self.view_functions[rule.endpoint](**req.view_args)
  File "C:/Projects/Udacity/Python/Fyyur/app.py", line 164, in venues
    states.append(state)
NameError: name 'state' is not defined
2020-09-21 13:42:08,151 INFO: errors [in C:/Projects/Udacity/Python/Fyyur/app.py:503]
2020-09-21 13:42:16,290 ERROR: Exception on /venues [GET] [in C:\Users\Major Ahmed\AppData\Local\Programs\Python\Python37\lib\site-packages\flask\app.py:1892]
Traceback (most recent call last):
  File "C:\Users\Major Ahmed\AppData\Local\Programs\Python\Python37\lib\site-packages\flask\app.py", line 2447, in wsgi_app
    response = self.full_dispatch_request()
  File "C:\Users\Major Ahmed\AppData\Local\Programs\Python\Python37\lib\site-packages\flask\app.py", line 1952, in full_dispatch_request
    rv = self.handle_user_exception(e)
  File "C:\Users\Major Ahmed\AppData\Local\Programs\Python\Python37\lib\site-packages\flask\app.py", line 1821, in handle_user_exception
    reraise(exc_type, exc_value, tb)
  File "C:\Users\Major Ahmed\AppData\Local\Programs\Python\Python37\lib\site-packages\flask\_compat.py", line 39, in reraise
    raise value
  File "C:\Users\Major Ahmed\AppData\Local\Programs\Python\Python37\lib\site-packages\flask\app.py", line 1950, in full_dispatch_request
    rv = self.dispatch_request()
  File "C:\Users\Major Ahmed\AppData\Local\Programs\Python\Python37\lib\site-packages\flask\app.py", line 1936, in dispatch_request
    return self.view_functions[rule.endpoint](**req.view_args)
  File "C:/Projects/Udacity/Python/Fyyur/app.py", line 173, in venues
    for show in ven.shows:
AttributeError: 'list' object has no attribute 'shows'
2020-09-21 13:44:27,857 INFO: errors [in C:/Projects/Udacity/Python/Fyyur/app.py:504]
2020-09-21 13:44:35,161 ERROR: Exception on /venues [GET] [in C:\Users\Major Ahmed\AppData\Local\Programs\Python\Python37\lib\site-packages\flask\app.py:1892]
Traceback (most recent call last):
  File "C:\Users\Major Ahmed\AppData\Local\Programs\Python\Python37\lib\site-packages\flask\app.py", line 2447, in wsgi_app
    response = self.full_dispatch_request()
  File "C:\Users\Major Ahmed\AppData\Local\Programs\Python\Python37\lib\site-packages\flask\app.py", line 1952, in full_dispatch_request
    rv = self.handle_user_exception(e)
  File "C:\Users\Major Ahmed\AppData\Local\Programs\Python\Python37\lib\site-packages\flask\app.py", line 1821, in handle_user_exception
    reraise(exc_type, exc_value, tb)
  File "C:\Users\Major Ahmed\AppData\Local\Programs\Python\Python37\lib\site-packages\flask\_compat.py", line 39, in reraise
    raise value
  File "C:\Users\Major Ahmed\AppData\Local\Programs\Python\Python37\lib\site-packages\flask\app.py", line 1950, in full_dispatch_request
    rv = self.dispatch_request()
  File "C:\Users\Major Ahmed\AppData\Local\Programs\Python\Python37\lib\site-packages\flask\app.py", line 1936, in dispatch_request
    return self.view_functions[rule.endpoint](**req.view_args)
  File "C:/Projects/Udacity/Python/Fyyur/app.py", line 177, in venues
    ven["num_upcoming_shows"] = upcoming_shows
TypeError: 'Venue' object does not support item assignment
2020-09-21 13:47:48,874 INFO: errors [in C:/Projects/Udacity/Python/Fyyur/app.py:504]
2020-09-21 13:48:24,771 INFO: errors [in C:/Projects/Udacity/Python/Fyyur/app.py:512]
2020-09-21 13:49:36,662 INFO: errors [in C:/Projects/Udacity/Python/Fyyur/app.py:516]
2020-09-21 13:50:12,724 INFO: errors [in C:/Projects/Udacity/Python/Fyyur/app.py:516]
2020-09-21 13:55:19,936 INFO: errors [in C:/Projects/Udacity/Python/Fyyur/app.py:505]
2020-09-21 13:56:20,890 INFO: errors [in C:/Projects/Udacity/Python/Fyyur/app.py:505]
2020-09-21 13:56:33,973 INFO: errors [in C:/Projects/Udacity/Python/Fyyur/app.py:505]
2020-09-21 13:56:46,686 INFO: errors [in C:/Projects/Udacity/Python/Fyyur/app.py:505]
2020-09-21 13:57:34,424 INFO: errors [in C:/Projects/Udacity/Python/Fyyur/app.py:505]
2020-09-21 13:58:21,621 INFO: errors [in C:/Projects/Udacity/Python/Fyyur/app.py:515]
2020-09-21 14:00:48,467 INFO: errors [in C:/Projects/Udacity/Python/Fyyur/app.py:524]
2020-09-21 14:09:20,193 INFO: errors [in C:/Projects/Udacity/Python/Fyyur/app.py:525]
2020-09-21 14:09:44,452 INFO: errors [in C:/Projects/Udacity/Python/Fyyur/app.py:529]
2020-09-21 14:11:24,879 INFO: errors [in C:/Projects/Udacity/Python/Fyyur/app.py:529]
2020-09-21 14:14:14,128 INFO: errors [in C:/Projects/Udacity/Python/Fyyur/app.py:529]
2020-09-21 14:17:39,547 INFO: errors [in C:/Projects/Udacity/Python/Fyyur/app.py:530]
2020-09-21 14:19:35,573 INFO: errors [in C:/Projects/Udacity/Python/Fyyur/app.py:529]
2020-09-21 14:23:15,837 INFO: errors [in C:/Projects/Udacity/Python/Fyyur/app.py:529]
2020-09-21 14:25:39,677 INFO: errors [in C:/Projects/Udacity/Python/Fyyur/app.py:528]
2020-09-21 14:26:41,544 INFO: errors [in C:/Projects/Udacity/Python/Fyyur/app.py:528]
2020-09-21 14:27:21,711 INFO: errors [in C:/Projects/Udacity/Python/Fyyur/app.py:528]
2020-09-21 14:27:56,946 INFO: errors [in C:/Projects/Udacity/Python/Fyyur/app.py:529]
2020-09-21 14:30:41,505 INFO: errors [in C:/Projects/Udacity/Python/Fyyur/app.py:529]
2020-09-21 14:35:40,459 INFO: errors [in C:/Projects/Udacity/Python/Fyyur/app.py:529]
2020-09-21 14:37:40,514 INFO: errors [in C:/Projects/Udacity/Python/Fyyur/app.py:529]
2020-09-21 14:39:07,069 INFO: errors [in C:/Projects/Udacity/Python/Fyyur/app.py:530]
2020-09-21 14:39:23,599 INFO: errors [in C:/Projects/Udacity/Python/Fyyur/app.py:530]
2020-09-21 14:39:52,275 INFO: errors [in C:/Projects/Udacity/Python/Fyyur/app.py:531]
2020-09-21 14:40:17,597 INFO: errors [in C:/Projects/Udacity/Python/Fyyur/app.py:531]
2020-09-21 14:41:30,112 INFO: errors [in C:/Projects/Udacity/Python/Fyyur/app.py:530]
2020-09-21 14:42:15,504 INFO: errors [in C:/Projects/Udacity/Python/Fyyur/app.py:530]
2020-09-21 14:43:19,467 INFO: errors [in C:/Projects/Udacity/Python/Fyyur/app.py:526]
2020-09-21 14:43:39,195 INFO: errors [in C:/Projects/Udacity/Python/Fyyur/app.py:527]
2020-09-21 14:44:32,372 INFO: errors [in C:/Projects/Udacity/Python/Fyyur/app.py:526]
2020-09-21 14:45:27,697 INFO: errors [in C:/Projects/Udacity/Python/Fyyur/app.py:526]
2020-09-21 14:46:15,582 INFO: errors [in C:/Projects/Udacity/Python/Fyyur/app.py:526]
2020-09-21 14:47:04,864 INFO: errors [in C:/Projects/Udacity/Python/Fyyur/app.py:527]
2020-09-21 14:55:44,493 INFO: errors [in C:/Projects/Udacity/Python/Fyyur/app.py:528]
2020-09-21 15:00:54,738 INFO: errors [in C:/Projects/Udacity/Python/Fyyur/app.py:530]
2020-09-21 15:01:05,128 INFO: errors [in C:/Projects/Udacity/Python/Fyyur/app.py:529]
2020-09-21 15:07:07,589 INFO: errors [in C:/Projects/Udacity/Python/Fyyur/app.py:532]
2020-09-21 15:58:29,132 INFO: errors [in C:/Projects/Udacity/Python/Fyyur/app.py:539]
2020-09-21 16:04:59,084 INFO: errors [in C:\Projects\Udacity\Python\Fyyur\app.py:519]
2020-09-21 16:05:21,800 INFO: errors [in C:\Projects\Udacity\Python\Fyyur\app.py:519]
2020-09-21 16:22:59,130 INFO: errors [in C:/Projects/Udacity/Python/Fyyur/app.py:563]
2020-09-21 16:23:15,321 ERROR: Exception on /venues/11 [GET] [in C:\Users\Major Ahmed\AppData\Local\Programs\Python\Python37\lib\site-packages\flask\app.py:1892]
Traceback (most recent call last):
  File "C:\Users\Major Ahmed\AppData\Local\Programs\Python\Python37\lib\site-packages\flask\app.py", line 2447, in wsgi_app
    response = self.full_dispatch_request()
  File "C:\Users\Major Ahmed\AppData\Local\Programs\Python\Python37\lib\site-packages\flask\app.py", line 1952, in full_dispatch_request
    rv = self.handle_user_exception(e)
  File "C:\Users\Major Ahmed\AppData\Local\Programs\Python\Python37\lib\site-packages\flask\app.py", line 1821, in handle_user_exception
    reraise(exc_type, exc_value, tb)
  File "C:\Users\Major Ahmed\AppData\Local\Programs\Python\Python37\lib\site-packages\flask\_compat.py", line 39, in reraise
    raise value
  File "C:\Users\Major Ahmed\AppData\Local\Programs\Python\Python37\lib\site-packages\flask\app.py", line 1950, in full_dispatch_request
    rv = self.dispatch_request()
  File "C:\Users\Major Ahmed\AppData\Local\Programs\Python\Python37\lib\site-packages\flask\app.py", line 1936, in dispatch_request
    return self.view_functions[rule.endpoint](**req.view_args)
  File "C:/Projects/Udacity/Python/Fyyur/app.py", line 266, in show_venue
    return render_template('pages/show_venue.html', venue=data)
  File "C:\Users\Major Ahmed\AppData\Local\Programs\Python\Python37\lib\site-packages\flask\templating.py", line 140, in render_template
    ctx.app,
  File "C:\Users\Major Ahmed\AppData\Local\Programs\Python\Python37\lib\site-packages\flask\templating.py", line 120, in _render
    rv = template.render(context)
  File "C:\Users\Major Ahmed\AppData\Local\Programs\Python\Python37\lib\site-packages\jinja2\environment.py", line 1090, in render
    self.environment.handle_exception()
  File "C:\Users\Major Ahmed\AppData\Local\Programs\Python\Python37\lib\site-packages\jinja2\environment.py", line 832, in handle_exception
    reraise(*rewrite_traceback_stack(source=source))
  File "C:\Users\Major Ahmed\AppData\Local\Programs\Python\Python37\lib\site-packages\jinja2\_compat.py", line 28, in reraise
    raise value.with_traceback(tb)
  File "C:\Projects\Udacity\Python\Fyyur\templates\pages\show_venue.html", line 1, in top-level template code
    {% extends 'layouts/main.html' %}
  File "C:\Projects\Udacity\Python\Fyyur\templates\layouts\main.html", line 103, in top-level template code
    {% block content %}{% endblock %}
  File "C:\Projects\Udacity\Python\Fyyur\templates\pages\show_venue.html", line 13, in block "content"
    {% for genre in venue.genres %}
TypeError: 'NoneType' object is not iterable
2020-09-21 16:23:52,404 INFO: errors [in C:/Projects/Udacity/Python/Fyyur/app.py:563]
2020-09-21 16:23:55,499 ERROR: Exception on /venues/11 [GET] [in C:\Users\Major Ahmed\AppData\Local\Programs\Python\Python37\lib\site-packages\flask\app.py:1892]
Traceback (most recent call last):
  File "C:\Users\Major Ahmed\AppData\Local\Programs\Python\Python37\lib\site-packages\flask\app.py", line 2447, in wsgi_app
    response = self.full_dispatch_request()
  File "C:\Users\Major Ahmed\AppData\Local\Programs\Python\Python37\lib\site-packages\flask\app.py", line 1952, in full_dispatch_request
    rv = self.handle_user_exception(e)
  File "C:\Users\Major Ahmed\AppData\Local\Programs\Python\Python37\lib\site-packages\flask\app.py", line 1821, in handle_user_exception
    reraise(exc_type, exc_value, tb)
  File "C:\Users\Major Ahmed\AppData\Local\Programs\Python\Python37\lib\site-packages\flask\_compat.py", line 39, in reraise
    raise value
  File "C:\Users\Major Ahmed\AppData\Local\Programs\Python\Python37\lib\site-packages\flask\app.py", line 1950, in full_dispatch_request
    rv = self.dispatch_request()
  File "C:\Users\Major Ahmed\AppData\Local\Programs\Python\Python37\lib\site-packages\flask\app.py", line 1936, in dispatch_request
    return self.view_functions[rule.endpoint](**req.view_args)
  File "C:/Projects/Udacity/Python/Fyyur/app.py", line 266, in show_venue
    return render_template('pages/show_venue.html', venue=data)
  File "C:\Users\Major Ahmed\AppData\Local\Programs\Python\Python37\lib\site-packages\flask\templating.py", line 140, in render_template
    ctx.app,
  File "C:\Users\Major Ahmed\AppData\Local\Programs\Python\Python37\lib\site-packages\flask\templating.py", line 120, in _render
    rv = template.render(context)
  File "C:\Users\Major Ahmed\AppData\Local\Programs\Python\Python37\lib\site-packages\jinja2\environment.py", line 1090, in render
    self.environment.handle_exception()
  File "C:\Users\Major Ahmed\AppData\Local\Programs\Python\Python37\lib\site-packages\jinja2\environment.py", line 832, in handle_exception
    reraise(*rewrite_traceback_stack(source=source))
  File "C:\Users\Major Ahmed\AppData\Local\Programs\Python\Python37\lib\site-packages\jinja2\_compat.py", line 28, in reraise
    raise value.with_traceback(tb)
  File "C:\Projects\Udacity\Python\Fyyur\templates\pages\show_venue.html", line 1, in top-level template code
    {% extends 'layouts/main.html' %}
  File "C:\Projects\Udacity\Python\Fyyur\templates\layouts\main.html", line 103, in top-level template code
    {% block content %}{% endblock %}
  File "C:\Projects\Udacity\Python\Fyyur\templates\pages\show_venue.html", line 57, in block "content"
    <h6>{{ show.start_time|datetime('full') }}</h6>
  File "C:/Projects/Udacity/Python/Fyyur/app.py", line 133, in format_datetime
    date = dateutil.parser.parse(value)
  File "C:\Users\Major Ahmed\AppData\Local\Programs\Python\Python37\lib\site-packages\dateutil\parser.py", line 1168, in parse
    return DEFAULTPARSER.parse(timestr, **kwargs)
  File "C:\Users\Major Ahmed\AppData\Local\Programs\Python\Python37\lib\site-packages\dateutil\parser.py", line 556, in parse
    res, skipped_tokens = self._parse(timestr, **kwargs)
  File "C:\Users\Major Ahmed\AppData\Local\Programs\Python\Python37\lib\site-packages\dateutil\parser.py", line 675, in _parse
    l = _timelex.split(timestr)         # Splits the timestr into tokens
  File "C:\Users\Major Ahmed\AppData\Local\Programs\Python\Python37\lib\site-packages\dateutil\parser.py", line 192, in split
    return list(cls(s))
  File "C:\Users\Major Ahmed\AppData\Local\Programs\Python\Python37\lib\site-packages\dateutil\parser.py", line 61, in __init__
    '{itype}'.format(itype=instream.__class__.__name__))
TypeError: Parser must be a string or character stream, not datetime
2020-09-21 16:25:09,653 INFO: errors [in C:/Projects/Udacity/Python/Fyyur/app.py:563]
2020-09-21 16:25:11,645 ERROR: Exception on /venues/11 [GET] [in C:\Users\Major Ahmed\AppData\Local\Programs\Python\Python37\lib\site-packages\flask\app.py:1892]
Traceback (most recent call last):
  File "C:\Users\Major Ahmed\AppData\Local\Programs\Python\Python37\lib\site-packages\flask\app.py", line 2447, in wsgi_app
    response = self.full_dispatch_request()
  File "C:\Users\Major Ahmed\AppData\Local\Programs\Python\Python37\lib\site-packages\flask\app.py", line 1952, in full_dispatch_request
    rv = self.handle_user_exception(e)
  File "C:\Users\Major Ahmed\AppData\Local\Programs\Python\Python37\lib\site-packages\flask\app.py", line 1821, in handle_user_exception
    reraise(exc_type, exc_value, tb)
  File "C:\Users\Major Ahmed\AppData\Local\Programs\Python\Python37\lib\site-packages\flask\_compat.py", line 39, in reraise
    raise value
  File "C:\Users\Major Ahmed\AppData\Local\Programs\Python\Python37\lib\site-packages\flask\app.py", line 1950, in full_dispatch_request
    rv = self.dispatch_request()
  File "C:\Users\Major Ahmed\AppData\Local\Programs\Python\Python37\lib\site-packages\flask\app.py", line 1936, in dispatch_request
    return self.view_functions[rule.endpoint](**req.view_args)
  File "C:/Projects/Udacity/Python/Fyyur/app.py", line 266, in show_venue
    return render_template('pages/show_venue.html', venue=data)
  File "C:\Users\Major Ahmed\AppData\Local\Programs\Python\Python37\lib\site-packages\flask\templating.py", line 140, in render_template
    ctx.app,
  File "C:\Users\Major Ahmed\AppData\Local\Programs\Python\Python37\lib\site-packages\flask\templating.py", line 120, in _render
    rv = template.render(context)
  File "C:\Users\Major Ahmed\AppData\Local\Programs\Python\Python37\lib\site-packages\jinja2\environment.py", line 1090, in render
    self.environment.handle_exception()
  File "C:\Users\Major Ahmed\AppData\Local\Programs\Python\Python37\lib\site-packages\jinja2\environment.py", line 832, in handle_exception
    reraise(*rewrite_traceback_stack(source=source))
  File "C:\Users\Major Ahmed\AppData\Local\Programs\Python\Python37\lib\site-packages\jinja2\_compat.py", line 28, in reraise
    raise value.with_traceback(tb)
  File "C:\Projects\Udacity\Python\Fyyur\templates\pages\show_venue.html", line 1, in top-level template code
    {% extends 'layouts/main.html' %}
  File "C:\Projects\Udacity\Python\Fyyur\templates\layouts\main.html", line 103, in top-level template code
    {% block content %}{% endblock %}
  File "C:\Projects\Udacity\Python\Fyyur\templates\pages\show_venue.html", line 57, in block "content"
    <h6>{{ show.start_time|datetime('full') }}</h6>
  File "C:/Projects/Udacity/Python/Fyyur/app.py", line 138, in format_datetime
    return babel.dates.format_datetime(date, format)
  File "C:\Users\Major Ahmed\AppData\Local\Programs\Python\Python37\lib\site-packages\babel\dates.py", line 738, in format_datetime
    return parse_pattern(format).apply(datetime, locale)
  File "C:\Users\Major Ahmed\AppData\Local\Programs\Python\Python37\lib\site-packages\babel\dates.py", line 1232, in apply
    return self % DateTimeFormat(datetime, locale)
  File "C:\Users\Major Ahmed\AppData\Local\Programs\Python\Python37\lib\site-packages\babel\dates.py", line 1229, in __mod__
    return self.format % other
  File "C:\Users\Major Ahmed\AppData\Local\Programs\Python\Python37\lib\site-packages\babel\dates.py", line 1264, in __getitem__
    return self.format_weekday(char, num)
  File "C:\Users\Major Ahmed\AppData\Local\Programs\Python\Python37\lib\site-packages\babel\dates.py", line 1397, in format_weekday
    return get_day_names(width, context, self.locale)[weekday]
  File "C:\Users\Major Ahmed\AppData\Local\Programs\Python\Python37\lib\site-packages\babel\dates.py", line 314, in get_day_names
    return Locale.parse(locale).days[context][width]
AttributeError: 'NoneType' object has no attribute 'days'
2020-09-21 16:26:24,846 INFO: errors [in C:/Projects/Udacity/Python/Fyyur/app.py:563]
2020-09-21 16:26:27,108 ERROR: Exception on /venues/11 [GET] [in C:\Users\Major Ahmed\AppData\Local\Programs\Python\Python37\lib\site-packages\flask\app.py:1892]
Traceback (most recent call last):
  File "C:\Users\Major Ahmed\AppData\Local\Programs\Python\Python37\lib\site-packages\flask\app.py", line 2447, in wsgi_app
    response = self.full_dispatch_request()
  File "C:\Users\Major Ahmed\AppData\Local\Programs\Python\Python37\lib\site-packages\flask\app.py", line 1952, in full_dispatch_request
    rv = self.handle_user_exception(e)
  File "C:\Users\Major Ahmed\AppData\Local\Programs\Python\Python37\lib\site-packages\flask\app.py", line 1821, in handle_user_exception
    reraise(exc_type, exc_value, tb)
  File "C:\Users\Major Ahmed\AppData\Local\Programs\Python\Python37\lib\site-packages\flask\_compat.py", line 39, in reraise
    raise value
  File "C:\Users\Major Ahmed\AppData\Local\Programs\Python\Python37\lib\site-packages\flask\app.py", line 1950, in full_dispatch_request
    rv = self.dispatch_request()
  File "C:\Users\Major Ahmed\AppData\Local\Programs\Python\Python37\lib\site-packages\flask\app.py", line 1936, in dispatch_request
    return self.view_functions[rule.endpoint](**req.view_args)
  File "C:/Projects/Udacity/Python/Fyyur/app.py", line 230, in show_venue
    "start_time": format_datetime(show.show_date)
  File "C:/Projects/Udacity/Python/Fyyur/app.py", line 133, in format_datetime
    date = dateutil.parser.parse(value)
  File "C:\Users\Major Ahmed\AppData\Local\Programs\Python\Python37\lib\site-packages\dateutil\parser.py", line 1168, in parse
    return DEFAULTPARSER.parse(timestr, **kwargs)
  File "C:\Users\Major Ahmed\AppData\Local\Programs\Python\Python37\lib\site-packages\dateutil\parser.py", line 556, in parse
    res, skipped_tokens = self._parse(timestr, **kwargs)
  File "C:\Users\Major Ahmed\AppData\Local\Programs\Python\Python37\lib\site-packages\dateutil\parser.py", line 675, in _parse
    l = _timelex.split(timestr)         # Splits the timestr into tokens
  File "C:\Users\Major Ahmed\AppData\Local\Programs\Python\Python37\lib\site-packages\dateutil\parser.py", line 192, in split
    return list(cls(s))
  File "C:\Users\Major Ahmed\AppData\Local\Programs\Python\Python37\lib\site-packages\dateutil\parser.py", line 61, in __init__
    '{itype}'.format(itype=instream.__class__.__name__))
TypeError: Parser must be a string or character stream, not datetime
2020-09-21 16:27:02,273 INFO: errors [in C:/Projects/Udacity/Python/Fyyur/app.py:563]
2020-09-21 16:27:05,052 ERROR: Exception on /venues/11 [GET] [in C:\Users\Major Ahmed\AppData\Local\Programs\Python\Python37\lib\site-packages\flask\app.py:1892]
Traceback (most recent call last):
  File "C:\Users\Major Ahmed\AppData\Local\Programs\Python\Python37\lib\site-packages\flask\app.py", line 2447, in wsgi_app
    response = self.full_dispatch_request()
  File "C:\Users\Major Ahmed\AppData\Local\Programs\Python\Python37\lib\site-packages\flask\app.py", line 1952, in full_dispatch_request
    rv = self.handle_user_exception(e)
  File "C:\Users\Major Ahmed\AppData\Local\Programs\Python\Python37\lib\site-packages\flask\app.py", line 1821, in handle_user_exception
    reraise(exc_type, exc_value, tb)
  File "C:\Users\Major Ahmed\AppData\Local\Programs\Python\Python37\lib\site-packages\flask\_compat.py", line 39, in reraise
    raise value
  File "C:\Users\Major Ahmed\AppData\Local\Programs\Python\Python37\lib\site-packages\flask\app.py", line 1950, in full_dispatch_request
    rv = self.dispatch_request()
  File "C:\Users\Major Ahmed\AppData\Local\Programs\Python\Python37\lib\site-packages\flask\app.py", line 1936, in dispatch_request
    return self.view_functions[rule.endpoint](**req.view_args)
  File "C:/Projects/Udacity/Python/Fyyur/app.py", line 230, in show_venue
    "start_time": format_datetime(str(show.show_date))
  File "C:/Projects/Udacity/Python/Fyyur/app.py", line 138, in format_datetime
    return babel.dates.format_datetime(date, format)
  File "C:\Users\Major Ahmed\AppData\Local\Programs\Python\Python37\lib\site-packages\babel\dates.py", line 738, in format_datetime
    return parse_pattern(format).apply(datetime, locale)
  File "C:\Users\Major Ahmed\AppData\Local\Programs\Python\Python37\lib\site-packages\babel\dates.py", line 1232, in apply
    return self % DateTimeFormat(datetime, locale)
  File "C:\Users\Major Ahmed\AppData\Local\Programs\Python\Python37\lib\site-packages\babel\dates.py", line 1229, in __mod__
    return self.format % other
  File "C:\Users\Major Ahmed\AppData\Local\Programs\Python\Python37\lib\site-packages\babel\dates.py", line 1264, in __getitem__
    return self.format_weekday(char, num)
  File "C:\Users\Major Ahmed\AppData\Local\Programs\Python\Python37\lib\site-packages\babel\dates.py", line 1397, in format_weekday
    return get_day_names(width, context, self.locale)[weekday]
  File "C:\Users\Major Ahmed\AppData\Local\Programs\Python\Python37\lib\site-packages\babel\dates.py", line 314, in get_day_names
    return Locale.parse(locale).days[context][width]
AttributeError: 'NoneType' object has no attribute 'days'
2020-09-21 16:28:48,458 INFO: errors [in C:/Projects/Udacity/Python/Fyyur/app.py:563]
2020-09-21 16:28:50,780 ERROR: Exception on /venues/11 [GET] [in C:\Users\Major Ahmed\AppData\Local\Programs\Python\Python37\lib\site-packages\flask\app.py:1892]
Traceback (most recent call last):
  File "C:\Users\Major Ahmed\AppData\Local\Programs\Python\Python37\lib\site-packages\flask\app.py", line 2447, in wsgi_app
    response = self.full_dispatch_request()
  File "C:\Users\Major Ahmed\AppData\Local\Programs\Python\Python37\lib\site-packages\flask\app.py", line 1952, in full_dispatch_request
    rv = self.handle_user_exception(e)
  File "C:\Users\Major Ahmed\AppData\Local\Programs\Python\Python37\lib\site-packages\flask\app.py", line 1821, in handle_user_exception
    reraise(exc_type, exc_value, tb)
  File "C:\Users\Major Ahmed\AppData\Local\Programs\Python\Python37\lib\site-packages\flask\_compat.py", line 39, in reraise
    raise value
  File "C:\Users\Major Ahmed\AppData\Local\Programs\Python\Python37\lib\site-packages\flask\app.py", line 1950, in full_dispatch_request
    rv = self.dispatch_request()
  File "C:\Users\Major Ahmed\AppData\Local\Programs\Python\Python37\lib\site-packages\flask\app.py", line 1936, in dispatch_request
    return self.view_functions[rule.endpoint](**req.view_args)
  File "C:/Projects/Udacity/Python/Fyyur/app.py", line 266, in show_venue
    return render_template('pages/show_venue.html', venue=data)
  File "C:\Users\Major Ahmed\AppData\Local\Programs\Python\Python37\lib\site-packages\flask\templating.py", line 140, in render_template
    ctx.app,
  File "C:\Users\Major Ahmed\AppData\Local\Programs\Python\Python37\lib\site-packages\flask\templating.py", line 120, in _render
    rv = template.render(context)
  File "C:\Users\Major Ahmed\AppData\Local\Programs\Python\Python37\lib\site-packages\jinja2\environment.py", line 1090, in render
    self.environment.handle_exception()
  File "C:\Users\Major Ahmed\AppData\Local\Programs\Python\Python37\lib\site-packages\jinja2\environment.py", line 832, in handle_exception
    reraise(*rewrite_traceback_stack(source=source))
  File "C:\Users\Major Ahmed\AppData\Local\Programs\Python\Python37\lib\site-packages\jinja2\_compat.py", line 28, in reraise
    raise value.with_traceback(tb)
  File "C:\Projects\Udacity\Python\Fyyur\templates\pages\show_venue.html", line 1, in top-level template code
    {% extends 'layouts/main.html' %}
  File "C:\Projects\Udacity\Python\Fyyur\templates\layouts\main.html", line 103, in top-level template code
    {% block content %}{% endblock %}
  File "C:\Projects\Udacity\Python\Fyyur\templates\pages\show_venue.html", line 57, in block "content"
    <h6>{{ show.start_time|datetime('full') }}</h6>
  File "C:/Projects/Udacity/Python/Fyyur/app.py", line 138, in format_datetime
    return babel.dates.format_datetime(date, format)
  File "C:\Users\Major Ahmed\AppData\Local\Programs\Python\Python37\lib\site-packages\babel\dates.py", line 738, in format_datetime
    return parse_pattern(format).apply(datetime, locale)
  File "C:\Users\Major Ahmed\AppData\Local\Programs\Python\Python37\lib\site-packages\babel\dates.py", line 1232, in apply
    return self % DateTimeFormat(datetime, locale)
  File "C:\Users\Major Ahmed\AppData\Local\Programs\Python\Python37\lib\site-packages\babel\dates.py", line 1229, in __mod__
    return self.format % other
  File "C:\Users\Major Ahmed\AppData\Local\Programs\Python\Python37\lib\site-packages\babel\dates.py", line 1264, in __getitem__
    return self.format_weekday(char, num)
  File "C:\Users\Major Ahmed\AppData\Local\Programs\Python\Python37\lib\site-packages\babel\dates.py", line 1397, in format_weekday
    return get_day_names(width, context, self.locale)[weekday]
  File "C:\Users\Major Ahmed\AppData\Local\Programs\Python\Python37\lib\site-packages\babel\dates.py", line 314, in get_day_names
    return Locale.parse(locale).days[context][width]
AttributeError: 'NoneType' object has no attribute 'days'
2020-09-21 16:31:53,371 INFO: errors [in C:/Projects/Udacity/Python/Fyyur/app.py:563]
2020-09-21 16:32:22,086 INFO: errors [in C:/Projects/Udacity/Python/Fyyur/app.py:563]
2020-09-21 16:32:33,714 INFO: errors [in C:/Projects/Udacity/Python/Fyyur/app.py:563]
2020-09-21 16:32:48,286 INFO: errors [in C:/Projects/Udacity/Python/Fyyur/app.py:563]
2020-09-21 16:35:04,785 INFO: errors [in C:/Projects/Udacity/Python/Fyyur/app.py:565]
2020-09-21 16:35:07,028 ERROR: Exception on /venues/11 [GET] [in C:\Users\Major Ahmed\AppData\Local\Programs\Python\Python37\lib\site-packages\flask\app.py:1892]
Traceback (most recent call last):
  File "C:\Users\Major Ahmed\AppData\Local\Programs\Python\Python37\lib\site-packages\flask\app.py", line 2447, in wsgi_app
    response = self.full_dispatch_request()
  File "C:\Users\Major Ahmed\AppData\Local\Programs\Python\Python37\lib\site-packages\flask\app.py", line 1952, in full_dispatch_request
    rv = self.handle_user_exception(e)
  File "C:\Users\Major Ahmed\AppData\Local\Programs\Python\Python37\lib\site-packages\flask\app.py", line 1821, in handle_user_exception
    reraise(exc_type, exc_value, tb)
  File "C:\Users\Major Ahmed\AppData\Local\Programs\Python\Python37\lib\site-packages\flask\_compat.py", line 39, in reraise
    raise value
  File "C:\Users\Major Ahmed\AppData\Local\Programs\Python\Python37\lib\site-packages\flask\app.py", line 1950, in full_dispatch_request
    rv = self.dispatch_request()
  File "C:\Users\Major Ahmed\AppData\Local\Programs\Python\Python37\lib\site-packages\flask\app.py", line 1936, in dispatch_request
    return self.view_functions[rule.endpoint](**req.view_args)
  File "C:/Projects/Udacity/Python/Fyyur/app.py", line 268, in show_venue
    return render_template('pages/show_venue.html', venue=data)
  File "C:\Users\Major Ahmed\AppData\Local\Programs\Python\Python37\lib\site-packages\flask\templating.py", line 140, in render_template
    ctx.app,
  File "C:\Users\Major Ahmed\AppData\Local\Programs\Python\Python37\lib\site-packages\flask\templating.py", line 120, in _render
    rv = template.render(context)
  File "C:\Users\Major Ahmed\AppData\Local\Programs\Python\Python37\lib\site-packages\jinja2\environment.py", line 1090, in render
    self.environment.handle_exception()
  File "C:\Users\Major Ahmed\AppData\Local\Programs\Python\Python37\lib\site-packages\jinja2\environment.py", line 832, in handle_exception
    reraise(*rewrite_traceback_stack(source=source))
  File "C:\Users\Major Ahmed\AppData\Local\Programs\Python\Python37\lib\site-packages\jinja2\_compat.py", line 28, in reraise
    raise value.with_traceback(tb)
  File "C:\Projects\Udacity\Python\Fyyur\templates\pages\show_venue.html", line 1, in top-level template code
    {% extends 'layouts/main.html' %}
  File "C:\Projects\Udacity\Python\Fyyur\templates\layouts\main.html", line 103, in top-level template code
    {% block content %}{% endblock %}
  File "C:\Projects\Udacity\Python\Fyyur\templates\pages\show_venue.html", line 57, in block "content"
    <h6>{{ show.start_time|datetime('full') }}</h6>
  File "C:/Projects/Udacity/Python/Fyyur/app.py", line 133, in format_datetime
    date = dateutil.parser.parse(value)
  File "C:\Users\Major Ahmed\AppData\Local\Programs\Python\Python37\lib\site-packages\dateutil\parser.py", line 1168, in parse
    return DEFAULTPARSER.parse(timestr, **kwargs)
  File "C:\Users\Major Ahmed\AppData\Local\Programs\Python\Python37\lib\site-packages\dateutil\parser.py", line 556, in parse
    res, skipped_tokens = self._parse(timestr, **kwargs)
  File "C:\Users\Major Ahmed\AppData\Local\Programs\Python\Python37\lib\site-packages\dateutil\parser.py", line 675, in _parse
    l = _timelex.split(timestr)         # Splits the timestr into tokens
  File "C:\Users\Major Ahmed\AppData\Local\Programs\Python\Python37\lib\site-packages\dateutil\parser.py", line 192, in split
    return list(cls(s))
  File "C:\Users\Major Ahmed\AppData\Local\Programs\Python\Python37\lib\site-packages\dateutil\parser.py", line 59, in __init__
    if getattr(instream, 'read', None) is None:
jinja2.exceptions.UndefinedError: 'dict object' has no attribute 'start_time'
2020-09-21 16:36:28,524 INFO: errors [in C:/Projects/Udacity/Python/Fyyur/app.py:567]
2020-09-21 16:36:31,254 ERROR: Exception on /venues/11 [GET] [in C:\Users\Major Ahmed\AppData\Local\Programs\Python\Python37\lib\site-packages\flask\app.py:1892]
Traceback (most recent call last):
  File "C:\Users\Major Ahmed\AppData\Local\Programs\Python\Python37\lib\site-packages\flask\app.py", line 2447, in wsgi_app
    response = self.full_dispatch_request()
  File "C:\Users\Major Ahmed\AppData\Local\Programs\Python\Python37\lib\site-packages\flask\app.py", line 1952, in full_dispatch_request
    rv = self.handle_user_exception(e)
  File "C:\Users\Major Ahmed\AppData\Local\Programs\Python\Python37\lib\site-packages\flask\app.py", line 1821, in handle_user_exception
    reraise(exc_type, exc_value, tb)
  File "C:\Users\Major Ahmed\AppData\Local\Programs\Python\Python37\lib\site-packages\flask\_compat.py", line 39, in reraise
    raise value
  File "C:\Users\Major Ahmed\AppData\Local\Programs\Python\Python37\lib\site-packages\flask\app.py", line 1950, in full_dispatch_request
    rv = self.dispatch_request()
  File "C:\Users\Major Ahmed\AppData\Local\Programs\Python\Python37\lib\site-packages\flask\app.py", line 1936, in dispatch_request
    return self.view_functions[rule.endpoint](**req.view_args)
  File "C:/Projects/Udacity/Python/Fyyur/app.py", line 270, in show_venue
    return render_template('pages/show_venue.html', venue=data)
  File "C:\Users\Major Ahmed\AppData\Local\Programs\Python\Python37\lib\site-packages\flask\templating.py", line 140, in render_template
    ctx.app,
  File "C:\Users\Major Ahmed\AppData\Local\Programs\Python\Python37\lib\site-packages\flask\templating.py", line 120, in _render
    rv = template.render(context)
  File "C:\Users\Major Ahmed\AppData\Local\Programs\Python\Python37\lib\site-packages\jinja2\environment.py", line 1090, in render
    self.environment.handle_exception()
  File "C:\Users\Major Ahmed\AppData\Local\Programs\Python\Python37\lib\site-packages\jinja2\environment.py", line 832, in handle_exception
    reraise(*rewrite_traceback_stack(source=source))
  File "C:\Users\Major Ahmed\AppData\Local\Programs\Python\Python37\lib\site-packages\jinja2\_compat.py", line 28, in reraise
    raise value.with_traceback(tb)
  File "C:\Projects\Udacity\Python\Fyyur\templates\pages\show_venue.html", line 1, in top-level template code
    {% extends 'layouts/main.html' %}
  File "C:\Projects\Udacity\Python\Fyyur\templates\layouts\main.html", line 103, in top-level template code
    {% block content %}{% endblock %}
  File "C:\Projects\Udacity\Python\Fyyur\templates\pages\show_venue.html", line 57, in block "content"
    <h6>{{ show.start_time|datetime('full') }}</h6>
  File "C:/Projects/Udacity/Python/Fyyur/app.py", line 133, in format_datetime
    date = dateutil.parser.parse(value)
  File "C:\Users\Major Ahmed\AppData\Local\Programs\Python\Python37\lib\site-packages\dateutil\parser.py", line 1168, in parse
    return DEFAULTPARSER.parse(timestr, **kwargs)
  File "C:\Users\Major Ahmed\AppData\Local\Programs\Python\Python37\lib\site-packages\dateutil\parser.py", line 556, in parse
    res, skipped_tokens = self._parse(timestr, **kwargs)
  File "C:\Users\Major Ahmed\AppData\Local\Programs\Python\Python37\lib\site-packages\dateutil\parser.py", line 675, in _parse
    l = _timelex.split(timestr)         # Splits the timestr into tokens
  File "C:\Users\Major Ahmed\AppData\Local\Programs\Python\Python37\lib\site-packages\dateutil\parser.py", line 192, in split
    return list(cls(s))
  File "C:\Users\Major Ahmed\AppData\Local\Programs\Python\Python37\lib\site-packages\dateutil\parser.py", line 61, in __init__
    '{itype}'.format(itype=instream.__class__.__name__))
TypeError: Parser must be a string or character stream, not NoneType
2020-09-21 16:37:16,627 INFO: errors [in C:/Projects/Udacity/Python/Fyyur/app.py:565]
2020-09-21 16:37:20,986 ERROR: Exception on /venues/11 [GET] [in C:\Users\Major Ahmed\AppData\Local\Programs\Python\Python37\lib\site-packages\flask\app.py:1892]
Traceback (most recent call last):
  File "C:\Users\Major Ahmed\AppData\Local\Programs\Python\Python37\lib\site-packages\flask\app.py", line 2447, in wsgi_app
    response = self.full_dispatch_request()
  File "C:\Users\Major Ahmed\AppData\Local\Programs\Python\Python37\lib\site-packages\flask\app.py", line 1952, in full_dispatch_request
    rv = self.handle_user_exception(e)
  File "C:\Users\Major Ahmed\AppData\Local\Programs\Python\Python37\lib\site-packages\flask\app.py", line 1821, in handle_user_exception
    reraise(exc_type, exc_value, tb)
  File "C:\Users\Major Ahmed\AppData\Local\Programs\Python\Python37\lib\site-packages\flask\_compat.py", line 39, in reraise
    raise value
  File "C:\Users\Major Ahmed\AppData\Local\Programs\Python\Python37\lib\site-packages\flask\app.py", line 1950, in full_dispatch_request
    rv = self.dispatch_request()
  File "C:\Users\Major Ahmed\AppData\Local\Programs\Python\Python37\lib\site-packages\flask\app.py", line 1936, in dispatch_request
    return self.view_functions[rule.endpoint](**req.view_args)
  File "C:/Projects/Udacity/Python/Fyyur/app.py", line 268, in show_venue
    return render_template('pages/show_venue.html', venue=data)
  File "C:\Users\Major Ahmed\AppData\Local\Programs\Python\Python37\lib\site-packages\flask\templating.py", line 140, in render_template
    ctx.app,
  File "C:\Users\Major Ahmed\AppData\Local\Programs\Python\Python37\lib\site-packages\flask\templating.py", line 120, in _render
    rv = template.render(context)
  File "C:\Users\Major Ahmed\AppData\Local\Programs\Python\Python37\lib\site-packages\jinja2\environment.py", line 1090, in render
    self.environment.handle_exception()
  File "C:\Users\Major Ahmed\AppData\Local\Programs\Python\Python37\lib\site-packages\jinja2\environment.py", line 832, in handle_exception
    reraise(*rewrite_traceback_stack(source=source))
  File "C:\Users\Major Ahmed\AppData\Local\Programs\Python\Python37\lib\site-packages\jinja2\_compat.py", line 28, in reraise
    raise value.with_traceback(tb)
  File "C:\Projects\Udacity\Python\Fyyur\templates\pages\show_venue.html", line 1, in top-level template code
    {% extends 'layouts/main.html' %}
  File "C:\Projects\Udacity\Python\Fyyur\templates\layouts\main.html", line 103, in top-level template code
    {% block content %}{% endblock %}
  File "C:\Projects\Udacity\Python\Fyyur\templates\pages\show_venue.html", line 57, in block "content"
    <h6>{{ show.start_time|datetime('full') }}</h6>
  File "C:/Projects/Udacity/Python/Fyyur/app.py", line 133, in format_datetime
    date = dateutil.parser.parse(value)
  File "C:\Users\Major Ahmed\AppData\Local\Programs\Python\Python37\lib\site-packages\dateutil\parser.py", line 1168, in parse
    return DEFAULTPARSER.parse(timestr, **kwargs)
  File "C:\Users\Major Ahmed\AppData\Local\Programs\Python\Python37\lib\site-packages\dateutil\parser.py", line 556, in parse
    res, skipped_tokens = self._parse(timestr, **kwargs)
  File "C:\Users\Major Ahmed\AppData\Local\Programs\Python\Python37\lib\site-packages\dateutil\parser.py", line 675, in _parse
    l = _timelex.split(timestr)         # Splits the timestr into tokens
  File "C:\Users\Major Ahmed\AppData\Local\Programs\Python\Python37\lib\site-packages\dateutil\parser.py", line 192, in split
    return list(cls(s))
  File "C:\Users\Major Ahmed\AppData\Local\Programs\Python\Python37\lib\site-packages\dateutil\parser.py", line 61, in __init__
    '{itype}'.format(itype=instream.__class__.__name__))
TypeError: Parser must be a string or character stream, not datetime
2020-09-21 16:38:31,520 INFO: errors [in C:/Projects/Udacity/Python/Fyyur/app.py:565]
2020-09-21 16:38:34,143 ERROR: Exception on /venues/11 [GET] [in C:\Users\Major Ahmed\AppData\Local\Programs\Python\Python37\lib\site-packages\flask\app.py:1892]
Traceback (most recent call last):
  File "C:\Users\Major Ahmed\AppData\Local\Programs\Python\Python37\lib\site-packages\flask\app.py", line 2447, in wsgi_app
    response = self.full_dispatch_request()
  File "C:\Users\Major Ahmed\AppData\Local\Programs\Python\Python37\lib\site-packages\flask\app.py", line 1952, in full_dispatch_request
    rv = self.handle_user_exception(e)
  File "C:\Users\Major Ahmed\AppData\Local\Programs\Python\Python37\lib\site-packages\flask\app.py", line 1821, in handle_user_exception
    reraise(exc_type, exc_value, tb)
  File "C:\Users\Major Ahmed\AppData\Local\Programs\Python\Python37\lib\site-packages\flask\_compat.py", line 39, in reraise
    raise value
  File "C:\Users\Major Ahmed\AppData\Local\Programs\Python\Python37\lib\site-packages\flask\app.py", line 1950, in full_dispatch_request
    rv = self.dispatch_request()
  File "C:\Users\Major Ahmed\AppData\Local\Programs\Python\Python37\lib\site-packages\flask\app.py", line 1936, in dispatch_request
    return self.view_functions[rule.endpoint](**req.view_args)
  File "C:/Projects/Udacity/Python/Fyyur/app.py", line 268, in show_venue
    return render_template('pages/show_venue.html', venue=data)
  File "C:\Users\Major Ahmed\AppData\Local\Programs\Python\Python37\lib\site-packages\flask\templating.py", line 140, in render_template
    ctx.app,
  File "C:\Users\Major Ahmed\AppData\Local\Programs\Python\Python37\lib\site-packages\flask\templating.py", line 120, in _render
    rv = template.render(context)
  File "C:\Users\Major Ahmed\AppData\Local\Programs\Python\Python37\lib\site-packages\jinja2\environment.py", line 1090, in render
    self.environment.handle_exception()
  File "C:\Users\Major Ahmed\AppData\Local\Programs\Python\Python37\lib\site-packages\jinja2\environment.py", line 832, in handle_exception
    reraise(*rewrite_traceback_stack(source=source))
  File "C:\Users\Major Ahmed\AppData\Local\Programs\Python\Python37\lib\site-packages\jinja2\_compat.py", line 28, in reraise
    raise value.with_traceback(tb)
  File "C:\Projects\Udacity\Python\Fyyur\templates\pages\show_venue.html", line 1, in top-level template code
    {% extends 'layouts/main.html' %}
  File "C:\Projects\Udacity\Python\Fyyur\templates\layouts\main.html", line 103, in top-level template code
    {% block content %}{% endblock %}
  File "C:\Projects\Udacity\Python\Fyyur\templates\pages\show_venue.html", line 57, in block "content"
    <h6>{{ show.start_time|datetime('full') }}</h6>
  File "C:/Projects/Udacity/Python/Fyyur/app.py", line 133, in format_datetime
    date = dateutil.parser.parse(value)
  File "C:\Users\Major Ahmed\AppData\Local\Programs\Python\Python37\lib\site-packages\dateutil\parser.py", line 1168, in parse
    return DEFAULTPARSER.parse(timestr, **kwargs)
  File "C:\Users\Major Ahmed\AppData\Local\Programs\Python\Python37\lib\site-packages\dateutil\parser.py", line 556, in parse
    res, skipped_tokens = self._parse(timestr, **kwargs)
  File "C:\Users\Major Ahmed\AppData\Local\Programs\Python\Python37\lib\site-packages\dateutil\parser.py", line 675, in _parse
    l = _timelex.split(timestr)         # Splits the timestr into tokens
  File "C:\Users\Major Ahmed\AppData\Local\Programs\Python\Python37\lib\site-packages\dateutil\parser.py", line 192, in split
    return list(cls(s))
  File "C:\Users\Major Ahmed\AppData\Local\Programs\Python\Python37\lib\site-packages\dateutil\parser.py", line 61, in __init__
    '{itype}'.format(itype=instream.__class__.__name__))
TypeError: Parser must be a string or character stream, not builtin_function_or_method
2020-09-21 16:39:08,396 INFO: errors [in C:/Projects/Udacity/Python/Fyyur/app.py:565]
2020-09-21 16:39:23,038 INFO: errors [in C:/Projects/Udacity/Python/Fyyur/app.py:565]
2020-09-21 16:46:48,686 INFO: errors [in C:/Projects/Udacity/Python/Fyyur/app.py:567]
2020-09-21 16:49:00,517 INFO: errors [in C:/Projects/Udacity/Python/Fyyur/app.py:567]
2020-09-21 16:49:19,355 INFO: errors [in C:/Projects/Udacity/Python/Fyyur/app.py:567]
2020-09-21 16:49:35,823 INFO: errors [in C:/Projects/Udacity/Python/Fyyur/app.py:567]
2020-09-21 16:51:47,987 ERROR: Exception on /venues/11 [GET] [in C:\Users\Major Ahmed\AppData\Local\Programs\Python\Python37\lib\site-packages\flask\app.py:1892]
Traceback (most recent call last):
  File "C:\Users\Major Ahmed\AppData\Local\Programs\Python\Python37\lib\site-packages\flask\app.py", line 2447, in wsgi_app
    response = self.full_dispatch_request()
  File "C:\Users\Major Ahmed\AppData\Local\Programs\Python\Python37\lib\site-packages\flask\app.py", line 1952, in full_dispatch_request
    rv = self.handle_user_exception(e)
  File "C:\Users\Major Ahmed\AppData\Local\Programs\Python\Python37\lib\site-packages\flask\app.py", line 1821, in handle_user_exception
    reraise(exc_type, exc_value, tb)
  File "C:\Users\Major Ahmed\AppData\Local\Programs\Python\Python37\lib\site-packages\flask\_compat.py", line 39, in reraise
    raise value
  File "C:\Users\Major Ahmed\AppData\Local\Programs\Python\Python37\lib\site-packages\flask\app.py", line 1950, in full_dispatch_request
    rv = self.dispatch_request()
  File "C:\Users\Major Ahmed\AppData\Local\Programs\Python\Python37\lib\site-packages\flask\app.py", line 1936, in dispatch_request
    return self.view_functions[rule.endpoint](**req.view_args)
  File "C:/Projects/Udacity/Python/Fyyur/app.py", line 270, in show_venue
    return render_template('pages/show_venue.html', venue=data)
  File "C:\Users\Major Ahmed\AppData\Local\Programs\Python\Python37\lib\site-packages\flask\templating.py", line 140, in render_template
    ctx.app,
  File "C:\Users\Major Ahmed\AppData\Local\Programs\Python\Python37\lib\site-packages\flask\templating.py", line 120, in _render
    rv = template.render(context)
  File "C:\Users\Major Ahmed\AppData\Local\Programs\Python\Python37\lib\site-packages\jinja2\environment.py", line 1090, in render
    self.environment.handle_exception()
  File "C:\Users\Major Ahmed\AppData\Local\Programs\Python\Python37\lib\site-packages\jinja2\environment.py", line 832, in handle_exception
    reraise(*rewrite_traceback_stack(source=source))
  File "C:\Users\Major Ahmed\AppData\Local\Programs\Python\Python37\lib\site-packages\jinja2\_compat.py", line 28, in reraise
    raise value.with_traceback(tb)
  File "C:\Projects\Udacity\Python\Fyyur\templates\pages\show_venue.html", line 1, in top-level template code
    {% extends 'layouts/main.html' %}
  File "C:\Projects\Udacity\Python\Fyyur\templates\layouts\main.html", line 103, in top-level template code
    {% block content %}{% endblock %}
  File "C:\Projects\Udacity\Python\Fyyur\templates\pages\show_venue.html", line 57, in block "content"
    <h6>{{ show.start_time|datetime('full') }}</h6>
  File "C:/Projects/Udacity/Python/Fyyur/app.py", line 133, in format_datetime
    date = dateutil.parser.parse(value)
  File "C:\Users\Major Ahmed\AppData\Local\Programs\Python\Python37\lib\site-packages\dateutil\parser.py", line 1168, in parse
    return DEFAULTPARSER.parse(timestr, **kwargs)
  File "C:\Users\Major Ahmed\AppData\Local\Programs\Python\Python37\lib\site-packages\dateutil\parser.py", line 556, in parse
    res, skipped_tokens = self._parse(timestr, **kwargs)
  File "C:\Users\Major Ahmed\AppData\Local\Programs\Python\Python37\lib\site-packages\dateutil\parser.py", line 675, in _parse
    l = _timelex.split(timestr)         # Splits the timestr into tokens
  File "C:\Users\Major Ahmed\AppData\Local\Programs\Python\Python37\lib\site-packages\dateutil\parser.py", line 192, in split
    return list(cls(s))
  File "C:\Users\Major Ahmed\AppData\Local\Programs\Python\Python37\lib\site-packages\dateutil\parser.py", line 61, in __init__
    '{itype}'.format(itype=instream.__class__.__name__))
TypeError: Parser must be a string or character stream, not builtin_function_or_method
2020-09-21 16:52:33,007 INFO: errors [in C:/Projects/Udacity/Python/Fyyur/app.py:567]
2020-09-21 16:52:35,153 ERROR: Exception on /venues/11 [GET] [in C:\Users\Major Ahmed\AppData\Local\Programs\Python\Python37\lib\site-packages\flask\app.py:1892]
Traceback (most recent call last):
  File "C:\Users\Major Ahmed\AppData\Local\Programs\Python\Python37\lib\site-packages\flask\app.py", line 2447, in wsgi_app
    response = self.full_dispatch_request()
  File "C:\Users\Major Ahmed\AppData\Local\Programs\Python\Python37\lib\site-packages\flask\app.py", line 1952, in full_dispatch_request
    rv = self.handle_user_exception(e)
  File "C:\Users\Major Ahmed\AppData\Local\Programs\Python\Python37\lib\site-packages\flask\app.py", line 1821, in handle_user_exception
    reraise(exc_type, exc_value, tb)
  File "C:\Users\Major Ahmed\AppData\Local\Programs\Python\Python37\lib\site-packages\flask\_compat.py", line 39, in reraise
    raise value
  File "C:\Users\Major Ahmed\AppData\Local\Programs\Python\Python37\lib\site-packages\flask\app.py", line 1950, in full_dispatch_request
    rv = self.dispatch_request()
  File "C:\Users\Major Ahmed\AppData\Local\Programs\Python\Python37\lib\site-packages\flask\app.py", line 1936, in dispatch_request
    return self.view_functions[rule.endpoint](**req.view_args)
  File "C:/Projects/Udacity/Python/Fyyur/app.py", line 270, in show_venue
    return render_template('pages/show_venue.html', venue=data)
  File "C:\Users\Major Ahmed\AppData\Local\Programs\Python\Python37\lib\site-packages\flask\templating.py", line 140, in render_template
    ctx.app,
  File "C:\Users\Major Ahmed\AppData\Local\Programs\Python\Python37\lib\site-packages\flask\templating.py", line 120, in _render
    rv = template.render(context)
  File "C:\Users\Major Ahmed\AppData\Local\Programs\Python\Python37\lib\site-packages\jinja2\environment.py", line 1090, in render
    self.environment.handle_exception()
  File "C:\Users\Major Ahmed\AppData\Local\Programs\Python\Python37\lib\site-packages\jinja2\environment.py", line 832, in handle_exception
    reraise(*rewrite_traceback_stack(source=source))
  File "C:\Users\Major Ahmed\AppData\Local\Programs\Python\Python37\lib\site-packages\jinja2\_compat.py", line 28, in reraise
    raise value.with_traceback(tb)
  File "C:\Projects\Udacity\Python\Fyyur\templates\pages\show_venue.html", line 1, in top-level template code
    {% extends 'layouts/main.html' %}
  File "C:\Projects\Udacity\Python\Fyyur\templates\layouts\main.html", line 103, in top-level template code
    {% block content %}{% endblock %}
  File "C:\Projects\Udacity\Python\Fyyur\templates\pages\show_venue.html", line 57, in block "content"
    <h6>{{ show.start_time|datetime('full') }}</h6>
  File "C:/Projects/Udacity/Python/Fyyur/app.py", line 138, in format_datetime
    return babel.dates.format_datetime(date, format)
  File "C:\Users\Major Ahmed\AppData\Local\Programs\Python\Python37\lib\site-packages\babel\dates.py", line 738, in format_datetime
    return parse_pattern(format).apply(datetime, locale)
  File "C:\Users\Major Ahmed\AppData\Local\Programs\Python\Python37\lib\site-packages\babel\dates.py", line 1232, in apply
    return self % DateTimeFormat(datetime, locale)
  File "C:\Users\Major Ahmed\AppData\Local\Programs\Python\Python37\lib\site-packages\babel\dates.py", line 1229, in __mod__
    return self.format % other
  File "C:\Users\Major Ahmed\AppData\Local\Programs\Python\Python37\lib\site-packages\babel\dates.py", line 1264, in __getitem__
    return self.format_weekday(char, num)
  File "C:\Users\Major Ahmed\AppData\Local\Programs\Python\Python37\lib\site-packages\babel\dates.py", line 1397, in format_weekday
    return get_day_names(width, context, self.locale)[weekday]
  File "C:\Users\Major Ahmed\AppData\Local\Programs\Python\Python37\lib\site-packages\babel\dates.py", line 314, in get_day_names
    return Locale.parse(locale).days[context][width]
AttributeError: 'NoneType' object has no attribute 'days'
2020-09-21 16:58:29,649 INFO: errors [in C:/Projects/Udacity/Python/Fyyur/app.py:561]
2020-09-21 16:58:32,838 ERROR: Exception on /venues/11 [GET] [in C:\Users\Major Ahmed\AppData\Local\Programs\Python\Python37\lib\site-packages\flask\app.py:1892]
Traceback (most recent call last):
  File "C:\Users\Major Ahmed\AppData\Local\Programs\Python\Python37\lib\site-packages\flask\app.py", line 2447, in wsgi_app
    response = self.full_dispatch_request()
  File "C:\Users\Major Ahmed\AppData\Local\Programs\Python\Python37\lib\site-packages\flask\app.py", line 1952, in full_dispatch_request
    rv = self.handle_user_exception(e)
  File "C:\Users\Major Ahmed\AppData\Local\Programs\Python\Python37\lib\site-packages\flask\app.py", line 1821, in handle_user_exception
    reraise(exc_type, exc_value, tb)
  File "C:\Users\Major Ahmed\AppData\Local\Programs\Python\Python37\lib\site-packages\flask\_compat.py", line 39, in reraise
    raise value
  File "C:\Users\Major Ahmed\AppData\Local\Programs\Python\Python37\lib\site-packages\flask\app.py", line 1950, in full_dispatch_request
    rv = self.dispatch_request()
  File "C:\Users\Major Ahmed\AppData\Local\Programs\Python\Python37\lib\site-packages\flask\app.py", line 1936, in dispatch_request
    return self.view_functions[rule.endpoint](**req.view_args)
  File "C:/Projects/Udacity/Python/Fyyur/app.py", line 264, in show_venue
    return render_template('pages/show_venue.html', venue=data)
  File "C:\Users\Major Ahmed\AppData\Local\Programs\Python\Python37\lib\site-packages\flask\templating.py", line 140, in render_template
    ctx.app,
  File "C:\Users\Major Ahmed\AppData\Local\Programs\Python\Python37\lib\site-packages\flask\templating.py", line 120, in _render
    rv = template.render(context)
  File "C:\Users\Major Ahmed\AppData\Local\Programs\Python\Python37\lib\site-packages\jinja2\environment.py", line 1090, in render
    self.environment.handle_exception()
  File "C:\Users\Major Ahmed\AppData\Local\Programs\Python\Python37\lib\site-packages\jinja2\environment.py", line 832, in handle_exception
    reraise(*rewrite_traceback_stack(source=source))
  File "C:\Users\Major Ahmed\AppData\Local\Programs\Python\Python37\lib\site-packages\jinja2\_compat.py", line 28, in reraise
    raise value.with_traceback(tb)
  File "C:\Projects\Udacity\Python\Fyyur\templates\pages\show_venue.html", line 1, in top-level template code
    {% extends 'layouts/main.html' %} {% block title %}Venue Search{% endblock %} {%
  File "C:\Projects\Udacity\Python\Fyyur\templates\layouts\main.html", line 103, in top-level template code
    {% block content %}{% endblock %}
  File "C:\Projects\Udacity\Python\Fyyur\templates\pages\show_venue.html", line 72, in block "content"
    <!-- <h6>{{ show.start_time|datetime('full') }}</h6> -->
  File "C:/Projects/Udacity/Python/Fyyur/app.py", line 136, in format_datetime
    return babel.dates.format_datetime(date, format)
  File "C:\Users\Major Ahmed\AppData\Local\Programs\Python\Python37\lib\site-packages\babel\dates.py", line 738, in format_datetime
    return parse_pattern(format).apply(datetime, locale)
  File "C:\Users\Major Ahmed\AppData\Local\Programs\Python\Python37\lib\site-packages\babel\dates.py", line 1232, in apply
    return self % DateTimeFormat(datetime, locale)
  File "C:\Users\Major Ahmed\AppData\Local\Programs\Python\Python37\lib\site-packages\babel\dates.py", line 1229, in __mod__
    return self.format % other
  File "C:\Users\Major Ahmed\AppData\Local\Programs\Python\Python37\lib\site-packages\babel\dates.py", line 1264, in __getitem__
    return self.format_weekday(char, num)
  File "C:\Users\Major Ahmed\AppData\Local\Programs\Python\Python37\lib\site-packages\babel\dates.py", line 1397, in format_weekday
    return get_day_names(width, context, self.locale)[weekday]
  File "C:\Users\Major Ahmed\AppData\Local\Programs\Python\Python37\lib\site-packages\babel\dates.py", line 314, in get_day_names
    return Locale.parse(locale).days[context][width]
AttributeError: 'NoneType' object has no attribute 'days'
2020-09-21 16:59:26,217 INFO: errors [in C:/Projects/Udacity/Python/Fyyur/app.py:561]
2020-09-21 16:59:34,778 ERROR: Exception on /venues/11 [GET] [in C:\Users\Major Ahmed\AppData\Local\Programs\Python\Python37\lib\site-packages\flask\app.py:1892]
Traceback (most recent call last):
  File "C:\Users\Major Ahmed\AppData\Local\Programs\Python\Python37\lib\site-packages\flask\app.py", line 2447, in wsgi_app
    response = self.full_dispatch_request()
  File "C:\Users\Major Ahmed\AppData\Local\Programs\Python\Python37\lib\site-packages\flask\app.py", line 1952, in full_dispatch_request
    rv = self.handle_user_exception(e)
  File "C:\Users\Major Ahmed\AppData\Local\Programs\Python\Python37\lib\site-packages\flask\app.py", line 1821, in handle_user_exception
    reraise(exc_type, exc_value, tb)
  File "C:\Users\Major Ahmed\AppData\Local\Programs\Python\Python37\lib\site-packages\flask\_compat.py", line 39, in reraise
    raise value
  File "C:\Users\Major Ahmed\AppData\Local\Programs\Python\Python37\lib\site-packages\flask\app.py", line 1950, in full_dispatch_request
    rv = self.dispatch_request()
  File "C:\Users\Major Ahmed\AppData\Local\Programs\Python\Python37\lib\site-packages\flask\app.py", line 1936, in dispatch_request
    return self.view_functions[rule.endpoint](**req.view_args)
  File "C:/Projects/Udacity/Python/Fyyur/app.py", line 264, in show_venue
    return render_template('pages/show_venue.html', venue=data)
  File "C:\Users\Major Ahmed\AppData\Local\Programs\Python\Python37\lib\site-packages\flask\templating.py", line 140, in render_template
    ctx.app,
  File "C:\Users\Major Ahmed\AppData\Local\Programs\Python\Python37\lib\site-packages\flask\templating.py", line 120, in _render
    rv = template.render(context)
  File "C:\Users\Major Ahmed\AppData\Local\Programs\Python\Python37\lib\site-packages\jinja2\environment.py", line 1090, in render
    self.environment.handle_exception()
  File "C:\Users\Major Ahmed\AppData\Local\Programs\Python\Python37\lib\site-packages\jinja2\environment.py", line 832, in handle_exception
    reraise(*rewrite_traceback_stack(source=source))
  File "C:\Users\Major Ahmed\AppData\Local\Programs\Python\Python37\lib\site-packages\jinja2\_compat.py", line 28, in reraise
    raise value.with_traceback(tb)
  File "C:\Projects\Udacity\Python\Fyyur\templates\pages\show_venue.html", line 1, in top-level template code
    {% extends 'layouts/main.html' %} {% block title %}Venue Search{% endblock %} {%
  File "C:\Projects\Udacity\Python\Fyyur\templates\layouts\main.html", line 103, in top-level template code
    {% block content %}{% endblock %}
  File "C:\Projects\Udacity\Python\Fyyur\templates\pages\show_venue.html", line 72, in block "content"
    <!-- <h6>{{ show.start_time|datetime('full') }}</h6> -->
  File "C:/Projects/Udacity/Python/Fyyur/app.py", line 136, in format_datetime
    return babel.dates.format_datetime(date, format)
  File "C:\Users\Major Ahmed\AppData\Local\Programs\Python\Python37\lib\site-packages\babel\dates.py", line 738, in format_datetime
    return parse_pattern(format).apply(datetime, locale)
  File "C:\Users\Major Ahmed\AppData\Local\Programs\Python\Python37\lib\site-packages\babel\dates.py", line 1232, in apply
    return self % DateTimeFormat(datetime, locale)
  File "C:\Users\Major Ahmed\AppData\Local\Programs\Python\Python37\lib\site-packages\babel\dates.py", line 1229, in __mod__
    return self.format % other
  File "C:\Users\Major Ahmed\AppData\Local\Programs\Python\Python37\lib\site-packages\babel\dates.py", line 1264, in __getitem__
    return self.format_weekday(char, num)
  File "C:\Users\Major Ahmed\AppData\Local\Programs\Python\Python37\lib\site-packages\babel\dates.py", line 1397, in format_weekday
    return get_day_names(width, context, self.locale)[weekday]
  File "C:\Users\Major Ahmed\AppData\Local\Programs\Python\Python37\lib\site-packages\babel\dates.py", line 314, in get_day_names
    return Locale.parse(locale).days[context][width]
AttributeError: 'NoneType' object has no attribute 'days'
2020-09-21 16:59:35,885 ERROR: Exception on /venues/11 [GET] [in C:\Users\Major Ahmed\AppData\Local\Programs\Python\Python37\lib\site-packages\flask\app.py:1892]
Traceback (most recent call last):
  File "C:\Users\Major Ahmed\AppData\Local\Programs\Python\Python37\lib\site-packages\flask\app.py", line 2447, in wsgi_app
    response = self.full_dispatch_request()
  File "C:\Users\Major Ahmed\AppData\Local\Programs\Python\Python37\lib\site-packages\flask\app.py", line 1952, in full_dispatch_request
    rv = self.handle_user_exception(e)
  File "C:\Users\Major Ahmed\AppData\Local\Programs\Python\Python37\lib\site-packages\flask\app.py", line 1821, in handle_user_exception
    reraise(exc_type, exc_value, tb)
  File "C:\Users\Major Ahmed\AppData\Local\Programs\Python\Python37\lib\site-packages\flask\_compat.py", line 39, in reraise
    raise value
  File "C:\Users\Major Ahmed\AppData\Local\Programs\Python\Python37\lib\site-packages\flask\app.py", line 1950, in full_dispatch_request
    rv = self.dispatch_request()
  File "C:\Users\Major Ahmed\AppData\Local\Programs\Python\Python37\lib\site-packages\flask\app.py", line 1936, in dispatch_request
    return self.view_functions[rule.endpoint](**req.view_args)
  File "C:/Projects/Udacity/Python/Fyyur/app.py", line 264, in show_venue
    return render_template('pages/show_venue.html', venue=data)
  File "C:\Users\Major Ahmed\AppData\Local\Programs\Python\Python37\lib\site-packages\flask\templating.py", line 140, in render_template
    ctx.app,
  File "C:\Users\Major Ahmed\AppData\Local\Programs\Python\Python37\lib\site-packages\flask\templating.py", line 120, in _render
    rv = template.render(context)
  File "C:\Users\Major Ahmed\AppData\Local\Programs\Python\Python37\lib\site-packages\jinja2\environment.py", line 1090, in render
    self.environment.handle_exception()
  File "C:\Users\Major Ahmed\AppData\Local\Programs\Python\Python37\lib\site-packages\jinja2\environment.py", line 832, in handle_exception
    reraise(*rewrite_traceback_stack(source=source))
  File "C:\Users\Major Ahmed\AppData\Local\Programs\Python\Python37\lib\site-packages\jinja2\_compat.py", line 28, in reraise
    raise value.with_traceback(tb)
  File "C:\Projects\Udacity\Python\Fyyur\templates\pages\show_venue.html", line 1, in top-level template code
    {% extends 'layouts/main.html' %} {% block title %}Venue Search{% endblock %} {%
  File "C:\Projects\Udacity\Python\Fyyur\templates\layouts\main.html", line 103, in top-level template code
    {% block content %}{% endblock %}
  File "C:\Projects\Udacity\Python\Fyyur\templates\pages\show_venue.html", line 72, in block "content"
    <!-- <h6>{{ show.start_time|datetime('full') }}</h6> -->
  File "C:/Projects/Udacity/Python/Fyyur/app.py", line 136, in format_datetime
    return babel.dates.format_datetime(date, format)
  File "C:\Users\Major Ahmed\AppData\Local\Programs\Python\Python37\lib\site-packages\babel\dates.py", line 738, in format_datetime
    return parse_pattern(format).apply(datetime, locale)
  File "C:\Users\Major Ahmed\AppData\Local\Programs\Python\Python37\lib\site-packages\babel\dates.py", line 1232, in apply
    return self % DateTimeFormat(datetime, locale)
  File "C:\Users\Major Ahmed\AppData\Local\Programs\Python\Python37\lib\site-packages\babel\dates.py", line 1229, in __mod__
    return self.format % other
  File "C:\Users\Major Ahmed\AppData\Local\Programs\Python\Python37\lib\site-packages\babel\dates.py", line 1264, in __getitem__
    return self.format_weekday(char, num)
  File "C:\Users\Major Ahmed\AppData\Local\Programs\Python\Python37\lib\site-packages\babel\dates.py", line 1397, in format_weekday
    return get_day_names(width, context, self.locale)[weekday]
  File "C:\Users\Major Ahmed\AppData\Local\Programs\Python\Python37\lib\site-packages\babel\dates.py", line 314, in get_day_names
    return Locale.parse(locale).days[context][width]
AttributeError: 'NoneType' object has no attribute 'days'
2020-09-21 17:00:38,552 INFO: errors [in C:/Projects/Udacity/Python/Fyyur/app.py:561]
2020-09-21 17:02:29,903 INFO: errors [in C:/Projects/Udacity/Python/Fyyur/app.py:561]
2020-09-21 17:02:39,084 ERROR: Exception on /venues/11 [GET] [in C:\Users\Major Ahmed\AppData\Local\Programs\Python\Python37\lib\site-packages\flask\app.py:1892]
Traceback (most recent call last):
  File "C:\Users\Major Ahmed\AppData\Local\Programs\Python\Python37\lib\site-packages\flask\app.py", line 2447, in wsgi_app
    response = self.full_dispatch_request()
  File "C:\Users\Major Ahmed\AppData\Local\Programs\Python\Python37\lib\site-packages\flask\app.py", line 1952, in full_dispatch_request
    rv = self.handle_user_exception(e)
  File "C:\Users\Major Ahmed\AppData\Local\Programs\Python\Python37\lib\site-packages\flask\app.py", line 1821, in handle_user_exception
    reraise(exc_type, exc_value, tb)
  File "C:\Users\Major Ahmed\AppData\Local\Programs\Python\Python37\lib\site-packages\flask\_compat.py", line 39, in reraise
    raise value
  File "C:\Users\Major Ahmed\AppData\Local\Programs\Python\Python37\lib\site-packages\flask\app.py", line 1950, in full_dispatch_request
    rv = self.dispatch_request()
  File "C:\Users\Major Ahmed\AppData\Local\Programs\Python\Python37\lib\site-packages\flask\app.py", line 1936, in dispatch_request
    return self.view_functions[rule.endpoint](**req.view_args)
  File "C:/Projects/Udacity/Python/Fyyur/app.py", line 247, in show_venue
    "genres": list(venue.genres),
TypeError: 'NoneType' object is not iterable
2020-09-21 17:16:48,314 INFO: errors [in C:/Projects/Udacity/Python/Fyyur/app.py:561]
2020-09-21 17:18:10,334 INFO: errors [in C:/Projects/Udacity/Python/Fyyur/app.py:561]
2020-09-21 17:22:46,045 ERROR: Exception on /artists/3 [GET] [in C:\Users\Major Ahmed\AppData\Local\Programs\Python\Python37\lib\site-packages\flask\app.py:1892]
Traceback (most recent call last):
  File "C:\Users\Major Ahmed\AppData\Local\Programs\Python\Python37\lib\site-packages\flask\app.py", line 2447, in wsgi_app
    response = self.full_dispatch_request()
  File "C:\Users\Major Ahmed\AppData\Local\Programs\Python\Python37\lib\site-packages\flask\app.py", line 1952, in full_dispatch_request
    rv = self.handle_user_exception(e)
  File "C:\Users\Major Ahmed\AppData\Local\Programs\Python\Python37\lib\site-packages\flask\app.py", line 1821, in handle_user_exception
    reraise(exc_type, exc_value, tb)
  File "C:\Users\Major Ahmed\AppData\Local\Programs\Python\Python37\lib\site-packages\flask\_compat.py", line 39, in reraise
    raise value
  File "C:\Users\Major Ahmed\AppData\Local\Programs\Python\Python37\lib\site-packages\flask\app.py", line 1950, in full_dispatch_request
    rv = self.dispatch_request()
  File "C:\Users\Major Ahmed\AppData\Local\Programs\Python\Python37\lib\site-packages\flask\app.py", line 1936, in dispatch_request
    return self.view_functions[rule.endpoint](**req.view_args)
  File "C:/Projects/Udacity/Python/Fyyur/app.py", line 402, in show_artist
    data = list(filter(lambda d: d['id'] == artist_id, [data1, data2, data3]))[0]
IndexError: list index out of range
2020-09-21 17:40:28,497 INFO: errors [in C:/Projects/Udacity/Python/Fyyur/app.py:561]
2020-09-21 17:42:05,450 INFO: errors [in C:/Projects/Udacity/Python/Fyyur/app.py:561]
2020-09-21 18:37:12,830 INFO: errors [in C:/Projects/Udacity/Python/Fyyur/app.py:561]
2020-09-21 18:43:14,101 INFO: errors [in C:/Projects/Udacity/Python/Fyyur/app.py:561]
2020-09-21 18:45:07,021 INFO: errors [in C:/Projects/Udacity/Python/Fyyur/app.py:561]
2020-09-21 18:46:05,211 INFO: errors [in C:/Projects/Udacity/Python/Fyyur/app.py:561]
2020-09-21 18:46:37,775 INFO: errors [in C:/Projects/Udacity/Python/Fyyur/app.py:561]
2020-09-21 18:50:17,386 INFO: errors [in C:/Projects/Udacity/Python/Fyyur/app.py:561]
2020-09-21 18:52:52,411 INFO: errors [in C:/Projects/Udacity/Python/Fyyur/app.py:561]
2020-09-21 18:53:48,554 INFO: errors [in C:/Projects/Udacity/Python/Fyyur/app.py:561]
2020-09-21 18:55:54,748 INFO: errors [in C:/Projects/Udacity/Python/Fyyur/app.py:561]
2020-09-21 18:56:06,780 ERROR: Exception on /venues/create [POST] [in C:\Users\Major Ahmed\AppData\Local\Programs\Python\Python37\lib\site-packages\flask\app.py:1892]
Traceback (most recent call last):
  File "C:\Users\Major Ahmed\AppData\Local\Programs\Python\Python37\lib\site-packages\flask\app.py", line 2447, in wsgi_app
    response = self.full_dispatch_request()
  File "C:\Users\Major Ahmed\AppData\Local\Programs\Python\Python37\lib\site-packages\flask\app.py", line 1952, in full_dispatch_request
    rv = self.handle_user_exception(e)
  File "C:\Users\Major Ahmed\AppData\Local\Programs\Python\Python37\lib\site-packages\flask\app.py", line 1821, in handle_user_exception
    reraise(exc_type, exc_value, tb)
  File "C:\Users\Major Ahmed\AppData\Local\Programs\Python\Python37\lib\site-packages\flask\_compat.py", line 39, in reraise
    raise value
  File "C:\Users\Major Ahmed\AppData\Local\Programs\Python\Python37\lib\site-packages\flask\app.py", line 1950, in full_dispatch_request
    rv = self.dispatch_request()
  File "C:\Users\Major Ahmed\AppData\Local\Programs\Python\Python37\lib\site-packages\flask\app.py", line 1936, in dispatch_request
    return self.view_functions[rule.endpoint](**req.view_args)
  File "C:/Projects/Udacity/Python/Fyyur/app.py", line 278, in create_venue_submission
    print(request.form.genres)
AttributeError: 'ImmutableMultiDict' object has no attribute 'genres'
2020-09-21 18:56:35,990 INFO: errors [in C:/Projects/Udacity/Python/Fyyur/app.py:561]
2020-09-21 18:59:18,776 INFO: errors [in C:/Projects/Udacity/Python/Fyyur/app.py:568]
2020-09-21 18:59:22,402 ERROR: Exception on /venues/create [POST] [in C:\Users\Major Ahmed\AppData\Local\Programs\Python\Python37\lib\site-packages\flask\app.py:1892]
Traceback (most recent call last):
  File "C:\Users\Major Ahmed\AppData\Local\Programs\Python\Python37\lib\site-packages\flask\app.py", line 2447, in wsgi_app
    response = self.full_dispatch_request()
  File "C:\Users\Major Ahmed\AppData\Local\Programs\Python\Python37\lib\site-packages\flask\app.py", line 1952, in full_dispatch_request
    rv = self.handle_user_exception(e)
  File "C:\Users\Major Ahmed\AppData\Local\Programs\Python\Python37\lib\site-packages\flask\app.py", line 1821, in handle_user_exception
    reraise(exc_type, exc_value, tb)
  File "C:\Users\Major Ahmed\AppData\Local\Programs\Python\Python37\lib\site-packages\flask\_compat.py", line 39, in reraise
    raise value
  File "C:\Users\Major Ahmed\AppData\Local\Programs\Python\Python37\lib\site-packages\flask\app.py", line 1950, in full_dispatch_request
    rv = self.dispatch_request()
  File "C:\Users\Major Ahmed\AppData\Local\Programs\Python\Python37\lib\site-packages\flask\app.py", line 1936, in dispatch_request
    return self.view_functions[rule.endpoint](**req.view_args)
  File "C:/Projects/Udacity/Python/Fyyur/app.py", line 282, in create_venue_submission
    print(request.form.key)
AttributeError: 'ImmutableMultiDict' object has no attribute 'key'
2020-09-21 18:59:53,528 INFO: errors [in C:/Projects/Udacity/Python/Fyyur/app.py:568]
2020-09-21 18:59:56,859 INFO: errors [in C:/Projects/Udacity/Python/Fyyur/app.py:568]
2020-09-21 19:00:38,693 INFO: errors [in C:/Projects/Udacity/Python/Fyyur/app.py:567]
2020-09-21 19:01:31,006 INFO: errors [in C:/Projects/Udacity/Python/Fyyur/app.py:566]
2020-09-21 19:04:12,164 INFO: errors [in C:/Projects/Udacity/Python/Fyyur/app.py:568]
2020-09-21 19:05:20,256 INFO: errors [in C:/Projects/Udacity/Python/Fyyur/app.py:568]
2020-09-21 19:05:26,301 ERROR: Exception on /venues/create [POST] [in C:\Users\Major Ahmed\AppData\Local\Programs\Python\Python37\lib\site-packages\flask\app.py:1892]
Traceback (most recent call last):
  File "C:\Users\Major Ahmed\AppData\Local\Programs\Python\Python37\lib\site-packages\flask\app.py", line 2447, in wsgi_app
    response = self.full_dispatch_request()
  File "C:\Users\Major Ahmed\AppData\Local\Programs\Python\Python37\lib\site-packages\flask\app.py", line 1952, in full_dispatch_request
    rv = self.handle_user_exception(e)
  File "C:\Users\Major Ahmed\AppData\Local\Programs\Python\Python37\lib\site-packages\flask\app.py", line 1821, in handle_user_exception
    reraise(exc_type, exc_value, tb)
  File "C:\Users\Major Ahmed\AppData\Local\Programs\Python\Python37\lib\site-packages\flask\_compat.py", line 39, in reraise
    raise value
  File "C:\Users\Major Ahmed\AppData\Local\Programs\Python\Python37\lib\site-packages\flask\app.py", line 1950, in full_dispatch_request
    rv = self.dispatch_request()
  File "C:\Users\Major Ahmed\AppData\Local\Programs\Python\Python37\lib\site-packages\flask\app.py", line 1936, in dispatch_request
    return self.view_functions[rule.endpoint](**req.view_args)
  File "C:/Projects/Udacity/Python/Fyyur/app.py", line 281, in create_venue_submission
    for k,v in request.form:
ValueError: too many values to unpack (expected 2)
2020-09-21 19:06:14,889 INFO: errors [in C:/Projects/Udacity/Python/Fyyur/app.py:568]
2020-09-21 19:06:55,146 INFO: errors [in C:/Projects/Udacity/Python/Fyyur/app.py:568]
2020-09-21 19:13:00,943 INFO: errors [in C:/Projects/Udacity/Python/Fyyur/app.py:570]
2020-09-21 19:13:06,779 ERROR: Exception on /venues/create [POST] [in C:\Users\Major Ahmed\AppData\Local\Programs\Python\Python37\lib\site-packages\flask\app.py:1892]
Traceback (most recent call last):
  File "C:\Users\Major Ahmed\AppData\Local\Programs\Python\Python37\lib\site-packages\flask\app.py", line 2447, in wsgi_app
    response = self.full_dispatch_request()
  File "C:\Users\Major Ahmed\AppData\Local\Programs\Python\Python37\lib\site-packages\flask\app.py", line 1952, in full_dispatch_request
    rv = self.handle_user_exception(e)
  File "C:\Users\Major Ahmed\AppData\Local\Programs\Python\Python37\lib\site-packages\flask\app.py", line 1821, in handle_user_exception
    reraise(exc_type, exc_value, tb)
  File "C:\Users\Major Ahmed\AppData\Local\Programs\Python\Python37\lib\site-packages\flask\_compat.py", line 39, in reraise
    raise value
  File "C:\Users\Major Ahmed\AppData\Local\Programs\Python\Python37\lib\site-packages\flask\app.py", line 1950, in full_dispatch_request
    rv = self.dispatch_request()
  File "C:\Users\Major Ahmed\AppData\Local\Programs\Python\Python37\lib\site-packages\flask\app.py", line 1936, in dispatch_request
    return self.view_functions[rule.endpoint](**req.view_args)
  File "C:/Projects/Udacity/Python/Fyyur/app.py", line 281, in create_venue_submission
    form = UpdateWidgetForm(request.form)
NameError: name 'UpdateWidgetForm' is not defined
2020-09-21 19:15:02,243 INFO: errors [in C:/Projects/Udacity/Python/Fyyur/app.py:570]
2020-09-21 19:15:44,537 INFO: errors [in C:/Projects/Udacity/Python/Fyyur/app.py:570]
2020-09-21 19:42:34,378 INFO: errors [in C:/Projects/Udacity/Python/Fyyur/app.py:570]
2020-09-21 19:44:25,450 INFO: errors [in C:/Projects/Udacity/Python/Fyyur/app.py:570]
2020-09-21 19:45:59,152 INFO: errors [in C:/Projects/Udacity/Python/Fyyur/app.py:570]
2020-09-21 19:46:10,714 ERROR: Exception on /artists/create [GET] [in C:\Users\Major Ahmed\AppData\Local\Programs\Python\Python37\lib\site-packages\flask\app.py:1892]
Traceback (most recent call last):
  File "C:\Users\Major Ahmed\AppData\Local\Programs\Python\Python37\lib\site-packages\flask\app.py", line 2447, in wsgi_app
    response = self.full_dispatch_request()
  File "C:\Users\Major Ahmed\AppData\Local\Programs\Python\Python37\lib\site-packages\flask\app.py", line 1952, in full_dispatch_request
    rv = self.handle_user_exception(e)
  File "C:\Users\Major Ahmed\AppData\Local\Programs\Python\Python37\lib\site-packages\flask\app.py", line 1821, in handle_user_exception
    reraise(exc_type, exc_value, tb)
  File "C:\Users\Major Ahmed\AppData\Local\Programs\Python\Python37\lib\site-packages\flask\_compat.py", line 39, in reraise
    raise value
  File "C:\Users\Major Ahmed\AppData\Local\Programs\Python\Python37\lib\site-packages\flask\app.py", line 1950, in full_dispatch_request
    rv = self.dispatch_request()
  File "C:\Users\Major Ahmed\AppData\Local\Programs\Python\Python37\lib\site-packages\flask\app.py", line 1936, in dispatch_request
    return self.view_functions[rule.endpoint](**req.view_args)
  File "C:/Projects/Udacity/Python/Fyyur/app.py", line 474, in create_artist_form
    return render_template('forms/new_artist.html', form=form)
  File "C:\Users\Major Ahmed\AppData\Local\Programs\Python\Python37\lib\site-packages\flask\templating.py", line 140, in render_template
    ctx.app,
  File "C:\Users\Major Ahmed\AppData\Local\Programs\Python\Python37\lib\site-packages\flask\templating.py", line 120, in _render
    rv = template.render(context)
  File "C:\Users\Major Ahmed\AppData\Local\Programs\Python\Python37\lib\site-packages\jinja2\environment.py", line 1090, in render
    self.environment.handle_exception()
  File "C:\Users\Major Ahmed\AppData\Local\Programs\Python\Python37\lib\site-packages\jinja2\environment.py", line 832, in handle_exception
    reraise(*rewrite_traceback_stack(source=source))
  File "C:\Users\Major Ahmed\AppData\Local\Programs\Python\Python37\lib\site-packages\jinja2\_compat.py", line 28, in reraise
    raise value.with_traceback(tb)
  File "C:\Projects\Udacity\Python\Fyyur\templates\forms\new_artist.html", line 1, in top-level template code
    {% extends 'layouts/main.html' %} {% block title %}New Artist{% endblock %} {%
  File "C:\Projects\Udacity\Python\Fyyur\templates\layouts\main.html", line 103, in top-level template code
    {% block content %}{% endblock %}
  File "C:\Projects\Udacity\Python\Fyyur\templates\forms\new_artist.html", line 45, in block "content"
    {{ form.seeking_talent(class_ = 'form-control', autofocus = true) }}
jinja2.exceptions.UndefinedError: 'forms.ArtistForm object' has no attribute 'seeking_talent'
2020-09-21 19:46:47,790 ERROR: Exception on /artists/create [GET] [in C:\Users\Major Ahmed\AppData\Local\Programs\Python\Python37\lib\site-packages\flask\app.py:1892]
Traceback (most recent call last):
  File "C:\Users\Major Ahmed\AppData\Local\Programs\Python\Python37\lib\site-packages\flask\app.py", line 2447, in wsgi_app
    response = self.full_dispatch_request()
  File "C:\Users\Major Ahmed\AppData\Local\Programs\Python\Python37\lib\site-packages\flask\app.py", line 1952, in full_dispatch_request
    rv = self.handle_user_exception(e)
  File "C:\Users\Major Ahmed\AppData\Local\Programs\Python\Python37\lib\site-packages\flask\app.py", line 1821, in handle_user_exception
    reraise(exc_type, exc_value, tb)
  File "C:\Users\Major Ahmed\AppData\Local\Programs\Python\Python37\lib\site-packages\flask\_compat.py", line 39, in reraise
    raise value
  File "C:\Users\Major Ahmed\AppData\Local\Programs\Python\Python37\lib\site-packages\flask\app.py", line 1950, in full_dispatch_request
    rv = self.dispatch_request()
  File "C:\Users\Major Ahmed\AppData\Local\Programs\Python\Python37\lib\site-packages\flask\app.py", line 1936, in dispatch_request
    return self.view_functions[rule.endpoint](**req.view_args)
  File "C:/Projects/Udacity/Python/Fyyur/app.py", line 474, in create_artist_form
    return render_template('forms/new_artist.html', form=form)
  File "C:\Users\Major Ahmed\AppData\Local\Programs\Python\Python37\lib\site-packages\flask\templating.py", line 140, in render_template
    ctx.app,
  File "C:\Users\Major Ahmed\AppData\Local\Programs\Python\Python37\lib\site-packages\flask\templating.py", line 120, in _render
    rv = template.render(context)
  File "C:\Users\Major Ahmed\AppData\Local\Programs\Python\Python37\lib\site-packages\jinja2\environment.py", line 1090, in render
    self.environment.handle_exception()
  File "C:\Users\Major Ahmed\AppData\Local\Programs\Python\Python37\lib\site-packages\jinja2\environment.py", line 832, in handle_exception
    reraise(*rewrite_traceback_stack(source=source))
  File "C:\Users\Major Ahmed\AppData\Local\Programs\Python\Python37\lib\site-packages\jinja2\_compat.py", line 28, in reraise
    raise value.with_traceback(tb)
  File "C:\Projects\Udacity\Python\Fyyur\templates\forms\new_artist.html", line 1, in top-level template code
    {% extends 'layouts/main.html' %} {% block title %}New Artist{% endblock %} {%
  File "C:\Projects\Udacity\Python\Fyyur\templates\layouts\main.html", line 103, in top-level template code
    {% block content %}{% endblock %}
  File "C:\Projects\Udacity\Python\Fyyur\templates\forms\new_artist.html", line 45, in block "content"
    {{ form.seeking_venue(class_ = 'form-control', autofocus = true) }}
jinja2.exceptions.UndefinedError: 'forms.ArtistForm object' has no attribute 'seeking_talent'
2020-09-21 19:46:52,167 INFO: errors [in C:/Projects/Udacity/Python/Fyyur/app.py:570]
2020-09-21 19:48:48,374 INFO: errors [in C:/Projects/Udacity/Python/Fyyur/app.py:570]
2020-09-21 20:25:10,423 INFO: errors [in C:/Projects/Udacity/Python/Fyyur/app.py:588]
2020-09-21 20:31:11,452 INFO: errors [in C:/Projects/Udacity/Python/Fyyur/app.py:588]
2020-09-21 20:37:45,952 INFO: errors [in C:/Projects/Udacity/Python/Fyyur/app.py:588]
2020-09-21 20:38:46,317 INFO: errors [in C:/Projects/Udacity/Python/Fyyur/app.py:588]
2020-09-21 20:39:24,832 INFO: errors [in C:/Projects/Udacity/Python/Fyyur/app.py:588]
2020-09-21 20:39:48,843 INFO: errors [in C:/Projects/Udacity/Python/Fyyur/app.py:588]
2020-09-21 20:40:32,009 INFO: errors [in C:/Projects/Udacity/Python/Fyyur/app.py:588]
2020-09-21 20:41:42,955 INFO: errors [in C:/Projects/Udacity/Python/Fyyur/app.py:588]
2020-09-21 20:42:36,396 INFO: errors [in C:/Projects/Udacity/Python/Fyyur/app.py:588]
2020-09-21 20:45:03,104 INFO: errors [in C:/Projects/Udacity/Python/Fyyur/app.py:588]
2020-09-21 20:46:32,784 INFO: errors [in C:/Projects/Udacity/Python/Fyyur/app.py:588]
2020-09-21 20:47:56,095 INFO: errors [in C:/Projects/Udacity/Python/Fyyur/app.py:588]
2020-09-21 20:47:58,435 ERROR: Exception on /venues [GET] [in C:\Users\Major Ahmed\AppData\Local\Programs\Python\Python37\lib\site-packages\flask\app.py:1892]
Traceback (most recent call last):
  File "C:\Users\Major Ahmed\AppData\Local\Programs\Python\Python37\lib\site-packages\flask\app.py", line 2447, in wsgi_app
    response = self.full_dispatch_request()
  File "C:\Users\Major Ahmed\AppData\Local\Programs\Python\Python37\lib\site-packages\flask\app.py", line 1952, in full_dispatch_request
    rv = self.handle_user_exception(e)
  File "C:\Users\Major Ahmed\AppData\Local\Programs\Python\Python37\lib\site-packages\flask\app.py", line 1821, in handle_user_exception
    reraise(exc_type, exc_value, tb)
  File "C:\Users\Major Ahmed\AppData\Local\Programs\Python\Python37\lib\site-packages\flask\_compat.py", line 39, in reraise
    raise value
  File "C:\Users\Major Ahmed\AppData\Local\Programs\Python\Python37\lib\site-packages\flask\app.py", line 1950, in full_dispatch_request
    rv = self.dispatch_request()
  File "C:\Users\Major Ahmed\AppData\Local\Programs\Python\Python37\lib\site-packages\flask\app.py", line 1936, in dispatch_request
    return self.view_functions[rule.endpoint](**req.view_args)
  File "C:/Projects/Udacity/Python/Fyyur/app.py", line 189, in venues
    return render_template('pages/venues.html', areas=data_temp);
  File "C:\Users\Major Ahmed\AppData\Local\Programs\Python\Python37\lib\site-packages\flask\templating.py", line 140, in render_template
    ctx.app,
  File "C:\Users\Major Ahmed\AppData\Local\Programs\Python\Python37\lib\site-packages\flask\templating.py", line 120, in _render
    rv = template.render(context)
  File "C:\Users\Major Ahmed\AppData\Local\Programs\Python\Python37\lib\site-packages\jinja2\environment.py", line 1090, in render
    self.environment.handle_exception()
  File "C:\Users\Major Ahmed\AppData\Local\Programs\Python\Python37\lib\site-packages\jinja2\environment.py", line 832, in handle_exception
    reraise(*rewrite_traceback_stack(source=source))
  File "C:\Users\Major Ahmed\AppData\Local\Programs\Python\Python37\lib\site-packages\jinja2\_compat.py", line 28, in reraise
    raise value.with_traceback(tb)
  File "C:\Projects\Udacity\Python\Fyyur\templates\pages\venues.html", line 1, in top-level template code
    {% extends 'layouts/main.html' %} {% block title %}Fyyur | Venues{% endblock %}
  File "C:\Projects\Udacity\Python\Fyyur\templates\layouts\main.html", line 103, in top-level template code
    {% block content %}{% endblock %}
  File "C:\Projects\Udacity\Python\Fyyur\templates\pages\venues.html", line 15, in block "content"
    <a style="margin-left: 100px;" href="#" data-id="{{venue.id}}"
  File "C:\Users\Major Ahmed\AppData\Local\Programs\Python\Python37\lib\site-packages\jinja2\environment.py", line 471, in getattr
    return getattr(obj, attribute)
jinja2.exceptions.UndefinedError: 'venue' is undefined
2020-09-21 20:48:04,286 ERROR: Exception on /venues [GET] [in C:\Users\Major Ahmed\AppData\Local\Programs\Python\Python37\lib\site-packages\flask\app.py:1892]
Traceback (most recent call last):
  File "C:\Users\Major Ahmed\AppData\Local\Programs\Python\Python37\lib\site-packages\flask\app.py", line 2447, in wsgi_app
    response = self.full_dispatch_request()
  File "C:\Users\Major Ahmed\AppData\Local\Programs\Python\Python37\lib\site-packages\flask\app.py", line 1952, in full_dispatch_request
    rv = self.handle_user_exception(e)
  File "C:\Users\Major Ahmed\AppData\Local\Programs\Python\Python37\lib\site-packages\flask\app.py", line 1821, in handle_user_exception
    reraise(exc_type, exc_value, tb)
  File "C:\Users\Major Ahmed\AppData\Local\Programs\Python\Python37\lib\site-packages\flask\_compat.py", line 39, in reraise
    raise value
  File "C:\Users\Major Ahmed\AppData\Local\Programs\Python\Python37\lib\site-packages\flask\app.py", line 1950, in full_dispatch_request
    rv = self.dispatch_request()
  File "C:\Users\Major Ahmed\AppData\Local\Programs\Python\Python37\lib\site-packages\flask\app.py", line 1936, in dispatch_request
    return self.view_functions[rule.endpoint](**req.view_args)
  File "C:/Projects/Udacity/Python/Fyyur/app.py", line 189, in venues
    return render_template('pages/venues.html', areas=data_temp);
  File "C:\Users\Major Ahmed\AppData\Local\Programs\Python\Python37\lib\site-packages\flask\templating.py", line 140, in render_template
    ctx.app,
  File "C:\Users\Major Ahmed\AppData\Local\Programs\Python\Python37\lib\site-packages\flask\templating.py", line 120, in _render
    rv = template.render(context)
  File "C:\Users\Major Ahmed\AppData\Local\Programs\Python\Python37\lib\site-packages\jinja2\environment.py", line 1090, in render
    self.environment.handle_exception()
  File "C:\Users\Major Ahmed\AppData\Local\Programs\Python\Python37\lib\site-packages\jinja2\environment.py", line 832, in handle_exception
    reraise(*rewrite_traceback_stack(source=source))
  File "C:\Users\Major Ahmed\AppData\Local\Programs\Python\Python37\lib\site-packages\jinja2\_compat.py", line 28, in reraise
    raise value.with_traceback(tb)
  File "C:\Projects\Udacity\Python\Fyyur\templates\pages\venues.html", line 1, in top-level template code
    {% extends 'layouts/main.html' %} {% block title %}Fyyur | Venues{% endblock %}
  File "C:\Projects\Udacity\Python\Fyyur\templates\layouts\main.html", line 103, in top-level template code
    {% block content %}{% endblock %}
  File "C:\Projects\Udacity\Python\Fyyur\templates\pages\venues.html", line 15, in block "content"
    <a style="margin-left: 100px;" href="#" data-id="{{venue.id}}"
  File "C:\Users\Major Ahmed\AppData\Local\Programs\Python\Python37\lib\site-packages\jinja2\environment.py", line 471, in getattr
    return getattr(obj, attribute)
jinja2.exceptions.UndefinedError: 'venue' is undefined
2020-09-21 20:48:34,558 INFO: errors [in C:/Projects/Udacity/Python/Fyyur/app.py:588]
2020-09-21 20:48:36,959 ERROR: Exception on /venues [GET] [in C:\Users\Major Ahmed\AppData\Local\Programs\Python\Python37\lib\site-packages\flask\app.py:1892]
Traceback (most recent call last):
  File "C:\Users\Major Ahmed\AppData\Local\Programs\Python\Python37\lib\site-packages\flask\app.py", line 2447, in wsgi_app
    response = self.full_dispatch_request()
  File "C:\Users\Major Ahmed\AppData\Local\Programs\Python\Python37\lib\site-packages\flask\app.py", line 1952, in full_dispatch_request
    rv = self.handle_user_exception(e)
  File "C:\Users\Major Ahmed\AppData\Local\Programs\Python\Python37\lib\site-packages\flask\app.py", line 1821, in handle_user_exception
    reraise(exc_type, exc_value, tb)
  File "C:\Users\Major Ahmed\AppData\Local\Programs\Python\Python37\lib\site-packages\flask\_compat.py", line 39, in reraise
    raise value
  File "C:\Users\Major Ahmed\AppData\Local\Programs\Python\Python37\lib\site-packages\flask\app.py", line 1950, in full_dispatch_request
    rv = self.dispatch_request()
  File "C:\Users\Major Ahmed\AppData\Local\Programs\Python\Python37\lib\site-packages\flask\app.py", line 1936, in dispatch_request
    return self.view_functions[rule.endpoint](**req.view_args)
  File "C:/Projects/Udacity/Python/Fyyur/app.py", line 189, in venues
    return render_template('pages/venues.html', areas=data_temp);
  File "C:\Users\Major Ahmed\AppData\Local\Programs\Python\Python37\lib\site-packages\flask\templating.py", line 140, in render_template
    ctx.app,
  File "C:\Users\Major Ahmed\AppData\Local\Programs\Python\Python37\lib\site-packages\flask\templating.py", line 120, in _render
    rv = template.render(context)
  File "C:\Users\Major Ahmed\AppData\Local\Programs\Python\Python37\lib\site-packages\jinja2\environment.py", line 1090, in render
    self.environment.handle_exception()
  File "C:\Users\Major Ahmed\AppData\Local\Programs\Python\Python37\lib\site-packages\jinja2\environment.py", line 832, in handle_exception
    reraise(*rewrite_traceback_stack(source=source))
  File "C:\Users\Major Ahmed\AppData\Local\Programs\Python\Python37\lib\site-packages\jinja2\_compat.py", line 28, in reraise
    raise value.with_traceback(tb)
  File "C:\Projects\Udacity\Python\Fyyur\templates\pages\venues.html", line 1, in top-level template code
    {% extends 'layouts/main.html' %} {% block title %}Fyyur | Venues{% endblock %}
  File "C:\Projects\Udacity\Python\Fyyur\templates\layouts\main.html", line 103, in top-level template code
    {% block content %}{% endblock %}
  File "C:\Projects\Udacity\Python\Fyyur\templates\pages\venues.html", line 15, in block "content"
    <a href="#" data-id="{{venue.id}}"><i class="fas fa-trash"></i></a>
  File "C:\Users\Major Ahmed\AppData\Local\Programs\Python\Python37\lib\site-packages\jinja2\environment.py", line 471, in getattr
    return getattr(obj, attribute)
jinja2.exceptions.UndefinedError: 'venue' is undefined
2020-09-21 20:49:17,116 INFO: errors [in C:/Projects/Udacity/Python/Fyyur/app.py:588]
2020-09-21 20:49:48,840 INFO: errors [in C:/Projects/Udacity/Python/Fyyur/app.py:588]
2020-09-21 20:50:23,695 INFO: errors [in C:/Projects/Udacity/Python/Fyyur/app.py:588]
2020-09-21 20:50:58,755 INFO: errors [in C:/Projects/Udacity/Python/Fyyur/app.py:588]
2020-09-21 20:51:22,366 INFO: errors [in C:/Projects/Udacity/Python/Fyyur/app.py:588]
2020-09-21 20:51:51,753 INFO: errors [in C:/Projects/Udacity/Python/Fyyur/app.py:588]
2020-09-21 20:59:00,826 INFO: errors [in C:/Projects/Udacity/Python/Fyyur/app.py:588]
2020-09-21 21:04:33,495 INFO: errors [in C:/Projects/Udacity/Python/Fyyur/app.py:588]
2020-09-21 21:04:48,462 INFO: errors [in C:/Projects/Udacity/Python/Fyyur/app.py:588]
2020-09-21 21:05:12,024 INFO: errors [in C:/Projects/Udacity/Python/Fyyur/app.py:588]
2020-09-21 21:05:38,826 INFO: errors [in C:/Projects/Udacity/Python/Fyyur/app.py:588]
2020-09-21 21:06:31,022 INFO: errors [in C:/Projects/Udacity/Python/Fyyur/app.py:588]
2020-09-21 21:48:25,452 INFO: errors [in C:/Projects/Udacity/Python/Fyyur/app.py:608]
2020-09-21 21:48:59,136 INFO: errors [in C:/Projects/Udacity/Python/Fyyur/app.py:608]
2020-09-21 21:49:42,843 ERROR: Exception on /venues/14 [DELETE] [in C:\Users\Major Ahmed\AppData\Local\Programs\Python\Python37\lib\site-packages\flask\app.py:1892]
Traceback (most recent call last):
  File "C:\Users\Major Ahmed\AppData\Local\Programs\Python\Python37\lib\site-packages\flask\app.py", line 2447, in wsgi_app
    response = self.full_dispatch_request()
  File "C:\Users\Major Ahmed\AppData\Local\Programs\Python\Python37\lib\site-packages\flask\app.py", line 1952, in full_dispatch_request
    rv = self.handle_user_exception(e)
  File "C:\Users\Major Ahmed\AppData\Local\Programs\Python\Python37\lib\site-packages\flask\app.py", line 1821, in handle_user_exception
    reraise(exc_type, exc_value, tb)
  File "C:\Users\Major Ahmed\AppData\Local\Programs\Python\Python37\lib\site-packages\flask\_compat.py", line 39, in reraise
    raise value
  File "C:\Users\Major Ahmed\AppData\Local\Programs\Python\Python37\lib\site-packages\flask\app.py", line 1950, in full_dispatch_request
    rv = self.dispatch_request()
  File "C:\Users\Major Ahmed\AppData\Local\Programs\Python\Python37\lib\site-packages\flask\app.py", line 1936, in dispatch_request
    return self.view_functions[rule.endpoint](**req.view_args)
  File "C:/Projects/Udacity/Python/Fyyur/app.py", line 326, in delete_venue
    venue.delete()
AttributeError: 'Venue' object has no attribute 'delete'
2020-09-21 21:49:51,970 ERROR: Exception on /venues/14 [DELETE] [in C:\Users\Major Ahmed\AppData\Local\Programs\Python\Python37\lib\site-packages\flask\app.py:1892]
Traceback (most recent call last):
  File "C:\Users\Major Ahmed\AppData\Local\Programs\Python\Python37\lib\site-packages\flask\app.py", line 2447, in wsgi_app
    response = self.full_dispatch_request()
  File "C:\Users\Major Ahmed\AppData\Local\Programs\Python\Python37\lib\site-packages\flask\app.py", line 1952, in full_dispatch_request
    rv = self.handle_user_exception(e)
  File "C:\Users\Major Ahmed\AppData\Local\Programs\Python\Python37\lib\site-packages\flask\app.py", line 1821, in handle_user_exception
    reraise(exc_type, exc_value, tb)
  File "C:\Users\Major Ahmed\AppData\Local\Programs\Python\Python37\lib\site-packages\flask\_compat.py", line 39, in reraise
    raise value
  File "C:\Users\Major Ahmed\AppData\Local\Programs\Python\Python37\lib\site-packages\flask\app.py", line 1950, in full_dispatch_request
    rv = self.dispatch_request()
  File "C:\Users\Major Ahmed\AppData\Local\Programs\Python\Python37\lib\site-packages\flask\app.py", line 1936, in dispatch_request
    return self.view_functions[rule.endpoint](**req.view_args)
  File "C:/Projects/Udacity/Python/Fyyur/app.py", line 326, in delete_venue
    venue.delete()
AttributeError: 'Venue' object has no attribute 'delete'
2020-09-21 21:56:07,992 INFO: errors [in C:/Projects/Udacity/Python/Fyyur/app.py:612]
2020-09-21 21:56:24,349 ERROR: Exception on /venues/14 [DELETE] [in C:\Users\Major Ahmed\AppData\Local\Programs\Python\Python37\lib\site-packages\flask\app.py:1892]
Traceback (most recent call last):
  File "C:\Users\Major Ahmed\AppData\Local\Programs\Python\Python37\lib\site-packages\flask\app.py", line 2447, in wsgi_app
    response = self.full_dispatch_request()
  File "C:\Users\Major Ahmed\AppData\Local\Programs\Python\Python37\lib\site-packages\flask\app.py", line 1952, in full_dispatch_request
    rv = self.handle_user_exception(e)
  File "C:\Users\Major Ahmed\AppData\Local\Programs\Python\Python37\lib\site-packages\flask\app.py", line 1821, in handle_user_exception
    reraise(exc_type, exc_value, tb)
  File "C:\Users\Major Ahmed\AppData\Local\Programs\Python\Python37\lib\site-packages\flask\_compat.py", line 39, in reraise
    raise value
  File "C:\Users\Major Ahmed\AppData\Local\Programs\Python\Python37\lib\site-packages\flask\app.py", line 1950, in full_dispatch_request
    rv = self.dispatch_request()
  File "C:\Users\Major Ahmed\AppData\Local\Programs\Python\Python37\lib\site-packages\flask\app.py", line 1936, in dispatch_request
    return self.view_functions[rule.endpoint](**req.view_args)
  File "C:/Projects/Udacity/Python/Fyyur/app.py", line 325, in delete_venue
    venue_name = venue.name
AttributeError: 'NoneType' object has no attribute 'name'
2020-09-21 21:57:01,512 INFO: errors [in C:/Projects/Udacity/Python/Fyyur/app.py:612]
2020-09-21 21:59:22,264 INFO: errors [in C:/Projects/Udacity/Python/Fyyur/app.py:610]
2020-09-21 22:00:16,634 INFO: errors [in C:/Projects/Udacity/Python/Fyyur/app.py:610]
2020-09-21 22:00:58,926 ERROR: Exception on /venues/15 [DELETE] [in C:\Users\Major Ahmed\AppData\Local\Programs\Python\Python37\lib\site-packages\flask\app.py:1892]
Traceback (most recent call last):
  File "C:\Users\Major Ahmed\AppData\Local\Programs\Python\Python37\lib\site-packages\flask\app.py", line 2447, in wsgi_app
    response = self.full_dispatch_request()
  File "C:\Users\Major Ahmed\AppData\Local\Programs\Python\Python37\lib\site-packages\flask\app.py", line 1952, in full_dispatch_request
    rv = self.handle_user_exception(e)
  File "C:\Users\Major Ahmed\AppData\Local\Programs\Python\Python37\lib\site-packages\flask\app.py", line 1821, in handle_user_exception
    reraise(exc_type, exc_value, tb)
  File "C:\Users\Major Ahmed\AppData\Local\Programs\Python\Python37\lib\site-packages\flask\_compat.py", line 39, in reraise
    raise value
  File "C:\Users\Major Ahmed\AppData\Local\Programs\Python\Python37\lib\site-packages\flask\app.py", line 1950, in full_dispatch_request
    rv = self.dispatch_request()
  File "C:\Users\Major Ahmed\AppData\Local\Programs\Python\Python37\lib\site-packages\flask\app.py", line 1936, in dispatch_request
    return self.view_functions[rule.endpoint](**req.view_args)
  File "C:/Projects/Udacity/Python/Fyyur/app.py", line 338, in delete_venue
    return jsonify({}), 204
NameError: name 'jsonify' is not defined
2020-09-21 22:01:31,532 INFO: errors [in C:/Projects/Udacity/Python/Fyyur/app.py:610]
2020-09-21 22:04:06,295 ERROR: Exception on /artists/4 [GET] [in C:\Users\Major Ahmed\AppData\Local\Programs\Python\Python37\lib\site-packages\flask\app.py:1892]
Traceback (most recent call last):
  File "C:\Users\Major Ahmed\AppData\Local\Programs\Python\Python37\lib\site-packages\flask\app.py", line 2447, in wsgi_app
    response = self.full_dispatch_request()
  File "C:\Users\Major Ahmed\AppData\Local\Programs\Python\Python37\lib\site-packages\flask\app.py", line 1952, in full_dispatch_request
    rv = self.handle_user_exception(e)
  File "C:\Users\Major Ahmed\AppData\Local\Programs\Python\Python37\lib\site-packages\flask\app.py", line 1821, in handle_user_exception
    reraise(exc_type, exc_value, tb)
  File "C:\Users\Major Ahmed\AppData\Local\Programs\Python\Python37\lib\site-packages\flask\_compat.py", line 39, in reraise
    raise value
  File "C:\Users\Major Ahmed\AppData\Local\Programs\Python\Python37\lib\site-packages\flask\app.py", line 1950, in full_dispatch_request
    rv = self.dispatch_request()
  File "C:\Users\Major Ahmed\AppData\Local\Programs\Python\Python37\lib\site-packages\flask\app.py", line 1936, in dispatch_request
    return self.view_functions[rule.endpoint](**req.view_args)
  File "C:/Projects/Udacity/Python/Fyyur/app.py", line 452, in show_artist
    data = list(filter(lambda d: d['id'] == artist_id, [data1, data2, data3]))[0]
  File "C:\Users\Major Ahmed\AppData\Local\Programs\Python\Python37\lib\site-packages\flask\templating.py", line 140, in render_template
    ctx.app,
  File "C:\Users\Major Ahmed\AppData\Local\Programs\Python\Python37\lib\site-packages\flask\templating.py", line 120, in _render
    rv = template.render(context)
  File "C:\Users\Major Ahmed\AppData\Local\Programs\Python\Python37\lib\site-packages\jinja2\environment.py", line 1090, in render
    self.environment.handle_exception()
  File "C:\Users\Major Ahmed\AppData\Local\Programs\Python\Python37\lib\site-packages\jinja2\environment.py", line 832, in handle_exception
    reraise(*rewrite_traceback_stack(source=source))
  File "C:\Users\Major Ahmed\AppData\Local\Programs\Python\Python37\lib\site-packages\jinja2\_compat.py", line 28, in reraise
    raise value.with_traceback(tb)
  File "C:\Projects\Udacity\Python\Fyyur\templates\pages\show_artist.html", line 1, in top-level template code
    {% extends 'layouts/main.html' %}
  File "C:\Projects\Udacity\Python\Fyyur\templates\layouts\main.html", line 103, in top-level template code
    {% block content %}{% endblock %}
  File "C:\Projects\Udacity\Python\Fyyur\templates\pages\show_artist.html", line 68, in block "content"
    <h6>{{ show.start_time|datetime('full') }}</h6>
  File "C:/Projects/Udacity/Python/Fyyur/app.py", line 136, in format_datetime
    return babel.dates.format_datetime(date, format)
  File "C:\Users\Major Ahmed\AppData\Local\Programs\Python\Python37\lib\site-packages\babel\dates.py", line 738, in format_datetime
    return parse_pattern(format).apply(datetime, locale)
  File "C:\Users\Major Ahmed\AppData\Local\Programs\Python\Python37\lib\site-packages\babel\dates.py", line 1232, in apply
    return self % DateTimeFormat(datetime, locale)
  File "C:\Users\Major Ahmed\AppData\Local\Programs\Python\Python37\lib\site-packages\babel\dates.py", line 1229, in __mod__
    return self.format % other
  File "C:\Users\Major Ahmed\AppData\Local\Programs\Python\Python37\lib\site-packages\babel\dates.py", line 1264, in __getitem__
    return self.format_weekday(char, num)
  File "C:\Users\Major Ahmed\AppData\Local\Programs\Python\Python37\lib\site-packages\babel\dates.py", line 1397, in format_weekday
    return get_day_names(width, context, self.locale)[weekday]
  File "C:\Users\Major Ahmed\AppData\Local\Programs\Python\Python37\lib\site-packages\babel\dates.py", line 314, in get_day_names
    return Locale.parse(locale).days[context][width]
AttributeError: 'NoneType' object has no attribute 'days'
2020-09-21 22:04:09,532 ERROR: Exception on /artists/5 [GET] [in C:\Users\Major Ahmed\AppData\Local\Programs\Python\Python37\lib\site-packages\flask\app.py:1892]
Traceback (most recent call last):
  File "C:\Users\Major Ahmed\AppData\Local\Programs\Python\Python37\lib\site-packages\flask\app.py", line 2447, in wsgi_app
    response = self.full_dispatch_request()
  File "C:\Users\Major Ahmed\AppData\Local\Programs\Python\Python37\lib\site-packages\flask\app.py", line 1952, in full_dispatch_request
    rv = self.handle_user_exception(e)
  File "C:\Users\Major Ahmed\AppData\Local\Programs\Python\Python37\lib\site-packages\flask\app.py", line 1821, in handle_user_exception
    reraise(exc_type, exc_value, tb)
  File "C:\Users\Major Ahmed\AppData\Local\Programs\Python\Python37\lib\site-packages\flask\_compat.py", line 39, in reraise
    raise value
  File "C:\Users\Major Ahmed\AppData\Local\Programs\Python\Python37\lib\site-packages\flask\app.py", line 1950, in full_dispatch_request
    rv = self.dispatch_request()
  File "C:\Users\Major Ahmed\AppData\Local\Programs\Python\Python37\lib\site-packages\flask\app.py", line 1936, in dispatch_request
    return self.view_functions[rule.endpoint](**req.view_args)
  File "C:/Projects/Udacity/Python/Fyyur/app.py", line 452, in show_artist
    data = list(filter(lambda d: d['id'] == artist_id, [data1, data2, data3]))[0]
  File "C:\Users\Major Ahmed\AppData\Local\Programs\Python\Python37\lib\site-packages\flask\templating.py", line 140, in render_template
    ctx.app,
  File "C:\Users\Major Ahmed\AppData\Local\Programs\Python\Python37\lib\site-packages\flask\templating.py", line 120, in _render
    rv = template.render(context)
  File "C:\Users\Major Ahmed\AppData\Local\Programs\Python\Python37\lib\site-packages\jinja2\environment.py", line 1090, in render
    self.environment.handle_exception()
  File "C:\Users\Major Ahmed\AppData\Local\Programs\Python\Python37\lib\site-packages\jinja2\environment.py", line 832, in handle_exception
    reraise(*rewrite_traceback_stack(source=source))
  File "C:\Users\Major Ahmed\AppData\Local\Programs\Python\Python37\lib\site-packages\jinja2\_compat.py", line 28, in reraise
    raise value.with_traceback(tb)
  File "C:\Projects\Udacity\Python\Fyyur\templates\pages\show_artist.html", line 1, in top-level template code
    {% extends 'layouts/main.html' %}
  File "C:\Projects\Udacity\Python\Fyyur\templates\layouts\main.html", line 103, in top-level template code
    {% block content %}{% endblock %}
  File "C:\Projects\Udacity\Python\Fyyur\templates\pages\show_artist.html", line 68, in block "content"
    <h6>{{ show.start_time|datetime('full') }}</h6>
  File "C:/Projects/Udacity/Python/Fyyur/app.py", line 136, in format_datetime
    return babel.dates.format_datetime(date, format)
  File "C:\Users\Major Ahmed\AppData\Local\Programs\Python\Python37\lib\site-packages\babel\dates.py", line 738, in format_datetime
    return parse_pattern(format).apply(datetime, locale)
  File "C:\Users\Major Ahmed\AppData\Local\Programs\Python\Python37\lib\site-packages\babel\dates.py", line 1232, in apply
    return self % DateTimeFormat(datetime, locale)
  File "C:\Users\Major Ahmed\AppData\Local\Programs\Python\Python37\lib\site-packages\babel\dates.py", line 1229, in __mod__
    return self.format % other
  File "C:\Users\Major Ahmed\AppData\Local\Programs\Python\Python37\lib\site-packages\babel\dates.py", line 1264, in __getitem__
    return self.format_weekday(char, num)
  File "C:\Users\Major Ahmed\AppData\Local\Programs\Python\Python37\lib\site-packages\babel\dates.py", line 1397, in format_weekday
    return get_day_names(width, context, self.locale)[weekday]
  File "C:\Users\Major Ahmed\AppData\Local\Programs\Python\Python37\lib\site-packages\babel\dates.py", line 314, in get_day_names
    return Locale.parse(locale).days[context][width]
AttributeError: 'NoneType' object has no attribute 'days'
2020-09-21 22:04:10,998 ERROR: Exception on /artists/6 [GET] [in C:\Users\Major Ahmed\AppData\Local\Programs\Python\Python37\lib\site-packages\flask\app.py:1892]
Traceback (most recent call last):
  File "C:\Users\Major Ahmed\AppData\Local\Programs\Python\Python37\lib\site-packages\flask\app.py", line 2447, in wsgi_app
    response = self.full_dispatch_request()
  File "C:\Users\Major Ahmed\AppData\Local\Programs\Python\Python37\lib\site-packages\flask\app.py", line 1952, in full_dispatch_request
    rv = self.handle_user_exception(e)
  File "C:\Users\Major Ahmed\AppData\Local\Programs\Python\Python37\lib\site-packages\flask\app.py", line 1821, in handle_user_exception
    reraise(exc_type, exc_value, tb)
  File "C:\Users\Major Ahmed\AppData\Local\Programs\Python\Python37\lib\site-packages\flask\_compat.py", line 39, in reraise
    raise value
  File "C:\Users\Major Ahmed\AppData\Local\Programs\Python\Python37\lib\site-packages\flask\app.py", line 1950, in full_dispatch_request
    rv = self.dispatch_request()
  File "C:\Users\Major Ahmed\AppData\Local\Programs\Python\Python37\lib\site-packages\flask\app.py", line 1936, in dispatch_request
    return self.view_functions[rule.endpoint](**req.view_args)
  File "C:/Projects/Udacity/Python/Fyyur/app.py", line 452, in show_artist
    data = list(filter(lambda d: d['id'] == artist_id, [data1, data2, data3]))[0]
  File "C:\Users\Major Ahmed\AppData\Local\Programs\Python\Python37\lib\site-packages\flask\templating.py", line 140, in render_template
    ctx.app,
  File "C:\Users\Major Ahmed\AppData\Local\Programs\Python\Python37\lib\site-packages\flask\templating.py", line 120, in _render
    rv = template.render(context)
  File "C:\Users\Major Ahmed\AppData\Local\Programs\Python\Python37\lib\site-packages\jinja2\environment.py", line 1090, in render
    self.environment.handle_exception()
  File "C:\Users\Major Ahmed\AppData\Local\Programs\Python\Python37\lib\site-packages\jinja2\environment.py", line 832, in handle_exception
    reraise(*rewrite_traceback_stack(source=source))
  File "C:\Users\Major Ahmed\AppData\Local\Programs\Python\Python37\lib\site-packages\jinja2\_compat.py", line 28, in reraise
    raise value.with_traceback(tb)
  File "C:\Projects\Udacity\Python\Fyyur\templates\pages\show_artist.html", line 1, in top-level template code
    {% extends 'layouts/main.html' %}
  File "C:\Projects\Udacity\Python\Fyyur\templates\layouts\main.html", line 103, in top-level template code
    {% block content %}{% endblock %}
  File "C:\Projects\Udacity\Python\Fyyur\templates\pages\show_artist.html", line 54, in block "content"
    <h6>{{ show.start_time|datetime('full') }}</h6>
  File "C:/Projects/Udacity/Python/Fyyur/app.py", line 136, in format_datetime
    return babel.dates.format_datetime(date, format)
  File "C:\Users\Major Ahmed\AppData\Local\Programs\Python\Python37\lib\site-packages\babel\dates.py", line 738, in format_datetime
    return parse_pattern(format).apply(datetime, locale)
  File "C:\Users\Major Ahmed\AppData\Local\Programs\Python\Python37\lib\site-packages\babel\dates.py", line 1232, in apply
    return self % DateTimeFormat(datetime, locale)
  File "C:\Users\Major Ahmed\AppData\Local\Programs\Python\Python37\lib\site-packages\babel\dates.py", line 1229, in __mod__
    return self.format % other
  File "C:\Users\Major Ahmed\AppData\Local\Programs\Python\Python37\lib\site-packages\babel\dates.py", line 1264, in __getitem__
    return self.format_weekday(char, num)
  File "C:\Users\Major Ahmed\AppData\Local\Programs\Python\Python37\lib\site-packages\babel\dates.py", line 1397, in format_weekday
    return get_day_names(width, context, self.locale)[weekday]
  File "C:\Users\Major Ahmed\AppData\Local\Programs\Python\Python37\lib\site-packages\babel\dates.py", line 314, in get_day_names
    return Locale.parse(locale).days[context][width]
AttributeError: 'NoneType' object has no attribute 'days'
2020-09-21 22:33:51,738 INFO: errors [in C:/Projects/Udacity/Python/Fyyur/app.py:608]
2020-09-21 22:34:02,587 ERROR: Exception on /artists [GET] [in C:\Users\Major Ahmed\AppData\Local\Programs\Python\Python37\lib\site-packages\flask\app.py:1892]
Traceback (most recent call last):
  File "C:\Users\Major Ahmed\AppData\Local\Programs\Python\Python37\lib\site-packages\flask\app.py", line 2447, in wsgi_app
    response = self.full_dispatch_request()
  File "C:\Users\Major Ahmed\AppData\Local\Programs\Python\Python37\lib\site-packages\flask\app.py", line 1952, in full_dispatch_request
    rv = self.handle_user_exception(e)
  File "C:\Users\Major Ahmed\AppData\Local\Programs\Python\Python37\lib\site-packages\flask\app.py", line 1821, in handle_user_exception
    reraise(exc_type, exc_value, tb)
  File "C:\Users\Major Ahmed\AppData\Local\Programs\Python\Python37\lib\site-packages\flask\_compat.py", line 39, in reraise
    raise value
  File "C:\Users\Major Ahmed\AppData\Local\Programs\Python\Python37\lib\site-packages\flask\app.py", line 1950, in full_dispatch_request
    rv = self.dispatch_request()
  File "C:\Users\Major Ahmed\AppData\Local\Programs\Python\Python37\lib\site-packages\flask\app.py", line 1936, in dispatch_request
    return self.view_functions[rule.endpoint](**req.view_args)
  File "C:/Projects/Udacity/Python/Fyyur/app.py", line 352, in artists
    for artist in artists:
TypeError: 'function' object is not iterable
2020-09-21 22:34:43,053 INFO: errors [in C:/Projects/Udacity/Python/Fyyur/app.py:608]
2020-09-21 22:34:47,204 ERROR: Exception on /artists [GET] [in C:\Users\Major Ahmed\AppData\Local\Programs\Python\Python37\lib\site-packages\flask\app.py:1892]
Traceback (most recent call last):
  File "C:\Users\Major Ahmed\AppData\Local\Programs\Python\Python37\lib\site-packages\flask\app.py", line 2447, in wsgi_app
    response = self.full_dispatch_request()
  File "C:\Users\Major Ahmed\AppData\Local\Programs\Python\Python37\lib\site-packages\flask\app.py", line 1952, in full_dispatch_request
    rv = self.handle_user_exception(e)
  File "C:\Users\Major Ahmed\AppData\Local\Programs\Python\Python37\lib\site-packages\flask\app.py", line 1821, in handle_user_exception
    reraise(exc_type, exc_value, tb)
  File "C:\Users\Major Ahmed\AppData\Local\Programs\Python\Python37\lib\site-packages\flask\_compat.py", line 39, in reraise
    raise value
  File "C:\Users\Major Ahmed\AppData\Local\Programs\Python\Python37\lib\site-packages\flask\app.py", line 1950, in full_dispatch_request
    rv = self.dispatch_request()
  File "C:\Users\Major Ahmed\AppData\Local\Programs\Python\Python37\lib\site-packages\flask\app.py", line 1936, in dispatch_request
    return self.view_functions[rule.endpoint](**req.view_args)
  File "C:/Projects/Udacity/Python/Fyyur/app.py", line 355, in artists
    name: artist.name
NameError: name 'name' is not defined
2020-09-21 22:35:21,331 INFO: errors [in C:/Projects/Udacity/Python/Fyyur/app.py:608]
2020-09-21 22:40:30,879 INFO: errors [in C:/Projects/Udacity/Python/Fyyur/app.py:612]
2020-09-21 22:49:54,995 INFO: errors [in C:/Projects/Udacity/Python/Fyyur/app.py:615]
2020-09-21 22:50:08,491 ERROR: Exception on /artists/search [POST] [in C:\Users\Major Ahmed\AppData\Local\Programs\Python\Python37\lib\site-packages\flask\app.py:1892]
Traceback (most recent call last):
  File "C:\Users\Major Ahmed\AppData\Local\Programs\Python\Python37\lib\site-packages\flask\app.py", line 2447, in wsgi_app
    response = self.full_dispatch_request()
  File "C:\Users\Major Ahmed\AppData\Local\Programs\Python\Python37\lib\site-packages\flask\app.py", line 1952, in full_dispatch_request
    rv = self.handle_user_exception(e)
  File "C:\Users\Major Ahmed\AppData\Local\Programs\Python\Python37\lib\site-packages\flask\app.py", line 1821, in handle_user_exception
    reraise(exc_type, exc_value, tb)
  File "C:\Users\Major Ahmed\AppData\Local\Programs\Python\Python37\lib\site-packages\flask\_compat.py", line 39, in reraise
    raise value
  File "C:\Users\Major Ahmed\AppData\Local\Programs\Python\Python37\lib\site-packages\flask\app.py", line 1950, in full_dispatch_request
    rv = self.dispatch_request()
  File "C:\Users\Major Ahmed\AppData\Local\Programs\Python\Python37\lib\site-packages\flask\app.py", line 1936, in dispatch_request
    return self.view_functions[rule.endpoint](**req.view_args)
  File "C:/Projects/Udacity/Python/Fyyur/app.py", line 366, in search_artists
    found_artists = Artist.quert.filter(Artist.name.ilike(f"%{artist_name}%")).all()
AttributeError: type object 'Artist' has no attribute 'quert'
2020-09-21 22:50:24,387 INFO: errors [in C:/Projects/Udacity/Python/Fyyur/app.py:615]
2020-09-21 23:08:00,934 INFO: errors [in C:/Projects/Udacity/Python/Fyyur/app.py:594]
2020-09-21 23:08:10,187 ERROR: Exception on /artists/2 [GET] [in C:\Users\Major Ahmed\AppData\Local\Programs\Python\Python37\lib\site-packages\flask\app.py:1892]
Traceback (most recent call last):
  File "C:\Users\Major Ahmed\AppData\Local\Programs\Python\Python37\lib\site-packages\flask\app.py", line 2447, in wsgi_app
    response = self.full_dispatch_request()
  File "C:\Users\Major Ahmed\AppData\Local\Programs\Python\Python37\lib\site-packages\flask\app.py", line 1952, in full_dispatch_request
    rv = self.handle_user_exception(e)
  File "C:\Users\Major Ahmed\AppData\Local\Programs\Python\Python37\lib\site-packages\flask\app.py", line 1821, in handle_user_exception
    reraise(exc_type, exc_value, tb)
  File "C:\Users\Major Ahmed\AppData\Local\Programs\Python\Python37\lib\site-packages\flask\_compat.py", line 39, in reraise
    raise value
  File "C:\Users\Major Ahmed\AppData\Local\Programs\Python\Python37\lib\site-packages\flask\app.py", line 1950, in full_dispatch_request
    rv = self.dispatch_request()
  File "C:\Users\Major Ahmed\AppData\Local\Programs\Python\Python37\lib\site-packages\flask\app.py", line 1936, in dispatch_request
    return self.view_functions[rule.endpoint](**req.view_args)
  File "C:/Projects/Udacity/Python/Fyyur/app.py", line 436, in show_artist
    return render_template('pages/show_artist.html', artist=data)
  File "C:\Users\Major Ahmed\AppData\Local\Programs\Python\Python37\lib\site-packages\flask\templating.py", line 140, in render_template
    ctx.app,
  File "C:\Users\Major Ahmed\AppData\Local\Programs\Python\Python37\lib\site-packages\flask\templating.py", line 120, in _render
    rv = template.render(context)
  File "C:\Users\Major Ahmed\AppData\Local\Programs\Python\Python37\lib\site-packages\jinja2\environment.py", line 1090, in render
    self.environment.handle_exception()
  File "C:\Users\Major Ahmed\AppData\Local\Programs\Python\Python37\lib\site-packages\jinja2\environment.py", line 832, in handle_exception
    reraise(*rewrite_traceback_stack(source=source))
  File "C:\Users\Major Ahmed\AppData\Local\Programs\Python\Python37\lib\site-packages\jinja2\_compat.py", line 28, in reraise
    raise value.with_traceback(tb)
  File "C:\Projects\Udacity\Python\Fyyur\templates\pages\show_artist.html", line 1, in top-level template code
    {% extends 'layouts/main.html' %}
  File "C:\Projects\Udacity\Python\Fyyur\templates\layouts\main.html", line 103, in top-level template code
    {% block content %}{% endblock %}
  File "C:\Projects\Udacity\Python\Fyyur\templates\pages\show_artist.html", line 54, in block "content"
    <h6>{{ show.start_time|datetime('full') }}</h6>
  File "C:/Projects/Udacity/Python/Fyyur/app.py", line 136, in format_datetime
    return babel.dates.format_datetime(date, format)
  File "C:\Users\Major Ahmed\AppData\Local\Programs\Python\Python37\lib\site-packages\babel\dates.py", line 738, in format_datetime
    return parse_pattern(format).apply(datetime, locale)
  File "C:\Users\Major Ahmed\AppData\Local\Programs\Python\Python37\lib\site-packages\babel\dates.py", line 1232, in apply
    return self % DateTimeFormat(datetime, locale)
  File "C:\Users\Major Ahmed\AppData\Local\Programs\Python\Python37\lib\site-packages\babel\dates.py", line 1229, in __mod__
    return self.format % other
  File "C:\Users\Major Ahmed\AppData\Local\Programs\Python\Python37\lib\site-packages\babel\dates.py", line 1264, in __getitem__
    return self.format_weekday(char, num)
  File "C:\Users\Major Ahmed\AppData\Local\Programs\Python\Python37\lib\site-packages\babel\dates.py", line 1397, in format_weekday
    return get_day_names(width, context, self.locale)[weekday]
  File "C:\Users\Major Ahmed\AppData\Local\Programs\Python\Python37\lib\site-packages\babel\dates.py", line 314, in get_day_names
    return Locale.parse(locale).days[context][width]
AttributeError: 'NoneType' object has no attribute 'days'
2020-09-21 23:09:00,836 INFO: errors [in C:/Projects/Udacity/Python/Fyyur/app.py:594]
2020-09-21 23:12:28,088 INFO: errors [in C:/Projects/Udacity/Python/Fyyur/app.py:594]
2020-09-21 23:13:18,193 INFO: errors [in C:/Projects/Udacity/Python/Fyyur/app.py:594]
2020-09-21 23:16:15,536 INFO: errors [in C:\Projects\Udacity\Python\Fyyur\app.py:594]
2020-09-21 23:16:23,246 INFO: errors [in C:\Projects\Udacity\Python\Fyyur\app.py:594]
2020-09-21 23:17:34,835 INFO: errors [in C:/Projects/Udacity/Python/Fyyur/app.py:594]
2020-09-21 23:17:42,658 INFO: errors [in C:\Projects\Udacity\Python\Fyyur\app.py:594]
2020-09-21 23:17:58,731 INFO: errors [in C:\Projects\Udacity\Python\Fyyur\app.py:594]
2020-09-21 23:18:51,485 INFO: errors [in C:/Projects/Udacity/Python/Fyyur/app.py:594]
2020-09-21 23:23:20,358 INFO: errors [in C:/Projects/Udacity/Python/Fyyur/app.py:605]
2020-09-21 23:24:25,897 INFO: errors [in C:/Projects/Udacity/Python/Fyyur/app.py:606]
2020-09-21 23:25:33,625 INFO: errors [in C:/Projects/Udacity/Python/Fyyur/app.py:606]
2020-09-21 23:28:01,144 INFO: errors [in C:/Projects/Udacity/Python/Fyyur/app.py:610]
2020-09-22 00:09:27,355 INFO: errors [in C:/Projects/Udacity/Python/Fyyur/app.py:612]
2020-09-22 00:38:28,739 INFO: errors [in C:/Projects/Udacity/Python/Fyyur/app.py:631]
2020-09-22 00:54:35,542 INFO: errors [in C:/Projects/Udacity/Python/Fyyur/app.py:611]
2020-09-22 00:54:44,466 ERROR: Exception on /shows [GET] [in C:\Users\Major Ahmed\AppData\Local\Programs\Python\Python37\lib\site-packages\flask\app.py:1892]
Traceback (most recent call last):
  File "C:\Users\Major Ahmed\AppData\Local\Programs\Python\Python37\lib\site-packages\flask\app.py", line 2447, in wsgi_app
    response = self.full_dispatch_request()
  File "C:\Users\Major Ahmed\AppData\Local\Programs\Python\Python37\lib\site-packages\flask\app.py", line 1952, in full_dispatch_request
    rv = self.handle_user_exception(e)
  File "C:\Users\Major Ahmed\AppData\Local\Programs\Python\Python37\lib\site-packages\flask\app.py", line 1821, in handle_user_exception
    reraise(exc_type, exc_value, tb)
  File "C:\Users\Major Ahmed\AppData\Local\Programs\Python\Python37\lib\site-packages\flask\_compat.py", line 39, in reraise
    raise value
  File "C:\Users\Major Ahmed\AppData\Local\Programs\Python\Python37\lib\site-packages\flask\app.py", line 1950, in full_dispatch_request
    rv = self.dispatch_request()
  File "C:\Users\Major Ahmed\AppData\Local\Programs\Python\Python37\lib\site-packages\flask\app.py", line 1936, in dispatch_request
    return self.view_functions[rule.endpoint](**req.view_args)
  File "C:/Projects/Udacity/Python/Fyyur/app.py", line 574, in shows
    return render_template('pages/shows.html', shows=data)
  File "C:\Users\Major Ahmed\AppData\Local\Programs\Python\Python37\lib\site-packages\flask\templating.py", line 140, in render_template
    ctx.app,
  File "C:\Users\Major Ahmed\AppData\Local\Programs\Python\Python37\lib\site-packages\flask\templating.py", line 120, in _render
    rv = template.render(context)
  File "C:\Users\Major Ahmed\AppData\Local\Programs\Python\Python37\lib\site-packages\jinja2\environment.py", line 1090, in render
    self.environment.handle_exception()
  File "C:\Users\Major Ahmed\AppData\Local\Programs\Python\Python37\lib\site-packages\jinja2\environment.py", line 832, in handle_exception
    reraise(*rewrite_traceback_stack(source=source))
  File "C:\Users\Major Ahmed\AppData\Local\Programs\Python\Python37\lib\site-packages\jinja2\_compat.py", line 28, in reraise
    raise value.with_traceback(tb)
  File "C:\Projects\Udacity\Python\Fyyur\templates\pages\shows.html", line 1, in top-level template code
    {% extends 'layouts/main.html' %}
  File "C:\Projects\Udacity\Python\Fyyur\templates\layouts\main.html", line 103, in top-level template code
    {% block content %}{% endblock %}
  File "C:\Projects\Udacity\Python\Fyyur\templates\pages\shows.html", line 9, in block "content"
    <h4>{{ show.start_time|datetime('full') }}</h4>
  File "C:/Projects/Udacity/Python/Fyyur/app.py", line 131, in format_datetime
    date = dateutil.parser.parse(value)
  File "C:\Users\Major Ahmed\AppData\Local\Programs\Python\Python37\lib\site-packages\dateutil\parser.py", line 1168, in parse
    return DEFAULTPARSER.parse(timestr, **kwargs)
  File "C:\Users\Major Ahmed\AppData\Local\Programs\Python\Python37\lib\site-packages\dateutil\parser.py", line 556, in parse
    res, skipped_tokens = self._parse(timestr, **kwargs)
  File "C:\Users\Major Ahmed\AppData\Local\Programs\Python\Python37\lib\site-packages\dateutil\parser.py", line 675, in _parse
    l = _timelex.split(timestr)         # Splits the timestr into tokens
  File "C:\Users\Major Ahmed\AppData\Local\Programs\Python\Python37\lib\site-packages\dateutil\parser.py", line 192, in split
    return list(cls(s))
  File "C:\Users\Major Ahmed\AppData\Local\Programs\Python\Python37\lib\site-packages\dateutil\parser.py", line 61, in __init__
    '{itype}'.format(itype=instream.__class__.__name__))
TypeError: Parser must be a string or character stream, not datetime
2020-09-22 00:55:38,690 INFO: errors [in C:/Projects/Udacity/Python/Fyyur/app.py:611]
2020-09-22 01:03:30,647 INFO: errors [in C:/Projects/Udacity/Python/Fyyur/app.py:616]
2020-09-22 01:08:08,205 INFO: errors [in C:/Projects/Udacity/Python/Fyyur/app.py:616]
2020-09-22 01:08:38,628 INFO: errors [in C:/Projects/Udacity/Python/Fyyur/app.py:616]
2020-09-22 01:12:01,457 INFO: errors [in C:/Projects/Udacity/Python/Fyyur/app.py:623]
2020-09-22 01:12:10,712 ERROR: Exception on /shows/create [POST] [in C:\Users\Major Ahmed\AppData\Local\Programs\Python\Python37\lib\site-packages\flask\app.py:1892]
Traceback (most recent call last):
  File "C:\Users\Major Ahmed\AppData\Local\Programs\Python\Python37\lib\site-packages\flask\app.py", line 2447, in wsgi_app
    response = self.full_dispatch_request()
  File "C:\Users\Major Ahmed\AppData\Local\Programs\Python\Python37\lib\site-packages\flask\app.py", line 1952, in full_dispatch_request
    rv = self.handle_user_exception(e)
  File "C:\Users\Major Ahmed\AppData\Local\Programs\Python\Python37\lib\site-packages\flask\app.py", line 1821, in handle_user_exception
    reraise(exc_type, exc_value, tb)
  File "C:\Users\Major Ahmed\AppData\Local\Programs\Python\Python37\lib\site-packages\flask\_compat.py", line 39, in reraise
    raise value
  File "C:\Users\Major Ahmed\AppData\Local\Programs\Python\Python37\lib\site-packages\flask\app.py", line 1950, in full_dispatch_request
    rv = self.dispatch_request()
  File "C:\Users\Major Ahmed\AppData\Local\Programs\Python\Python37\lib\site-packages\flask\app.py", line 1936, in dispatch_request
    return self.view_functions[rule.endpoint](**req.view_args)
  File "C:/Projects/Udacity/Python/Fyyur/app.py", line 591, in create_show_submission
    artist_id = int(request.form['artist_id'])
ValueError: invalid literal for int() with base 10: 'asd'
2020-09-22 01:12:38,465 INFO: errors [in C:/Projects/Udacity/Python/Fyyur/app.py:623]
2020-09-22 01:14:19,152 INFO: errors [in C:/Projects/Udacity/Python/Fyyur/app.py:625]
2020-09-22 01:14:35,303 ERROR: Exception on /shows/create [POST] [in C:\Users\Major Ahmed\AppData\Local\Programs\Python\Python37\lib\site-packages\flask\app.py:1892]
Traceback (most recent call last):
  File "C:\Users\Major Ahmed\AppData\Local\Programs\Python\Python37\lib\site-packages\flask\app.py", line 2447, in wsgi_app
    response = self.full_dispatch_request()
  File "C:\Users\Major Ahmed\AppData\Local\Programs\Python\Python37\lib\site-packages\flask\app.py", line 1952, in full_dispatch_request
    rv = self.handle_user_exception(e)
  File "C:\Users\Major Ahmed\AppData\Local\Programs\Python\Python37\lib\site-packages\flask\app.py", line 1821, in handle_user_exception
    reraise(exc_type, exc_value, tb)
  File "C:\Users\Major Ahmed\AppData\Local\Programs\Python\Python37\lib\site-packages\flask\_compat.py", line 39, in reraise
    raise value
  File "C:\Users\Major Ahmed\AppData\Local\Programs\Python\Python37\lib\site-packages\flask\app.py", line 1950, in full_dispatch_request
    rv = self.dispatch_request()
  File "C:\Users\Major Ahmed\AppData\Local\Programs\Python\Python37\lib\site-packages\flask\app.py", line 1936, in dispatch_request
    return self.view_functions[rule.endpoint](**req.view_args)
  File "C:/Projects/Udacity/Python/Fyyur/app.py", line 594, in create_show_submission
    show_time = datetime(request.form['start_time'])
TypeError: an integer is required (got type str)
2020-09-22 01:15:32,099 INFO: errors [in C:/Projects/Udacity/Python/Fyyur/app.py:625]
2020-09-22 01:15:38,991 ERROR: Exception on /shows/create [POST] [in C:\Users\Major Ahmed\AppData\Local\Programs\Python\Python37\lib\site-packages\flask\app.py:1892]
Traceback (most recent call last):
  File "C:\Users\Major Ahmed\AppData\Local\Programs\Python\Python37\lib\site-packages\flask\app.py", line 2447, in wsgi_app
    response = self.full_dispatch_request()
  File "C:\Users\Major Ahmed\AppData\Local\Programs\Python\Python37\lib\site-packages\flask\app.py", line 1952, in full_dispatch_request
    rv = self.handle_user_exception(e)
  File "C:\Users\Major Ahmed\AppData\Local\Programs\Python\Python37\lib\site-packages\flask\app.py", line 1821, in handle_user_exception
    reraise(exc_type, exc_value, tb)
  File "C:\Users\Major Ahmed\AppData\Local\Programs\Python\Python37\lib\site-packages\flask\_compat.py", line 39, in reraise
    raise value
  File "C:\Users\Major Ahmed\AppData\Local\Programs\Python\Python37\lib\site-packages\flask\app.py", line 1950, in full_dispatch_request
    rv = self.dispatch_request()
  File "C:\Users\Major Ahmed\AppData\Local\Programs\Python\Python37\lib\site-packages\flask\app.py", line 1936, in dispatch_request
    return self.view_functions[rule.endpoint](**req.view_args)
  File "C:/Projects/Udacity/Python/Fyyur/app.py", line 594, in create_show_submission
    show_time = datetime(format_datetime(request.form['start_time']))
  File "C:/Projects/Udacity/Python/Fyyur/app.py", line 136, in format_datetime
    return babel.dates.format_datetime(date, format)
  File "C:\Users\Major Ahmed\AppData\Local\Programs\Python\Python37\lib\site-packages\babel\dates.py", line 738, in format_datetime
    return parse_pattern(format).apply(datetime, locale)
  File "C:\Users\Major Ahmed\AppData\Local\Programs\Python\Python37\lib\site-packages\babel\dates.py", line 1232, in apply
    return self % DateTimeFormat(datetime, locale)
  File "C:\Users\Major Ahmed\AppData\Local\Programs\Python\Python37\lib\site-packages\babel\dates.py", line 1229, in __mod__
    return self.format % other
  File "C:\Users\Major Ahmed\AppData\Local\Programs\Python\Python37\lib\site-packages\babel\dates.py", line 1264, in __getitem__
    return self.format_weekday(char, num)
  File "C:\Users\Major Ahmed\AppData\Local\Programs\Python\Python37\lib\site-packages\babel\dates.py", line 1397, in format_weekday
    return get_day_names(width, context, self.locale)[weekday]
  File "C:\Users\Major Ahmed\AppData\Local\Programs\Python\Python37\lib\site-packages\babel\dates.py", line 314, in get_day_names
    return Locale.parse(locale).days[context][width]
AttributeError: 'NoneType' object has no attribute 'days'
2020-09-22 01:18:13,904 INFO: errors [in C:/Projects/Udacity/Python/Fyyur/app.py:626]
2020-09-22 01:18:53,396 INFO: errors [in C:/Projects/Udacity/Python/Fyyur/app.py:627]
2020-09-22 01:19:52,258 INFO: errors [in C:/Projects/Udacity/Python/Fyyur/app.py:627]
2020-09-22 01:20:36,220 INFO: errors [in C:/Projects/Udacity/Python/Fyyur/app.py:627]
2020-09-22 01:21:30,371 INFO: errors [in C:/Projects/Udacity/Python/Fyyur/app.py:627]
2020-09-22 01:21:57,747 INFO: errors [in C:/Projects/Udacity/Python/Fyyur/app.py:627]
2020-09-22 01:35:23,144 INFO: errors [in C:/Projects/Udacity/Python/Fyyur/app.py:651]
